Workbook

Sheet はじめに入力
A1: はじめに入力 | D1: 水色＝入力 グレー＝自動計算 単位：万円
A3: 【1】年間予算計画を立てる
A5: 1. 前提の入力 | K5: ※ツール代など
A6: 期首 | B6: マーケ経由の売上目標 | C6: 平均受注単価 | D6: 粗利率 | E6: 回収期間 | F6: リードタイム | G6: 1社あたりの月の粗利 | H6: CACの上限 | I6: 許容CPL | K6: 共通費
A7: 46478 | B7: 5750 | C7: 250 | D7: 0.4 | E7: 1.5 | F7: 4 | G7: =C7*D7/12 | H7: =C7*D7*E7 | I7: =IF(B17=0,0,H7*H17/B17) | K7: 0
A9: 2. チャネル別の計画（年間）の入力
A10: チャネル | B10: リード数 | C10: 有効リード率 | D10: 有効リード数 | E10: 商談化率 | F10: 商談数 | G10: 受注率 | H10: 受注数 | I10: 受注金額 | J10: 外部費用 | K10: 人件費 | L10: CPL | M10: CAC | N10: 回収期間 | O10: CPL判定
A11: 展示会 | B11: 220 | C11: =IF(B11=0,0,D11/B11) | D11: 55 | E11: =IF(D11=0,0,F11/D11) | F11: 22 | G11: =IF(F11=0,0,H11/F11) | H11: 6 | I11: =H11*$C$7 | J11: 500 | K11: 107 | L11: =IF(B11=0,0,(J11+K11)/B11) | M11: =IF(H11=0,0,(J11+K11)/H11) | N11: =IF($G$7=0,0,M11/$G$7) | O11: =IF(B11=0,"",IF(L11<=$I$7,"上限内","上限超え"))
A12: セミナー | B12: 80 | C12: =IF(B12=0,0,D12/B12) | D12: 50 | E12: =IF(D12=0,0,F12/D12) | F12: 20 | G12: =IF(F12=0,0,H12/F12) | H12: 6 | I12: =H12*$C$7 | J12: 90 | K12: 80 | L12: =IF(B12=0,0,(J12+K12)/B12) | M12: =IF(H12=0,0,(J12+K12)/H12) | N12: =IF($G$7=0,0,M12/$G$7) | O12: =IF(B12=0,"",IF(L12<=$I$7,"上限内","上限超え"))
A13: Web広告 | B13: 95 | C13: =IF(B13=0,0,D13/B13) | D13: 43 | E13: =IF(D13=0,0,F13/D13) | F13: 17 | G13: =IF(F13=0,0,H13/F13) | H13: 5 | I13: =H13*$C$7 | J13: 488 | K13: 35 | L13: =IF(B13=0,0,(J13+K13)/B13) | M13: =IF(H13=0,0,(J13+K13)/H13) | N13: =IF($G$7=0,0,M13/$G$7) | O13: =IF(B13=0,"",IF(L13<=$I$7,"上限内","上限超え"))
A14: 自社サイト | B14: 90 | C14: =IF(B14=0,0,D14/B14) | D14: 34 | E14: =IF(D14=0,0,F14/D14) | F14: 14 | G14: =IF(F14=0,0,H14/F14) | H14: 4 | I14: =H14*$C$7 | J14: 356 | K14: 141 | L14: =IF(B14=0,0,(J14+K14)/B14) | M14: =IF(H14=0,0,(J14+K14)/H14) | N14: =IF($G$7=0,0,M14/$G$7) | O14: =IF(B14=0,"",IF(L14<=$I$7,"上限内","上限超え"))
A15: SNS | B15: 12 | C15: =IF(B15=0,0,D15/B15) | D15: 5 | E15: =IF(D15=0,0,F15/D15) | F15: 2 | G15: =IF(F15=0,0,H15/F15) | H15: 1 | I15: =H15*$C$7 | J15: 12 | K15: 42 | L15: =IF(B15=0,0,(J15+K15)/B15) | M15: =IF(H15=0,0,(J15+K15)/H15) | N15: =IF($G$7=0,0,M15/$G$7) | O15: =IF(B15=0,"",IF(L15<=$I$7,"上限内","上限超え"))
A16: メール | B16: 20 | C16: =IF(B16=0,0,D16/B16) | D16: 8 | E16: =IF(D16=0,0,F16/D16) | F16: 3 | G16: =IF(F16=0,0,H16/F16) | H16: 1 | I16: =H16*$C$7 | J16: 96 | K16: 107 | L16: =IF(B16=0,0,(J16+K16)/B16) | M16: =IF(H16=0,0,(J16+K16)/H16) | N16: =IF($G$7=0,0,M16/$G$7) | O16: =IF(B16=0,"",IF(L16<=$I$7,"上限内","上限超え"))
A17: 合計 | B17: =SUM(B11:B16) | C17: =IF(B17=0,0,D17/B17) | D17: =SUM(D11:D16) | E17: =IF(D17=0,0,F17/D17) | F17: =SUM(F11:F16) | G17: =IF(F17=0,0,H17/F17) | H17: =SUM(H11:H16) | I17: =SUM(I11:I16) | J17: =SUM(J11:J16) | K17: =SUM(K11:K16) | L17: =IF(B17=0,0,(J17+K17)/B17) | M17: =IF(H17=0,0,(J17+K17)/H17) | N17: =IF($G$7=0,0,M17/$G$7) | O17: =IF(B17=0,"",IF(L17<=$I$7,"上限内","上限超え"))
A18: 判定＝CPLが許容CPL以下なら「上限内」、超えたら「上限超え」。CPL・CAC・回収期間は外部費用＋人件費で計算する
A20: 3. 計画の妥当性の確認：目標 | K20: 4. 計画の妥当性の確認：コスト
B21: リード数 | C21: 有効リード率 | D21: 有効リード数 | E21: 商談化率 | F21: 商談数 | G21: 受注率 | H21: 受注数 | I21: 受注金額 | K21: コスト合計 | L21: ROI（1年）
A22: 必要な数（逆算） | B22: =IF(D23=0,0,ROUNDUP(D22*B23/D23,0)) | C22: =IF(B22=0,0,D22/B22) | D22: =IF(F23=0,0,ROUNDUP(F22*D23/F23,0)) | E22: =IF(D22=0,0,F22/D22) | F22: =IF(H23=0,0,ROUNDUP(H22*F23/H23,0)) | G22: =IF(F22=0,0,H22/F22) | H22: =IF(C7=0,0,ROUNDUP(B7/C7,0)) | I22: =B7 | K22: =J17+K17+K7 | L22: =IF(K22=0,0,(I17*D7-K22)/K22)
A23: 計画の数 | B23: =B17 | C23: =IF(B23=0,0,D23/B23) | D23: =D17 | E23: =IF(D23=0,0,F23/D23) | F23: =F17 | G23: =IF(F23=0,0,H23/F23) | H23: =H17 | I23: =I17
A24: 判定 | B24: =IF(B23>=B22,"足りる","直す") | C24: - | D24: =IF(D23>=D22,"足りる","直す") | E24: - | F24: =IF(F23>=F22,"足りる","直す") | G24: - | H24: =IF(H23>=H22,"足りる","直す") | I24: =IF(I23>=I22,"足りる","直す")
A27: 【2】月別予算計画を立てる
A29: 1.年間計画（月別）の合計 | C29: ※2.チャネル別の計画（月別）の入力の合計が表示されます。
C30: =MONTH(EDATE($A$7,COLUMN()-3))&"月" | D30: =MONTH(EDATE($A$7,COLUMN()-3))&"月" | E30: =MONTH(EDATE($A$7,COLUMN()-3))&"月" | F30: =MONTH(EDATE($A$7,COLUMN()-3))&"月" | G30: =MONTH(EDATE($A$7,COLUMN()-3))&"月" | H30: =MONTH(EDATE($A$7,COLUMN()-3))&"月" | I30: =MONTH(EDATE($A$7,COLUMN()-3))&"月" | J30: =MONTH(EDATE($A$7,COLUMN()-3))&"月" | ... N30: =MONTH(EDATE($A$7,COLUMN()-3))&"月" | O30: 年間 | P30: 計画との差
A31: リード数 | C31: =C38+C44+C50+C56+C62+C68 | D31: =D38+D44+D50+D56+D62+D68 | E31: =E38+E44+E50+E56+E62+E68 | F31: =F38+F44+F50+F56+F62+F68 | G31: =G38+G44+G50+G56+G62+G68 | H31: =H38+H44+H50+H56+H62+H68 | I31: =I38+I44+I50+I56+I62+I68 | J31: =J38+J44+J50+J56+J62+J68 | ... N31: =N38+N44+N50+N56+N62+N68 | O31: =SUM(C31:N31) | P31: =O31-B17
A32: 有効リード数 | C32: =C39+C45+C51+C57+C63+C69 | D32: =D39+D45+D51+D57+D63+D69 | E32: =E39+E45+E51+E57+E63+E69 | F32: =F39+F45+F51+F57+F63+F69 | G32: =G39+G45+G51+G57+G63+G69 | H32: =H39+H45+H51+H57+H63+H69 | I32: =I39+I45+I51+I57+I63+I69 | J32: =J39+J45+J51+J57+J63+J69 | ... N32: =N39+N45+N51+N57+N63+N69 | O32: =SUM(C32:N32) | P32: =O32-D17
A33: 受注数の見込み | C33: =IF($D$17=0,0,INDEX($C$32:$N$32,MOD(COLUMN()-COLUMN($C$32)-$F$7,12)+1)*$H$17/$D$17) | D33: =IF($D$17=0,0,INDEX($C$32:$N$32,MOD(COLUMN()-COLUMN($C$32)-$F$7,12)+1)*$H$17/$D$17) | E33: =IF($D$17=0,0,INDEX($C$32:$N$32,MOD(COLUMN()-COLUMN($C$32)-$F$7,12)+1)*$H$17/$D$17) | F33: =IF($D$17=0,0,INDEX($C$32:$N$32,MOD(COLUMN()-COLUMN($C$32)-$F$7,12)+1)*$H$17/$D$17) | G33: =IF($D$17=0,0,INDEX($C$32:$N$32,MOD(COLUMN()-COLUMN($C$32)-$F$7,12)+1)*$H$17/$D$17) | H33: =IF($D$17=0,0,INDEX($C$32:$N$32,MOD(COLUMN()-COLUMN($C$32)-$F$7,12)+1)*$H$17/$D$17) | I33: =IF($D$17=0,0,INDEX($C$32:$N$32,MOD(COLUMN()-COLUMN($C$32)-$F$7,12)+1)*$H$17/$D$17) | J33: =IF($D$17=0,0,INDEX($C$32:$N$32,MOD(COLUMN()-COLUMN($C$32)-$F$7,12)+1)*$H$17/$D$17) | ... N33: =IF($D$17=0,0,INDEX($C$32:$N$32,MOD(COLUMN()-COLUMN($C$32)-$F$7,12)+1)*$H$17/$D$17) | O33: =SUM(C33:N33) | P33: =O33-H17
A34: 受注数の見込み＝リードを獲得した月からリードタイムの月数あとに計上する。期首からリードタイム分の月は、前期の同じ月のリードを今期と同じとみなして見込む。期末のリードタイム分の受注は翌期に入る
A36: 2.チャネル別の計画（月別）の入力 | C36: ※外部費用と人件費は年額÷12が自動で入ります。月ごとに違う場合は上書きしてください。
A37: チャネル | B37: 展示会 | C37: =MONTH(EDATE($A$7,COLUMN()-3))&"月" | D37: =MONTH(EDATE($A$7,COLUMN()-3))&"月" | E37: =MONTH(EDATE($A$7,COLUMN()-3))&"月" | F37: =MONTH(EDATE($A$7,COLUMN()-3))&"月" | G37: =MONTH(EDATE($A$7,COLUMN()-3))&"月" | H37: =MONTH(EDATE($A$7,COLUMN()-3))&"月" | I37: =MONTH(EDATE($A$7,COLUMN()-3))&"月" | J37: =MONTH(EDATE($A$7,COLUMN()-3))&"月" | ... N37: =MONTH(EDATE($A$7,COLUMN()-3))&"月" | O37: 年間 | P37: 計画との差
A38: 展示会 | B38: リード数 | C38: 0 | D38: 0 | E38: 110 | F38: 0 | G38: 0 | H38: 0 | I38: 0 | J38: 110 | K38: 0 | L38: 0 | M38: 0 | N38: 0 | O38: =SUM(C38:N38) | P38: =O38-$B$11
B39: 有効リード数 | C39: 0 | D39: 0 | E39: 27 | F39: 0 | G39: 0 | H39: 0 | I39: 0 | J39: 28 | K39: 0 | L39: 0 | M39: 0 | N39: 0 | O39: =SUM(C39:N39) | P39: =O39-$D$11
B40: 外部費用 | C40: =$J$11/12 | D40: =$J$11/12 | E40: =$J$11/12 | F40: =$J$11/12 | G40: =$J$11/12 | H40: =$J$11/12 | I40: =$J$11/12 | J40: =$J$11/12 | ... N40: =$J$11/12 | O40: =SUM(C40:N40) | P40: =O40-$J$11
B41: 人件費 | C41: =$K$11/12 | D41: =$K$11/12 | E41: =$K$11/12 | F41: =$K$11/12 | G41: =$K$11/12 | H41: =$K$11/12 | I41: =$K$11/12 | J41: =$K$11/12 | ... N41: =$K$11/12 | O41: =SUM(C41:N41) | P41: =O41-$K$11
A43: チャネル | B43: セミナー | C43: =MONTH(EDATE($A$7,COLUMN()-3))&"月" | D43: =MONTH(EDATE($A$7,COLUMN()-3))&"月" | E43: =MONTH(EDATE($A$7,COLUMN()-3))&"月" | F43: =MONTH(EDATE($A$7,COLUMN()-3))&"月" | G43: =MONTH(EDATE($A$7,COLUMN()-3))&"月" | H43: =MONTH(EDATE($A$7,COLUMN()-3))&"月" | I43: =MONTH(EDATE($A$7,COLUMN()-3))&"月" | J43: =MONTH(EDATE($A$7,COLUMN()-3))&"月" | ... N43: =MONTH(EDATE($A$7,COLUMN()-3))&"月" | O43: 年間 | P43: 計画との差
A44: セミナー | B44: リード数 | C44: 0 | D44: 13 | E44: 0 | F44: 13 | G44: 0 | H44: 13 | I44: 0 | J44: 13 | K44: 0 | L44: 14 | M44: 0 | N44: 14 | O44: =SUM(C44:N44) | P44: =O44-$B$12
B45: 有効リード数 | C45: 0 | D45: 8 | E45: 0 | F45: 8 | G45: 0 | H45: 8 | I45: 0 | J45: 8 | K45: 0 | L45: 9 | M45: 0 | N45: 9 | O45: =SUM(C45:N45) | P45: =O45-$D$12
B46: 外部費用 | C46: =$J$12/12 | D46: =$J$12/12 | E46: =$J$12/12 | F46: =$J$12/12 | G46: =$J$12/12 | H46: =$J$12/12 | I46: =$J$12/12 | J46: =$J$12/12 | ... N46: =$J$12/12 | O46: =SUM(C46:N46) | P46: =O46-$J$12
B47: 人件費 | C47: =$K$12/12 | D47: =$K$12/12 | E47: =$K$12/12 | F47: =$K$12/12 | G47: =$K$12/12 | H47: =$K$12/12 | I47: =$K$12/12 | J47: =$K$12/12 | ... N47: =$K$12/12 | O47: =SUM(C47:N47) | P47: =O47-$K$12
A49: チャネル | B49: Web広告 | C49: =MONTH(EDATE($A$7,COLUMN()-3))&"月" | D49: =MONTH(EDATE($A$7,COLUMN()-3))&"月" | E49: =MONTH(EDATE($A$7,COLUMN()-3))&"月" | F49: =MONTH(EDATE($A$7,COLUMN()-3))&"月" | G49: =MONTH(EDATE($A$7,COLUMN()-3))&"月" | H49: =MONTH(EDATE($A$7,COLUMN()-3))&"月" | I49: =MONTH(EDATE($A$7,COLUMN()-3))&"月" | J49: =MONTH(EDATE($A$7,COLUMN()-3))&"月" | ... N49: =MONTH(EDATE($A$7,COLUMN()-3))&"月" | O49: 年間 | P49: 計画との差
A50: Web広告 | B50: リード数 | C50: 5 | D50: 9 | E50: 9 | F50: 9 | G50: 9 | H50: 9 | I50: 9 | J50: 9 | K50: 10 | L50: 6 | M50: 6 | N50: 5 | O50: =SUM(C50:N50) | P50: =O50-$B$13
...

Sheet 毎月の実績入力
A1: 毎月の実績入力 | D1: 水色＝入力 グレー＝自動計算 単位：万円
A3: 1. 実績の合計（自動）
B4: 項目 | C4: =MONTH(EDATE('はじめに入力'!$A$7,0))&"月" | D4: =MONTH(EDATE('はじめに入力'!$A$7,1))&"月" | E4: =MONTH(EDATE('はじめに入力'!$A$7,2))&"月" | F4: =MONTH(EDATE('はじめに入力'!$A$7,3))&"月" | G4: =MONTH(EDATE('はじめに入力'!$A$7,4))&"月" | H4: =MONTH(EDATE('はじめに入力'!$A$7,5))&"月" | I4: =MONTH(EDATE('はじめに入力'!$A$7,6))&"月" | J4: =MONTH(EDATE('はじめに入力'!$A$7,7))&"月" | K4: =MONTH(EDATE('はじめに入力'!$A$7,8))&"月" | L4: =MONTH(EDATE('はじめに入力'!$A$7,9))&"月" | M4: =MONTH(EDATE('はじめに入力'!$A$7,10))&"月" | N4: =MONTH(EDATE('はじめに入力'!$A$7,11))&"月" | O4: 年間
B5: リード数 | C5: =C16+C24+C32+C40+C48+C56 | D5: =D16+D24+D32+D40+D48+D56 | E5: =E16+E24+E32+E40+E48+E56 | F5: =F16+F24+F32+F40+F48+F56 | G5: =G16+G24+G32+G40+G48+G56 | H5: =H16+H24+H32+H40+H48+H56 | I5: =I16+I24+I32+I40+I48+I56 | J5: =J16+J24+J32+J40+J48+J56 | ... N5: =N16+N24+N32+N40+N48+N56 | O5: =SUM(C5:N5)
B6: 有効リード数 | C6: =C17+C25+C33+C41+C49+C57 | D6: =D17+D25+D33+D41+D49+D57 | E6: =E17+E25+E33+E41+E49+E57 | F6: =F17+F25+F33+F41+F49+F57 | G6: =G17+G25+G33+G41+G49+G57 | H6: =H17+H25+H33+H41+H49+H57 | I6: =I17+I25+I33+I41+I49+I57 | J6: =J17+J25+J33+J41+J49+J57 | ... N6: =N17+N25+N33+N41+N49+N57 | O6: =SUM(C6:N6)
B7: 商談数 | C7: =C18+C26+C34+C42+C50+C58 | D7: =D18+D26+D34+D42+D50+D58 | E7: =E18+E26+E34+E42+E50+E58 | F7: =F18+F26+F34+F42+F50+F58 | G7: =G18+G26+G34+G42+G50+G58 | H7: =H18+H26+H34+H42+H50+H58 | I7: =I18+I26+I34+I42+I50+I58 | J7: =J18+J26+J34+J42+J50+J58 | ... N7: =N18+N26+N34+N42+N50+N58 | O7: =SUM(C7:N7)
B8: 受注数 | C8: =C19+C27+C35+C43+C51+C59 | D8: =D19+D27+D35+D43+D51+D59 | E8: =E19+E27+E35+E43+E51+E59 | F8: =F19+F27+F35+F43+F51+F59 | G8: =G19+G27+G35+G43+G51+G59 | H8: =H19+H27+H35+H43+H51+H59 | I8: =I19+I27+I35+I43+I51+I59 | J8: =J19+J27+J35+J43+J51+J59 | ... N8: =N19+N27+N35+N43+N51+N59 | O8: =SUM(C8:N8)
B9: 外部費用 | C9: =C20+C28+C36+C44+C52+C60 | D9: =D20+D28+D36+D44+D52+D60 | E9: =E20+E28+E36+E44+E52+E60 | F9: =F20+F28+F36+F44+F52+F60 | G9: =G20+G28+G36+G44+G52+G60 | H9: =H20+H28+H36+H44+H52+H60 | I9: =I20+I28+I36+I44+I52+I60 | J9: =J20+J28+J36+J44+J52+J60 | ... N9: =N20+N28+N36+N44+N52+N60 | O9: =SUM(C9:N9)
B10: 人件費 | C10: =C21+C29+C37+C45+C53+C61 | D10: =D21+D29+D37+D45+D53+D61 | E10: =E21+E29+E37+E45+E53+E61 | F10: =F21+F29+F37+F45+F53+F61 | G10: =G21+G29+G37+G45+G53+G61 | H10: =H21+H29+H37+H45+H53+H61 | I10: =I21+I29+I37+I45+I53+I61 | J10: =J21+J29+J37+J45+J53+J61 | ... N10: =N21+N29+N37+N45+N53+N61 | O10: =SUM(C10:N10)
A12: 2. チャネル別の実績（月別）の入力
A13: 毎月、水色のセルに実績を入れます。商談数・受注数は、わからない月は空欄、ゼロの月は0を入れます（空欄の月は率を計算しません）。
A14: 外部費用・人件費は計画の月額（年額÷12）が入っています。実際の額が違う月は上書きしてください
A15: チャネル | B15: 展示会 | C15: =C$4 | D15: =D$4 | E15: =E$4 | F15: =F$4 | G15: =G$4 | H15: =H$4 | I15: =I$4 | J15: =J$4 | ... N15: =N$4 | O15: 年間
A16: 展示会 | B16: リード数 | O16: =SUM(C16:N16)
B17: 有効リード数 | O17: =SUM(C17:N17)
B18: 商談数 | O18: =SUM(C18:N18)
B19: 受注数 | O19: =SUM(C19:N19)
B20: 外部費用 | C20: ='はじめに入力'!C40 | D20: ='はじめに入力'!D40 | E20: ='はじめに入力'!E40 | F20: ='はじめに入力'!F40 | G20: ='はじめに入力'!G40 | H20: ='はじめに入力'!H40 | I20: ='はじめに入力'!I40 | J20: ='はじめに入力'!J40 | ... N20: ='はじめに入力'!N40 | O20: =SUM(C20:N20)
B21: 人件費 | C21: ='はじめに入力'!C41 | D21: ='はじめに入力'!D41 | E21: ='はじめに入力'!E41 | F21: ='はじめに入力'!F41 | G21: ='はじめに入力'!G41 | H21: ='はじめに入力'!H41 | I21: ='はじめに入力'!I41 | J21: ='はじめに入力'!J41 | ... N21: ='はじめに入力'!N41 | O21: =SUM(C21:N21)
A23: チャネル | B23: セミナー | C23: =C$4 | D23: =D$4 | E23: =E$4 | F23: =F$4 | G23: =G$4 | H23: =H$4 | I23: =I$4 | J23: =J$4 | ... N23: =N$4 | O23: 年間
A24: セミナー | B24: リード数 | O24: =SUM(C24:N24)
B25: 有効リード数 | O25: =SUM(C25:N25)
B26: 商談数 | O26: =SUM(C26:N26)
B27: 受注数 | O27: =SUM(C27:N27)
B28: 外部費用 | C28: ='はじめに入力'!C46 | D28: ='はじめに入力'!D46 | E28: ='はじめに入力'!E46 | F28: ='はじめに入力'!F46 | G28: ='はじめに入力'!G46 | H28: ='はじめに入力'!H46 | I28: ='はじめに入力'!I46 | J28: ='はじめに入力'!J46 | ... N28: ='はじめに入力'!N46 | O28: =SUM(C28:N28)
B29: 人件費 | C29: ='はじめに入力'!C47 | D29: ='はじめに入力'!D47 | E29: ='はじめに入力'!E47 | F29: ='はじめに入力'!F47 | G29: ='はじめに入力'!G47 | H29: ='はじめに入力'!H47 | I29: ='はじめに入力'!I47 | J29: ='はじめに入力'!J47 | ... N29: ='はじめに入力'!N47 | O29: =SUM(C29:N29)
A31: チャネル | B31: Web広告 | C31: =C$4 | D31: =D$4 | E31: =E$4 | F31: =F$4 | G31: =G$4 | H31: =H$4 | I31: =I$4 | J31: =J$4 | ... N31: =N$4 | O31: 年間
A32: Web広告 | B32: リード数 | O32: =SUM(C32:N32)
B33: 有効リード数 | O33: =SUM(C33:N33)
B34: 商談数 | O34: =SUM(C34:N34)
B35: 受注数 | O35: =SUM(C35:N35)
B36: 外部費用 | C36: ='はじめに入力'!C52 | D36: ='はじめに入力'!D52 | E36: ='はじめに入力'!E52 | F36: ='はじめに入力'!F52 | G36: ='はじめに入力'!G52 | H36: ='はじめに入力'!H52 | I36: ='はじめに入力'!I52 | J36: ='はじめに入力'!J52 | ... N36: ='はじめに入力'!N52 | O36: =SUM(C36:N36)
B37: 人件費 | C37: ='はじめに入力'!C53 | D37: ='はじめに入力'!D53 | E37: ='はじめに入力'!E53 | F37: ='はじめに入力'!F53 | G37: ='はじめに入力'!G53 | H37: ='はじめに入力'!H53 | I37: ='はじめに入力'!I53 | J37: ='はじめに入力'!J53 | ... N37: ='はじめに入力'!N53 | O37: =SUM(C37:N37)
A39: チャネル | B39: 自社サイト | C39: =C$4 | D39: =D$4 | E39: =E$4 | F39: =F$4 | G39: =G$4 | H39: =H$4 | I39: =I$4 | J39: =J$4 | ... N39: =N$4 | O39: 年間
A40: 自社サイト | B40: リード数 | O40: =SUM(C40:N40)
B41: 有効リード数 | O41: =SUM(C41:N41)
B42: 商談数 | O42: =SUM(C42:N42)
B43: 受注数 | O43: =SUM(C43:N43)
B44: 外部費用 | C44: ='はじめに入力'!C58 | D44: ='はじめに入力'!D58 | E44: ='はじめに入力'!E58 | F44: ='はじめに入力'!F58 | G44: ='はじめに入力'!G58 | H44: ='はじめに入力'!H58 | I44: ='はじめに入力'!I58 | J44: ='はじめに入力'!J58 | ... N44: ='はじめに入力'!N58 | O44: =SUM(C44:N44)
B45: 人件費 | C45: ='はじめに入力'!C59 | D45: ='はじめに入力'!D59 | E45: ='はじめに入力'!E59 | F45: ='はじめに入力'!F59 | G45: ='はじめに入力'!G59 | H45: ='はじめに入力'!H59 | I45: ='はじめに入力'!I59 | J45: ='はじめに入力'!J59 | ... N45: ='はじめに入力'!N59 | O45: =SUM(C45:N45)
...

Sheet KPI診断
A1: KPI診断 | D1: 水色＝入力 グレー＝自動計算 単位：万円
A3: 1. 年間の結果（期末に確認。商談数・受注数は「毎月の実績入力」の合計を自動で表示） | R3: （計算用）対象月までの指標と課題（達成率1未満＝課題）
A5: 項目 | B5: リード数 | C5: 有効リード率 | D5: 有効リード数 | E5: 商談化率 | F5: 商談数 | G5: 受注率 | H5: 受注数 | I5: 費用 | J5: CAC | K5: 回収期間 | R5: チャネル | S5: 狙う指標 | T5: 達成率 | U5: 根拠 | V5: 判定 | W5: 実績の率
A6: 年間の目標 | B6: ='はじめに入力'!B17 | C6: ='はじめに入力'!C17 | D6: ='はじめに入力'!D17 | E6: ='はじめに入力'!E17 | F6: ='はじめに入力'!F17 | G6: ='はじめに入力'!G17 | H6: ='はじめに入力'!H17 | I6: ='はじめに入力'!J17+'はじめに入力'!K17+'はじめに入力'!K7 | J6: =IFERROR(I6/H6,"") | K6: =IFERROR(J6/'はじめに入力'!G7,"") | R6: 展示会 | S6: リード数 | T6: =IF(ISNUMBER($C27),$C27,"") | U6: =IF(T6="","","実績"&TEXT($B27,"#,##0")&"件（計画"&IFERROR(TEXT($B27/$C27,"#,##0"),"-")&"件・達成率"&TEXT(T6,"0%")&"）") | V6: =IF(T6="","",IF(T6>=1,"達成",IF(T6>=0.9,"やや届かない","届かない")))
A7: 年間の実績 | B7: =IF(AND(F7="",H7=""),"",'毎月の実績入力'!O5) | C7: =IFERROR(D7/B7,"") | D7: =IF(AND(F7="",H7=""),"",'毎月の実績入力'!O6) | E7: =IFERROR(F7/D7,"") | F7: ='毎月の実績入力'!O7 | G7: =IFERROR(H7/F7,"") | H7: ='毎月の実績入力'!O8 | I7: =IF(H7="","",'毎月の実績入力'!O9+'はじめに入力'!K17+'はじめに入力'!K7) | J7: =IF(H7="","",IFERROR(I7/H7,"")) | K7: =IF(J7="","",IFERROR(J7/'はじめに入力'!G7,"")) | R7: セミナー | S7: リード数 | T7: =IF(ISNUMBER($C28),$C28,"") | U7: =IF(T7="","","実績"&TEXT($B28,"#,##0")&"件（計画"&IFERROR(TEXT($B28/$C28,"#,##0"),"-")&"件・達成率"&TEXT(T7,"0%")&"）") | V7: =IF(T7="","",IF(T7>=1,"達成",IF(T7>=0.9,"やや届かない","届かない")))
A8: 達成率・差 | B8: =IF(B7="","",IFERROR(B7/B6,"")) | C8: =IF(C7="","",IFERROR((C7-C6)*100,"")) | D8: =IF(D7="","",IFERROR(D7/D6,"")) | E8: =IF(E7="","",IFERROR((E7-E6)*100,"")) | F8: =IF(F7="","",IFERROR(F7/F6,"")) | G8: =IF(G7="","",IFERROR((G7-G6)*100,"")) | H8: =IF(H7="","",IFERROR(H7/H6,"")) | I8: =IF(I7="","",IFERROR(I7/I6,"")) | J8: =IF(J7="","",J7-J6) | K8: =IF(K7="","",K7-K6) | R8: Web広告 | S8: リード数 | T8: =IF(ISNUMBER($C29),$C29,"") | U8: =IF(T8="","","実績"&TEXT($B29,"#,##0")&"件（計画"&IFERROR(TEXT($B29/$C29,"#,##0"),"-")&"件・達成率"&TEXT(T8,"0%")&"）") | V8: =IF(T8="","",IF(T8>=1,"達成",IF(T8>=0.9,"やや届かない","届かない")))
A9: 判定 | B9: =IF(B8="","",IF(B8>=1,"達成",IF(B8>=0.9,"やや届かない","届かない"))) | D9: =IF(D8="","",IF(D8>=1,"達成",IF(D8>=0.9,"やや届かない","届かない"))) | F9: =IF(F8="","",IF(F8>=1,"達成",IF(F8>=0.9,"やや届かない","届かない"))) | H9: =IF(H8="","",IF(H8>=1,"達成",IF(H8>=0.9,"やや届かない","届かない"))) | J9: =IF(J7="","",IF(J7<='はじめに入力'!H7,"上限内","上限超え")) | K9: =IF(K7="","",IF(K7<='はじめに入力'!E7*12,"上限内","上限超え")) | R9: 自社サイト | S9: リード数 | T9: =IF(ISNUMBER($C30),$C30,"") | U9: =IF(T9="","","実績"&TEXT($B30,"#,##0")&"件（計画"&IFERROR(TEXT($B30/$C30,"#,##0"),"-")&"件・達成率"&TEXT(T9,"0%")&"）") | V9: =IF(T9="","",IF(T9>=1,"達成",IF(T9>=0.9,"やや届かない","届かない")))
A10: 商談数・受注数を「毎月の実績入力」に入れると表示されます（期の途中は参考値）。 | R10: SNS | S10: リード数 | T10: =IF(ISNUMBER($C31),$C31,"") | U10: =IF(T10="","","実績"&TEXT($B31,"#,##0")&"件（計画"&IFERROR(TEXT($B31/$C31,"#,##0"),"-")&"件・達成率"&TEXT(T10,"0%")&"）") | V10: =IF(T10="","",IF(T10>=1,"達成",IF(T10>=0.9,"やや届かない","届かない")))
R11: メール | S11: リード数 | T11: =IF(ISNUMBER($C32),$C32,"") | U11: =IF(T11="","","実績"&TEXT($B32,"#,##0")&"件（計画"&IFERROR(TEXT($B32/$C32,"#,##0"),"-")&"件・達成率"&TEXT(T11,"0%")&"）") | V11: =IF(T11="","",IF(T11>=1,"達成",IF(T11>=0.9,"やや届かない","届かない")))
A12: 2. 予実表（対象月まで） | R12: Web広告 | S12: 有効リード率 | T12: =IF(AND(ISNUMBER($C29),ISNUMBER($E29)),IFERROR($E29/$C29,""),"") | U12: =IF(T12="","","有効リード率"&TEXT(W12,"0%")&"（計画"&TEXT(W12/T12,"0%")&"）") | V12: =IF(T12="","",IF(T12>=1,"達成",IF(T12>=0.9,"やや届かない","届かない"))) | W12: =IFERROR($D29/$B29,"")
R13: セミナー | S13: 有効リード率 | T13: =IF(AND(ISNUMBER($C28),ISNUMBER($E28)),IFERROR($E28/$C28,""),"") | U13: =IF(T13="","","有効リード率"&TEXT(W13,"0%")&"（計画"&TEXT(W13/T13,"0%")&"）") | V13: =IF(T13="","",IF(T13>=1,"達成",IF(T13>=0.9,"やや届かない","届かない"))) | W13: =IFERROR($D28/$B28,"")
A14: 対象月 | B14: 9月 | C14: 経過月数 | D14: =IFERROR(MATCH(B14,'毎月の実績入力'!$C$4:$N$4,0),"") | E14: 対象月を選ぶと、このシートの「2.」「3.」がその月までの数字になります | R14: 展示会 | S14: 有効リード率 | T14: =IF(AND(ISNUMBER($C27),ISNUMBER($E27)),IFERROR($E27/$C27,""),"") | U14: =IF(T14="","","有効リード率"&TEXT(W14,"0%")&"（計画"&TEXT(W14/T14,"0%")&"）") | V14: =IF(T14="","",IF(T14>=1,"達成",IF(T14>=0.9,"やや届かない","届かない"))) | W14: =IFERROR($D27/$B27,"")
R15: 自社サイト | S15: 有効リード率 | T15: =IF(AND(ISNUMBER($C30),ISNUMBER($E30)),IFERROR($E30/$C30,""),"") | U15: =IF(T15="","","有効リード率"&TEXT(W15,"0%")&"（計画"&TEXT(W15/T15,"0%")&"）") | V15: =IF(T15="","",IF(T15>=1,"達成",IF(T15>=0.9,"やや届かない","届かない"))) | W15: =IFERROR($D30/$B30,"")
A16: 項目 | B16: リード数 | C16: 有効リード率 | D16: 有効リード数 | F16: 外部費用 | G16: 人件費 | R16: SNS | S16: 有効リード率 | T16: =IF(AND(ISNUMBER($C31),ISNUMBER($E31)),IFERROR($E31/$C31,""),"") | U16: =IF(T16="","","有効リード率"&TEXT(W16,"0%")&"（計画"&TEXT(W16/T16,"0%")&"）") | V16: =IF(T16="","",IF(T16>=1,"達成",IF(T16>=0.9,"やや届かない","届かない"))) | W16: =IFERROR($D31/$B31,"")
A17: 計画 | B17: =IF($D$14="","",SUM(OFFSET('はじめに入力'!$C$31,0,0,1,$D$14))) | C17: =IFERROR(D17/B17,"") | D17: =IF($D$14="","",SUM(OFFSET('はじめに入力'!$C$32,0,0,1,$D$14))) | F17: =IF($D$14="","",SUM(OFFSET('はじめに入力'!$C$40,0,0,1,$D$14))+SUM(OFFSET('はじめに入力'!$C$46,0,0,1,$D$14))+SUM(OFFSET('はじめに入力'!$C$52,0,0,1,$D$14))+SUM(OFFSET('はじめに入力'!$C$58,0,0,1,$D$14))+SUM(OFFSET('はじめに入力'!$C$64,0,0,1,$D$14))+SUM(OFFSET('はじめに入力'!$C$70,0,0,1,$D$14))) | G17: =IF($D$14="","",SUM(OFFSET('はじめに入力'!$C$41,0,0,1,$D$14))+SUM(OFFSET('はじめに入力'!$C$47,0,0,1,$D$14))+SUM(OFFSET('はじめに入力'!$C$53,0,0,1,$D$14))+SUM(OFFSET('はじめに入力'!$C$59,0,0,1,$D$14))+SUM(OFFSET('はじめに入力'!$C$65,0,0,1,$D$14))+SUM(OFFSET('はじめに入力'!$C$71,0,0,1,$D$14))) | R17: メール | S17: 有効リード率 | T17: =IF(AND(ISNUMBER($C32),ISNUMBER($E32)),IFERROR($E32/$C32,""),"") | U17: =IF(T17="","","有効リード率"&TEXT(W17,"0%")&"（計画"&TEXT(W17/T17,"0%")&"）") | V17: =IF(T17="","",IF(T17>=1,"達成",IF(T17>=0.9,"やや届かない","届かない"))) | W17: =IFERROR($D32/$B32,"")
A18: 実績 | B18: =IF($D$14="","",SUM(OFFSET('毎月の実績入力'!$C$5,0,0,1,$D$14))) | C18: =IFERROR(D18/B18,"") | D18: =IF($D$14="","",SUM(OFFSET('毎月の実績入力'!$C$6,0,0,1,$D$14))) | F18: =IF($D$14="","",SUM(OFFSET('毎月の実績入力'!$C$9,0,0,1,$D$14))) | G18: =G17 | R18: 展示会 | S18: CPL | T18: =IF(ISNUMBER($I27),IFERROR('はじめに入力'!$I$7/$I27,""),"") | U18: =IF(T18="","","CPL "&TEXT($I27,"0.0")&"万円（許容"&TEXT('はじめに入力'!$I$7,"0.0")&"万円）") | V18: =IF(T18="","",IF(T18>=1,"上限内","上限超え"))
A19: 達成率・差 | B19: =IFERROR(B18/B17,"") | C19: =IFERROR((C18-C17)*100,"") | D19: =IFERROR(D18/D17,"") | F19: =IFERROR(F18/F17,"") | G19: =IFERROR(G18/G17,"") | R19: セミナー | S19: CPL | T19: =IF(ISNUMBER($I28),IFERROR('はじめに入力'!$I$7/$I28,""),"") | U19: =IF(T19="","","CPL "&TEXT($I28,"0.0")&"万円（許容"&TEXT('はじめに入力'!$I$7,"0.0")&"万円）") | V19: =IF(T19="","",IF(T19>=1,"上限内","上限超え"))
A20: 判定 | B20: =IF(B19="","",IF(B19>=1,"達成",IF(B19>=0.9,"やや届かない","届かない"))) | C20: - | D20: =IF(D19="","",IF(D19>=1,"達成",IF(D19>=0.9,"やや届かない","届かない"))) | R20: Web広告 | S20: CPL | T20: =IF(ISNUMBER($I29),IFERROR('はじめに入力'!$I$7/$I29,""),"") | U20: =IF(T20="","","CPL "&TEXT($I29,"0.0")&"万円（許容"&TEXT('はじめに入力'!$I$7,"0.0")&"万円）") | V20: =IF(T20="","",IF(T20>=1,"上限内","上限超え"))
A21: 判定＝達成率が100%以上なら「達成」、90〜99%なら「やや届かない」、90%未満なら「届かない」。率は差（ポイント）を表示 | R21: 自社サイト | S21: CPL | T21: =IF(ISNUMBER($I30),IFERROR('はじめに入力'!$I$7/$I30,""),"") | U21: =IF(T21="","","CPL "&TEXT($I30,"0.0")&"万円（許容"&TEXT('はじめに入力'!$I$7,"0.0")&"万円）") | V21: =IF(T21="","",IF(T21>=1,"上限内","上限超え"))
R22: SNS | S22: CPL | T22: =IF(ISNUMBER($I31),IFERROR('はじめに入力'!$I$7/$I31,""),"") | U22: =IF(T22="","","CPL "&TEXT($I31,"0.0")&"万円（許容"&TEXT('はじめに入力'!$I$7,"0.0")&"万円）") | V22: =IF(T22="","",IF(T22>=1,"上限内","上限超え"))
A23: 3. チャネル別予実表（対象月まで） | G23: 許容CPL | H23: ='はじめに入力'!I7 | R23: メール | S23: CPL | T23: =IF(ISNUMBER($I32),IFERROR('はじめに入力'!$I$7/$I32,""),"") | U23: =IF(T23="","","CPL "&TEXT($I32,"0.0")&"万円（許容"&TEXT('はじめに入力'!$I$7,"0.0")&"万円）") | V23: =IF(T23="","",IF(T23>=1,"上限内","上限超え"))
R24: 全体 | S24: 商談化率 | T24: =IF(ISNUMBER(W24),W24/'はじめに入力'!$E$17,"") | U24: =IF(T24="","","商談化率"&TEXT(W24,"0%")&"（計画"&TEXT('はじめに入力'!$E$17,"0%")&"）") | V24: =IF(T24="","",IF(T24>=1,"達成",IF(T24>=0.9,"やや届かない","届かない"))) | W24: =IFERROR(SUM(OFFSET('毎月の実績入力'!$C$7,0,0,1,$D$14))/SUM(OFFSET('毎月の実績入力'!$C$6,0,0,1,$D$14)),"")
A25: チャネル | B25: リード数 | D25: 有効リード数 | F25: 商談数 | G25: 受注数 | H25: 費用 | I25: CPL | J25: 判定 | K25: 撤退の判断 | R25: 全体 | S25: 受注率 | T25: =IF(ISNUMBER(W25),W25/'はじめに入力'!$G$17,"") | U25: =IF(T25="","","受注率"&TEXT(W25,"0%")&"（計画"&TEXT('はじめに入力'!$G$17,"0%")&"）") | V25: =IF(T25="","",IF(T25>=1,"達成",IF(T25>=0.9,"やや届かない","届かない"))) | W25: =IF($D$14<='はじめに入力'!$F$7,"",IFERROR(SUM(OFFSET('毎月の実績入力'!$C$8,0,0,1,$D$14))/SUM(OFFSET('毎月の実績入力'!$C$7,0,0,1,$D$14)),""))
B26: 実績 | C26: 達成率 | D26: 実績 | E26: 達成率
A27: 展示会 | B27: {=IFERROR(IF(H27="","",LET(s,IFERROR(MATCH(TRUE,INDEX('はじめに入力'!$C$38:$N$38>0,0),0),""),SUM(OFFSET('毎月の実績入力'!$C$16,0,s-1,1,$D$14-s+1)))),"")} | C27: {=IFERROR(IF(H27="","",LET(s,IFERROR(MATCH(TRUE,INDEX('はじめに入力'!$C$38:$N$38>0,0),0),""),IFERROR(B27/SUM(OFFSET('はじめに入力'!$C$38,0,s-1,1,$D$14-s+1)),""))),"")} | D27: {=IFERROR(IF(H27="","",LET(s,IFERROR(MATCH(TRUE,INDEX('はじめに入力'!$C$38:$N$38>0,0),0),""),SUM(OFFSET('毎月の実績入力'!$C$17,0,s-1,1,$D$14-s+1)))),"")} | E27: {=IFERROR(IF(H27="","",LET(s,IFERROR(MATCH(TRUE,INDEX('はじめに入力'!$C$38:$N$38>0,0),0),""),IFERROR(D27/SUM(OFFSET('はじめに入力'!$C$39,0,s-1,1,$D$14-s+1)),""))),"")} | F27: =IF($D$14="","",IF(COUNT(OFFSET('毎月の実績入力'!$C$18,0,0,1,$D$14))=0,"",SUM(OFFSET('毎月の実績入力'!$C$18,0,0,1,$D$14)))) | G27: =IF($D$14="","",IF(COUNT(OFFSET('毎月の実績入力'!$C$19,0,0,1,$D$14))=0,"",SUM(OFFSET('毎月の実績入力'!$C$19,0,0,1,$D$14)))) | H27: {=IFERROR(LET(s,IFERROR(MATCH(TRUE,INDEX('はじめに入力'!$C$38:$N$38>0,0),0),""),IF(OR($D$14="",s="",$D$14<s),"",IF(INDEX('毎月の実績入力'!$C$16:$N$16,$D$14)="","",SUM(OFFSET('毎月の実績入力'!$C$20,0,s-1,1,$D$14-s+1))+SUM(OFFSET('はじめに入力'!$C$41,0,s-1,1,$D$14-s+1))))),"")} | I27: =IF(H27="","",IFERROR(H27/B27,"―")) | J27: {=IFERROR(IF(H27="","",LET(s,IFERROR(MATCH(TRUE,INDEX('はじめに入力'!$C$38:$N$38>0,0),0),""),IF(SUM(OFFSET('毎月の実績入力'!$C$20,0,s-1,1,$D$14-s+1))=0,"費用なし",IF(OR(I27="―",I27>'はじめに入力'!$I$7),"上限超え","上限内")))),"")} | K27: {=IFERROR(IF(H27="","",LET(s,IFERROR(MATCH(TRUE,INDEX('はじめに入力'!$C$38:$N$38>0,0),0),""),IF($D$14<s+6,"判定前",IF(J27="費用なし","判定しない",IF(AND(J27="上限超え",C27<0.9),"撤退を検討","なし"))))),"")}
A28: セミナー | B28: {=IFERROR(IF(H28="","",LET(s,IFERROR(MATCH(TRUE,INDEX('はじめに入力'!$C$44:$N$44>0,0),0),""),SUM(OFFSET('毎月の実績入力'!$C$24,0,s-1,1,$D$14-s+1)))),"")} | C28: {=IFERROR(IF(H28="","",LET(s,IFERROR(MATCH(TRUE,INDEX('はじめに入力'!$C$44:$N$44>0,0),0),""),IFERROR(B28/SUM(OFFSET('はじめに入力'!$C$44,0,s-1,1,$D$14-s+1)),""))),"")} | D28: {=IFERROR(IF(H28="","",LET(s,IFERROR(MATCH(TRUE,INDEX('はじめに入力'!$C$44:$N$44>0,0),0),""),SUM(OFFSET('毎月の実績入力'!$C$25,0,s-1,1,$D$14-s+1)))),"")} | E28: {=IFERROR(IF(H28="","",LET(s,IFERROR(MATCH(TRUE,INDEX('はじめに入力'!$C$44:$N$44>0,0),0),""),IFERROR(D28/SUM(OFFSET('はじめに入力'!$C$45,0,s-1,1,$D$14-s+1)),""))),"")} | F28: =IF($D$14="","",IF(COUNT(OFFSET('毎月の実績入力'!$C$26,0,0,1,$D$14))=0,"",SUM(OFFSET('毎月の実績入力'!$C$26,0,0,1,$D$14)))) | G28: =IF($D$14="","",IF(COUNT(OFFSET('毎月の実績入力'!$C$27,0,0,1,$D$14))=0,"",SUM(OFFSET('毎月の実績入力'!$C$27,0,0,1,$D$14)))) | H28: {=IFERROR(LET(s,IFERROR(MATCH(TRUE,INDEX('はじめに入力'!$C$44:$N$44>0,0),0),""),IF(OR($D$14="",s="",$D$14<s),"",IF(INDEX('毎月の実績入力'!$C$24:$N$24,$D$14)="","",SUM(OFFSET('毎月の実績入力'!$C$28,0,s-1,1,$D$14-s+1))+SUM(OFFSET('はじめに入力'!$C$47,0,s-1,1,$D$14-s+1))))),"")} | I28: =IF(H28="","",IFERROR(H28/B28,"―")) | J28: {=IFERROR(IF(H28="","",LET(s,IFERROR(MATCH(TRUE,INDEX('はじめに入力'!$C$44:$N$44>0,0),0),""),IF(SUM(OFFSET('毎月の実績入力'!$C$28,0,s-1,1,$D$14-s+1))=0,"費用なし",IF(OR(I28="―",I28>'はじめに入力'!$I$7),"上限超え","上限内")))),"")} | K28: {=IFERROR(IF(H28="","",LET(s,IFERROR(MATCH(TRUE,INDEX('はじめに入力'!$C$44:$N$44>0,0),0),""),IF($D$14<s+6,"判定前",IF(J28="費用なし","判定しない",IF(AND(J28="上限超え",C28<0.9),"撤退を検討","なし"))))),"")}
A29: Web広告 | B29: {=IFERROR(IF(H29="","",LET(s,IFERROR(MATCH(TRUE,INDEX('はじめに入力'!$C$50:$N$50>0,0),0),""),SUM(OFFSET('毎月の実績入力'!$C$32,0,s-1,1,$D$14-s+1)))),"")} | C29: {=IFERROR(IF(H29="","",LET(s,IFERROR(MATCH(TRUE,INDEX('はじめに入力'!$C$50:$N$50>0,0),0),""),IFERROR(B29/SUM(OFFSET('はじめに入力'!$C$50,0,s-1,1,$D$14-s+1)),""))),"")} | D29: {=IFERROR(IF(H29="","",LET(s,IFERROR(MATCH(TRUE,INDEX('はじめに入力'!$C$50:$N$50>0,0),0),""),SUM(OFFSET('毎月の実績入力'!$C$33,0,s-1,1,$D$14-s+1)))),"")} | E29: {=IFERROR(IF(H29="","",LET(s,IFERROR(MATCH(TRUE,INDEX('はじめに入力'!$C$50:$N$50>0,0),0),""),IFERROR(D29/SUM(OFFSET('はじめに入力'!$C$51,0,s-1,1,$D$14-s+1)),""))),"")} | F29: =IF($D$14="","",IF(COUNT(OFFSET('毎月の実績入力'!$C$34,0,0,1,$D$14))=0,"",SUM(OFFSET('毎月の実績入力'!$C$34,0,0,1,$D$14)))) | G29: =IF($D$14="","",IF(COUNT(OFFSET('毎月の実績入力'!$C$35,0,0,1,$D$14))=0,"",SUM(OFFSET('毎月の実績入力'!$C$35,0,0,1,$D$14)))) | H29: {=IFERROR(LET(s,IFERROR(MATCH(TRUE,INDEX('はじめに入力'!$C$50:$N$50>0,0),0),""),IF(OR($D$14="",s="",$D$14<s),"",IF(INDEX('毎月の実績入力'!$C$32:$N$32,$D$14)="","",SUM(OFFSET('毎月の実績入力'!$C$36,0,s-1,1,$D$14-s+1))+SUM(OFFSET('はじめに入力'!$C$53,0,s-1,1,$D$14-s+1))))),"")} | I29: =IF(H29="","",IFERROR(H29/B29,"―")) | J29: {=IFERROR(IF(H29="","",LET(s,IFERROR(MATCH(TRUE,INDEX('はじめに入力'!$C$50:$N$50>0,0),0),""),IF(SUM(OFFSET('毎月の実績入力'!$C$36,0,s-1,1,$D$14-s+1))=0,"費用なし",IF(OR(I29="―",I29>'はじめに入力'!$I$7),"上限超え","上限内")))),"")} | K29: {=IFERROR(IF(H29="","",LET(s,IFERROR(MATCH(TRUE,INDEX('はじめに入力'!$C$50:$N$50>0,0),0),""),IF($D$14<s+6,"判定前",IF(J29="費用なし","判定しない",IF(AND(J29="上限超え",C29<0.9),"撤退を検討","なし"))))),"")}
A30: 自社サイト | B30: {=IFERROR(IF(H30="","",LET(s,IFERROR(MATCH(TRUE,INDEX('はじめに入力'!$C$56:$N$56>0,0),0),""),SUM(OFFSET('毎月の実績入力'!$C$40,0,s-1,1,$D$14-s+1)))),"")} | C30: {=IFERROR(IF(H30="","",LET(s,IFERROR(MATCH(TRUE,INDEX('はじめに入力'!$C$56:$N$56>0,0),0),""),IFERROR(B30/SUM(OFFSET('はじめに入力'!$C$56,0,s-1,1,$D$14-s+1)),""))),"")} | D30: {=IFERROR(IF(H30="","",LET(s,IFERROR(MATCH(TRUE,INDEX('はじめに入力'!$C$56:$N$56>0,0),0),""),SUM(OFFSET('毎月の実績入力'!$C$41,0,s-1,1,$D$14-s+1)))),"")} | E30: {=IFERROR(IF(H30="","",LET(s,IFERROR(MATCH(TRUE,INDEX('はじめに入力'!$C$56:$N$56>0,0),0),""),IFERROR(D30/SUM(OFFSET('はじめに入力'!$C$57,0,s-1,1,$D$14-s+1)),""))),"")} | F30: =IF($D$14="","",IF(COUNT(OFFSET('毎月の実績入力'!$C$42,0,0,1,$D$14))=0,"",SUM(OFFSET('毎月の実績入力'!$C$42,0,0,1,$D$14)))) | G30: =IF($D$14="","",IF(COUNT(OFFSET('毎月の実績入力'!$C$43,0,0,1,$D$14))=0,"",SUM(OFFSET('毎月の実績入力'!$C$43,0,0,1,$D$14)))) | H30: {=IFERROR(LET(s,IFERROR(MATCH(TRUE,INDEX('はじめに入力'!$C$56:$N$56>0,0),0),""),IF(OR($D$14="",s="",$D$14<s),"",IF(INDEX('毎月の実績入力'!$C$40:$N$40,$D$14)="","",SUM(OFFSET('毎月の実績入力'!$C$44,0,s-1,1,$D$14-s+1))+SUM(OFFSET('はじめに入力'!$C$59,0,s-1,1,$D$14-s+1))))),"")} | I30: =IF(H30="","",IFERROR(H30/B30,"―")) | J30: {=IFERROR(IF(H30="","",LET(s,IFERROR(MATCH(TRUE,INDEX('はじめに入力'!$C$56:$N$56>0,0),0),""),IF(SUM(OFFSET('毎月の実績入力'!$C$44,0,s-1,1,$D$14-s+1))=0,"費用なし",IF(OR(I30="―",I30>'はじめに入力'!$I$7),"上限超え","上限内")))),"")} | K30: {=IFERROR(IF(H30="","",LET(s,IFERROR(MATCH(TRUE,INDEX('はじめに入力'!$C$56:$N$56>0,0),0),""),IF($D$14<s+6,"判定前",IF(J30="費用なし","判定しない",IF(AND(J30="上限超え",C30<0.9),"撤退を検討","なし"))))),"")}
A31: SNS | B31: {=IFERROR(IF(H31="","",LET(s,IFERROR(MATCH(TRUE,INDEX('はじめに入力'!$C$62:$N$62>0,0),0),""),SUM(OFFSET('毎月の実績入力'!$C$48,0,s-1,1,$D$14-s+1)))),"")} | C31: {=IFERROR(IF(H31="","",LET(s,IFERROR(MATCH(TRUE,INDEX('はじめに入力'!$C$62:$N$62>0,0),0),""),IFERROR(B31/SUM(OFFSET('はじめに入力'!$C$62,0,s-1,1,$D$14-s+1)),""))),"")} | D31: {=IFERROR(IF(H31="","",LET(s,IFERROR(MATCH(TRUE,INDEX('はじめに入力'!$C$62:$N$62>0,0),0),""),SUM(OFFSET('毎月の実績入力'!$C$49,0,s-1,1,$D$14-s+1)))),"")} | E31: {=IFERROR(IF(H31="","",LET(s,IFERROR(MATCH(TRUE,INDEX('はじめに入力'!$C$62:$N$62>0,0),0),""),IFERROR(D31/SUM(OFFSET('はじめに入力'!$C$63,0,s-1,1,$D$14-s+1)),""))),"")} | F31: =IF($D$14="","",IF(COUNT(OFFSET('毎月の実績入力'!$C$50,0,0,1,$D$14))=0,"",SUM(OFFSET('毎月の実績入力'!$C$50,0,0,1,$D$14)))) | G31: =IF($D$14="","",IF(COUNT(OFFSET('毎月の実績入力'!$C$51,0,0,1,$D$14))=0,"",SUM(OFFSET('毎月の実績入力'!$C$51,0,0,1,$D$14)))) | H31: {=IFERROR(LET(s,IFERROR(MATCH(TRUE,INDEX('はじめに入力'!$C$62:$N$62>0,0),0),""),IF(OR($D$14="",s="",$D$14<s),"",IF(INDEX('毎月の実績入力'!$C$48:$N$48,$D$14)="","",SUM(OFFSET('毎月の実績入力'!$C$52,0,s-1,1,$D$14-s+1))+SUM(OFFSET('はじめに入力'!$C$65,0,s-1,1,$D$14-s+1))))),"")} | I31: =IF(H31="","",IFERROR(H31/B31,"―")) | J31: {=IFERROR(IF(H31="","",LET(s,IFERROR(MATCH(TRUE,INDEX('はじめに入力'!$C$62:$N$62>0,0),0),""),IF(SUM(OFFSET('毎月の実績入力'!$C$52,0,s-1,1,$D$14-s+1))=0,"費用なし",IF(OR(I31="―",I31>'はじめに入力'!$I$7),"上限超え","上限内")))),"")} | K31: {=IFERROR(IF(H31="","",LET(s,IFERROR(MATCH(TRUE,INDEX('はじめに入力'!$C$62:$N$62>0,0),0),""),IF($D$14<s+6,"判定前",IF(J31="費用なし","判定しない",IF(AND(J31="上限超え",C31<0.9),"撤退を検討","なし"))))),"")}
A32: メール | B32: {=IFERROR(IF(H32="","",LET(s,IFERROR(MATCH(TRUE,INDEX('はじめに入力'!$C$68:$N$68>0,0),0),""),SUM(OFFSET('毎月の実績入力'!$C$56,0,s-1,1,$D$14-s+1)))),"")} | C32: {=IFERROR(IF(H32="","",LET(s,IFERROR(MATCH(TRUE,INDEX('はじめに入力'!$C$68:$N$68>0,0),0),""),IFERROR(B32/SUM(OFFSET('はじめに入力'!$C$68,0,s-1,1,$D$14-s+1)),""))),"")} | D32: {=IFERROR(IF(H32="","",LET(s,IFERROR(MATCH(TRUE,INDEX('はじめに入力'!$C$68:$N$68>0,0),0),""),SUM(OFFSET('毎月の実績入力'!$C$57,0,s-1,1,$D$14-s+1)))),"")} | E32: {=IFERROR(IF(H32="","",LET(s,IFERROR(MATCH(TRUE,INDEX('はじめに入力'!$C$68:$N$68>0,0),0),""),IFERROR(D32/SUM(OFFSET('はじめに入力'!$C$69,0,s-1,1,$D$14-s+1)),""))),"")} | F32: =IF($D$14="","",IF(COUNT(OFFSET('毎月の実績入力'!$C$58,0,0,1,$D$14))=0,"",SUM(OFFSET('毎月の実績入力'!$C$58,0,0,1,$D$14)))) | G32: =IF($D$14="","",IF(COUNT(OFFSET('毎月の実績入力'!$C$59,0,0,1,$D$14))=0,"",SUM(OFFSET('毎月の実績入力'!$C$59,0,0,1,$D$14)))) | H32: {=IFERROR(LET(s,IFERROR(MATCH(TRUE,INDEX('はじめに入力'!$C$68:$N$68>0,0),0),""),IF(OR($D$14="",s="",$D$14<s),"",IF(INDEX('毎月の実績入力'!$C$56:$N$56,$D$14)="","",SUM(OFFSET('毎月の実績入力'!$C$60,0,s-1,1,$D$14-s+1))+SUM(OFFSET('はじめに入力'!$C$71,0,s-1,1,$D$14-s+1))))),"")} | I32: =IF(H32="","",IFERROR(H32/B32,"―")) | J32: {=IFERROR(IF(H32="","",LET(s,IFERROR(MATCH(TRUE,INDEX('はじめに入力'!$C$68:$N$68>0,0),0),""),IF(SUM(OFFSET('毎月の実績入力'!$C$60,0,s-1,1,$D$14-s+1))=0,"費用なし",IF(OR(I32="―",I32>'はじめに入力'!$I$7),"上限超え","上限内")))),"")} | K32: {=IFERROR(IF(H32="","",LET(s,IFERROR(MATCH(TRUE,INDEX('はじめに入力'!$C$68:$N$68>0,0),0),""),IF($D$14<s+6,"判定前",IF(J32="費用なし","判定しない",IF(AND(J32="上限超え",C32<0.9),"撤退を検討","なし"))))),"")}
A33: 開始月＝「はじめに入力」でそのチャネルの計画のリード数を最初に入れた月。リード数・有効リード数・費用は開始月から対象月までの累計、費用＝外部費用＋人件費、達成率＝実績÷計画。商談数・受注数は期首から対象月までの実績（チャネル別の計画はないため実績のみ）。判定＝累計のCPLが許容CPL以下なら「上限内」、超えたら「上限超え」。撤退の判断＝開始月＋6か月から、「上限超え」かつリード数の達成率が90%未満なら「撤退を検討」。外部費用を入れていないチャネルは判定しない
A35: 4. 課題と打ち手の選定
A36: 「5.打ち手の候補一覧」で選定月を選んだ打ち手と、施策ログに対象月で登録した打ち手が出ます。
A37: 指標 | B37: チャネル | C37: 課題 | F37: 打ち手 | K37: 実施月 | L37: 根拠 | M37: 状態 | Z37: （計算用）4.の表示
A38: =IFERROR(INDEX($Z$38:$AF$89,ROW()-37,1)&"","") | B38: =IFERROR(INDEX($Z$38:$AF$89,ROW()-37,2)&"","") | C38: =IFERROR(INDEX($Z$38:$AF$89,ROW()-37,3)&"","") | F38: =IFERROR(INDEX($Z$38:$AF$89,ROW()-37,4)&"","") | K38: =IFERROR(INDEX($Z$38:$AF$89,ROW()-37,5)&"","") | L38: =IFERROR(INDEX($Z$38:$AF$89,ROW()-37,6)&"","") | M38: =IFERROR(INDEX($Z$38:$AF$89,ROW()-37,7)&"","") | Z38: =IFERROR(__xludf.DUMMYFUNCTION("IFERROR(LET(m,$B$14,a,IFERROR(FILTER(HSTACK('施策ログ'!$B$5:$B$198,'施策ログ'!$C$5:$C$198,'施策ログ'!$D$5:$D$198,'施策ログ'!$G$5:$G$198,'施策ログ'!$L$5:$L$198,'施策ログ'!$M$5:$M$198,IF('施策ログ'!$A$5:$A$198=m,""登録済み"","""")),'施策ログ'!$A$5:$A$198=m,'施策ログ'!$G$5:$G$198<>""""),{"""","""""&","""","""","""","""",""""}),b,IFERROR(FILTER(HSTACK($A$53:$A$82,$B$53:$B$82,$C$53:$C$82,$F$53:$F$82,$M$53:$M$82,$L$53:$L$82,IF($K$53:$K$82=m,""未登録"","""")),$K$53:$K$82=m,$F$53:$F$82<>"""",COUNTIFS('施策ログ'!$A$5:$A$198,m,'施策ログ'!$G$5:$G$198,$F$53:$F$82)=0),{"&""""","""","""","""","""","""",""""}),v,VSTACK(a,b),FILTER(v,CHOOSECOLS(v,4)<>"""")),"""")"),"受注率") | AA38: =IFERROR(__xludf.DUMMYFUNCTION("""COMPUTED_VALUE"""),"全体") | AB38: =IFERROR(__xludf.DUMMYFUNCTION("""COMPUTED_VALUE"""),"商談で使う事例・サポートの資料が足りない") | AC38: =IFERROR(__xludf.DUMMYFUNCTION("""COMPUTED_VALUE"""),"導入事例とサポート体制の資料をマーケが営業に用意する") | AD38: =IFERROR(__xludf.DUMMYFUNCTION("""COMPUTED_VALUE"""),"10月") | AE38: =IFERROR(__xludf.DUMMYFUNCTION("""COMPUTED_VALUE"""),"9月まで：受注率20%（計画29%）") | AF38: =IFERROR(__xludf.DUMMYFUNCTION("""COMPUTED_VALUE"""),"登録済み")
A39: =IFERROR(INDEX($Z$38:$AF$89,ROW()-37,1)&"","") | B39: =IFERROR(INDEX($Z$38:$AF$89,ROW()-37,2)&"","") | C39: =IFERROR(INDEX($Z$38:$AF$89,ROW()-37,3)&"","") | F39: =IFERROR(INDEX($Z$38:$AF$89,ROW()-37,4)&"","") | K39: =IFERROR(INDEX($Z$38:$AF$89,ROW()-37,5)&"","") | L39: =IFERROR(INDEX($Z$38:$AF$89,ROW()-37,6)&"","") | M39: =IFERROR(INDEX($Z$38:$AF$89,ROW()-37,7)&"","") | Z39: =IFERROR(__xludf.DUMMYFUNCTION("""COMPUTED_VALUE"""),"リード数") | AA39: =IFERROR(__xludf.DUMMYFUNCTION("""COMPUTED_VALUE"""),"メール") | AB39: =IFERROR(__xludf.DUMMYFUNCTION("""COMPUTED_VALUE"""),"接点のあった人が配信リストに入っていない") | AC39: =IFERROR(__xludf.DUMMYFUNCTION("""COMPUTED_VALUE"""),"名刺交換・展示会・セミナー・資料DLで接点を持った人を法律に沿ってリストに入れ、フォームに配信の同意欄を置く") | AD39: =IFERROR(__xludf.DUMMYFUNCTION("""COMPUTED_VALUE"""),"10月") | AE39: =IFERROR(__xludf.DUMMYFUNCTION("""COMPUTED_VALUE"""),"9月まで：実績8件（計画9件・達成率89%）") | AF39: =IFERROR(__xludf.DUMMYFUNCTION("""COMPUTED_VALUE"""),"登録済み")
A40: =IFERROR(INDEX($Z$38:$AF$89,ROW()-37,1)&"","") | B40: =IFERROR(INDEX($Z$38:$AF$89,ROW()-37,2)&"","") | C40: =IFERROR(INDEX($Z$38:$AF$89,ROW()-37,3)&"","") | F40: =IFERROR(INDEX($Z$38:$AF$89,ROW()-37,4)&"","") | K40: =IFERROR(INDEX($Z$38:$AF$89,ROW()-37,5)&"","") | L40: =IFERROR(INDEX($Z$38:$AF$89,ROW()-37,6)&"","") | M40: =IFERROR(INDEX($Z$38:$AF$89,ROW()-37,7)&"","") | Z40: =IFERROR(__xludf.DUMMYFUNCTION("""COMPUTED_VALUE"""),"リード数") | AA40: =IFERROR(__xludf.DUMMYFUNCTION("""COMPUTED_VALUE"""),"展示会") | AB40: =IFERROR(__xludf.DUMMYFUNCTION("""COMPUTED_VALUE"""),"ブースで売り込みが強く、質問に答えられる人がいない") | AC40: =IFERROR(__xludf.DUMMYFUNCTION("""COMPUTED_VALUE"""),"質問に答えられる技術者を立て、導入事例を見せる") | AD40: =IFERROR(__xludf.DUMMYFUNCTION("""COMPUTED_VALUE"""),"2月") | AE40: =IFERROR(__xludf.DUMMYFUNCTION("""COMPUTED_VALUE"""),"9月まで：実績92件（計画110件・達成率84%）") | AF40: =IFERROR(__xludf.DUMMYFUNCTION("""COMPUTED_VALUE"""),"登録済み")
A41: =IFERROR(INDEX($Z$38:$AF$89,ROW()-37,1)&"","") | B41: =IFERROR(INDEX($Z$38:$AF$89,ROW()-37,2)&"","") | C41: =IFERROR(INDEX($Z$38:$AF$89,ROW()-37,3)&"","") | F41: =IFERROR(INDEX($Z$38:$AF$89,ROW()-37,4)&"","") | K41: =IFERROR(INDEX($Z$38:$AF$89,ROW()-37,5)&"","") | L41: =IFERROR(INDEX($Z$38:$AF$89,ROW()-37,6)&"","") | M41: =IFERROR(INDEX($Z$38:$AF$89,ROW()-37,7)&"","")
A42: =IFERROR(INDEX($Z$38:$AF$89,ROW()-37,1)&"","") | B42: =IFERROR(INDEX($Z$38:$AF$89,ROW()-37,2)&"","") | C42: =IFERROR(INDEX($Z$38:$AF$89,ROW()-37,3)&"","") | F42: =IFERROR(INDEX($Z$38:$AF$89,ROW()-37,4)&"","") | K42: =IFERROR(INDEX($Z$38:$AF$89,ROW()-37,5)&"","") | L42: =IFERROR(INDEX($Z$38:$AF$89,ROW()-37,6)&"","") | M42: =IFERROR(INDEX($Z$38:$AF$89,ROW()-37,7)&"","")
A43: =IFERROR(INDEX($Z$38:$AF$89,ROW()-37,1)&"","") | B43: =IFERROR(INDEX($Z$38:$AF$89,ROW()-37,2)&"","") | C43: =IFERROR(INDEX($Z$38:$AF$89,ROW()-37,3)&"","") | F43: =IFERROR(INDEX($Z$38:$AF$89,ROW()-37,4)&"","") | K43: =IFERROR(INDEX($Z$38:$AF$89,ROW()-37,5)&"","") | L43: =IFERROR(INDEX($Z$38:$AF$89,ROW()-37,6)&"","") | M43: =IFERROR(INDEX($Z$38:$AF$89,ROW()-37,7)&"","")
...

Sheet 施策ログ
A1: KPI管理表 施策ログ | D1: 水色＝入力 単位：時間
A3: 1. 施策ログの入力
A4: 登録月 | B4: 狙う指標 | C4: チャネル | D4: 課題 | G4: 打ち手 | L4: 実施月 | M4: 根拠 | N4: 状態 | O4: 見込み時間 | P4: 振り返り

Sheet 月次レポート
A1: ="マーケティング月次報告 "&$J$1 | I1: 対象月 | J1: 10月 | K1: =$N$2&"か月目" | L1: 単位：件 | M1: （計算用） | R1: （計算用）チャネル | S1: 狙う指標 | T1: 達成率 | U1: 課題 | V1: 判定
M2: 経過月数 | N2: =IFERROR(MATCH($J$1,'毎月の実績入力'!$C$4:$N$4,0),"") | R2: =$A32 | S2: リード数 | T2: =IF(ISNUMBER($C32),$C32,"") | U2: =IF(OR(T2="",T2>=1),"",$A32&"のリード数が計画を下回っている（達成率"&TEXT(T2,"0%")&"）") | V2: =IF(T2="","",IF(T2>=1,"達成",IF(T2>=0.9,"やや届かない","届かない")))
A3: 1. 結論 | M3: 平均受注単価 | N3: ='はじめに入力'!$C$7 | R3: =$A33 | S3: リード数 | T3: =IF(ISNUMBER($C33),$C33,"") | U3: =IF(OR(T3="",T3>=1),"",$A33&"のリード数が計画を下回っている（達成率"&TEXT(T3,"0%")&"）") | V3: =IF(T3="","",IF(T3>=1,"達成",IF(T3>=0.9,"やや届かない","届かない")))
R4: =$A34 | S4: リード数 | T4: =IF(ISNUMBER($C34),$C34,"") | U4: =IF(OR(T4="",T4>=1),"",$A34&"のリード数が計画を下回っている（達成率"&TEXT(T4,"0%")&"）") | V4: =IF(T4="","",IF(T4>=1,"達成",IF(T4>=0.9,"やや届かない","届かない")))
A5: ［実績］期首からの受注 | D5: 年間目標 | F5: 達成率 | M5: リードタイム | N5: ='はじめに入力'!$F$7 | R5: =$A35 | S5: リード数 | T5: =IF(ISNUMBER($C35),$C35,"") | U5: =IF(OR(T5="",T5>=1),"",$A35&"のリード数が計画を下回っている（達成率"&TEXT(T5,"0%")&"）") | V5: =IF(T5="","",IF(T5>=1,"達成",IF(T5>=0.9,"やや届かない","届かない")))
A6: =$N$7 | D6: ='はじめに入力'!$H$17 | F6: =IFERROR($N$7/'はじめに入力'!$H$17,"—") | M6: 累計の商談数 | N6: =SUM(OFFSET('毎月の実績入力'!$C$7,0,0,1,N2)) | R6: =$A36 | S6: リード数 | T6: =IF(ISNUMBER($C36),$C36,"") | U6: =IF(OR(T6="",T6>=1),"",$A36&"のリード数が計画を下回っている（達成率"&TEXT(T6,"0%")&"）") | V6: =IF(T6="","",IF(T6>=1,"達成",IF(T6>=0.9,"やや届かない","届かない")))
A7: ［見込み］期末の着地見込み | D7: 計画比 | F7: 不足 | M7: 累計の受注数 | N7: =SUM(OFFSET('毎月の実績入力'!$C$8,0,0,1,N2)) | R7: =$A37 | S7: リード数 | T7: =IF(ISNUMBER($C37),$C37,"") | U7: =IF(OR(T7="",T7>=1),"",$A37&"のリード数が計画を下回っている（達成率"&TEXT(T7,"0%")&"）") | V7: =IF(T7="","",IF(T7>=1,"達成",IF(T7>=0.9,"やや届かない","届かない")))
A8: =IFERROR($N$12/$N$3,0) | C8: =IFERROR(IF($N$12/$N$14>=1,"届く",IF($N$12/$N$14>=0.9,"やや届かない","届かない")),"") | D8: =IFERROR($N$12/$N$14,"—") | F8: =MAX(0,ROUNDUP('はじめに入力'!$H$17-$N$12/$N$3,0)) | M8: 受注済み | N8: =N7*N3 | R8: =$A32 | S8: 有効リード率 | T8: =IF(AND(ISNUMBER($C32),ISNUMBER($E32)),IFERROR($E32/$C32,""),"") | U8: =IF(OR(T8="",T8>=1),"",$A32&"の有効リード率が計画を下回っている（達成率"&TEXT(T8,"0%")&"）") | V8: =IF(T8="","",IF(T8>=1,"達成",IF(T8>=0.9,"やや届かない","届かない")))
A9: =IFERROR(__xludf.DUMMYFUNCTION("IFERROR(SPARKLINE({MIN($N$12/$N$3,'はじめに入力'!$H$17),MAX(0,'はじめに入力'!$H$17-$N$12/$N$3)},{""charttype"",""bar"";""max"",MAX('はじめに入力'!$H$17,$N$12/$N$3);""color1"",""#ffffff"";""color2"",""#e06666""}),"""")"),"") | M9: 進行中の商談 | N9: =MAX(0,N6-N7) | R9: =$A33 | S9: 有効リード率 | T9: =IF(AND(ISNUMBER($C33),ISNUMBER($E33)),IFERROR($E33/$C33,""),"") | U9: =IF(OR(T9="",T9>=1),"",$A33&"の有効リード率が計画を下回っている（達成率"&TEXT(T9,"0%")&"）") | V9: =IF(T9="","",IF(T9>=1,"達成",IF(T9>=0.9,"やや届かない","届かない")))
A10: =IF($N$15<=0,"着地見込みは年間目標に届いています",IF($N$16<=$N$2,"期内の挽回は難しく、不足分は来期の計画で扱います",$N$17&"までにリード＋"&$N$19&"件（商談＋"&$N$18&"件）で間に合う")) | M10: 進行中×受注率 | N10: =N9*'はじめに入力'!$G$17*N3 | R10: =$A34 | S10: 有効リード率 | T10: =IF(AND(ISNUMBER($C34),ISNUMBER($E34)),IFERROR($E34/$C34,""),"") | U10: =IF(OR(T10="",T10>=1),"",$A34&"の有効リード率が計画を下回っている（達成率"&TEXT(T10,"0%")&"）") | V10: =IF(T10="","",IF(T10>=1,"達成",IF(T10>=0.9,"やや届かない","届かない")))
M11: 期内に受注できる新規分 | N11: =SUMPRODUCT((COLUMN('はじめに入力'!$C$32:$N$32)-COLUMN('はじめに入力'!$C$32)+1>N2)*(COLUMN('はじめに入力'!$C$32:$N$32)-COLUMN('はじめに入力'!$C$32)+1+N5<=12)*'はじめに入力'!$C$32:$N$32)*'はじめに入力'!$E$17*'はじめに入力'!$G$17*N3 | R11: =$A35 | S11: 有効リード率 | T11: =IF(AND(ISNUMBER($C35),ISNUMBER($E35)),IFERROR($E35/$C35,""),"") | U11: =IF(OR(T11="",T11>=1),"",$A35&"の有効リード率が計画を下回っている（達成率"&TEXT(T11,"0%")&"）") | V11: =IF(T11="","",IF(T11>=1,"達成",IF(T11>=0.9,"やや届かない","届かない")))
A12: 2. KPI | M12: 着地見込み | N12: =N8+N10+N11 | R12: =$A36 | S12: 有効リード率 | T12: =IF(AND(ISNUMBER($C36),ISNUMBER($E36)),IFERROR($E36/$C36,""),"") | U12: =IF(OR(T12="",T12>=1),"",$A36&"の有効リード率が計画を下回っている（達成率"&TEXT(T12,"0%")&"）") | V12: =IF(T12="","",IF(T12>=1,"達成",IF(T12>=0.9,"やや届かない","届かない")))
R13: =$A37 | S13: 有効リード率 | T13: =IF(AND(ISNUMBER($C37),ISNUMBER($E37)),IFERROR($E37/$C37,""),"") | U13: =IF(OR(T13="",T13>=1),"",$A37&"の有効リード率が計画を下回っている（達成率"&TEXT(T13,"0%")&"）") | V13: =IF(T13="","",IF(T13>=1,"達成",IF(T13>=0.9,"やや届かない","届かない")))
A14: ="今月（"&$J$1&"）の動き 計画比・前月比" | M14: 年間目標 | N14: ='はじめに入力'!$B$7 | R14: =$A32 | S14: CPL | T14: =IF($G32="上限超え",IF(ISNUMBER($F32),'はじめに入力'!$I$7/$F32,0),"") | U14: =IF(OR(T14="",T14>=1),"",$A32&"のCPLが許容CPLを超えている（"&IF(ISNUMBER($F32),TEXT($F32,"0.0"),"リードなし")&"／許容"&TEXT('はじめに入力'!$I$7,"0.0")&"）") | V14: =IF(T14="","","上限超え")
A15: 新規リード | D15: 有効リード | G15: 新規商談 | J15: 受注 | M15: 計画まで | N15: =MAX(0,N14-N12) | R15: =$A33 | S15: CPL | T15: =IF($G33="上限超え",IF(ISNUMBER($F33),'はじめに入力'!$I$7/$F33,0),"") | U15: =IF(OR(T15="",T15>=1),"",$A33&"のCPLが許容CPLを超えている（"&IF(ISNUMBER($F33),TEXT($F33,"0.0"),"リードなし")&"／許容"&TEXT('はじめに入力'!$I$7,"0.0")&"）") | V15: =IF(T15="","","上限超え")
A16: {=INDEX('毎月の実績入力'!$C$5:$N$5,$N$2)} | D16: {=INDEX('毎月の実績入力'!$C$6:$N$6,$N$2)} | G16: {=INDEX('毎月の実績入力'!$C$7:$N$7,$N$2)} | J16: {=INDEX('毎月の実績入力'!$C$8:$N$8,$N$2)} | M16: 期限の月（番号） | N16: =12-N5 | R16: =$A34 | S16: CPL | T16: =IF($G34="上限超え",IF(ISNUMBER($F34),'はじめに入力'!$I$7/$F34,0),"") | U16: =IF(OR(T16="",T16>=1),"",$A34&"のCPLが許容CPLを超えている（"&IF(ISNUMBER($F34),TEXT($F34,"0.0"),"リードなし")&"／許容"&TEXT('はじめに入力'!$I$7,"0.0")&"）") | V16: =IF(T16="","","上限超え")
A17: {="計画比 "&IFERROR(TEXT(A16/INDEX('はじめに入力'!$C$31:$N$31,$N$2),"0%"),"—")&"・前月比 "&IF($N$2<2,"—",IFERROR(TEXT(A16/INDEX('毎月の実績入力'!$C$5:$N$5,$N$2-1)-1,"+0%;-0%;±0%"),"—"))} | D17: {="計画比 "&IFERROR(TEXT(D16/INDEX('はじめに入力'!$C$32:$N$32,$N$2),"0%"),"—")&"・前月比 "&IF($N$2<2,"—",IFERROR(TEXT(D16/INDEX('毎月の実績入力'!$C$6:$N$6,$N$2-1)-1,"+0%;-0%;±0%"),"—"))} | G17: {="前月比 "&IF($N$2<2,"—",IFERROR(TEXT(G16/INDEX('毎月の実績入力'!$C$7:$N$7,$N$2-1)-1,"+0%;-0%;±0%"),"—"))} | J17: {="前月比 "&IF($N$2<2,"—",IFERROR(TEXT(J16/INDEX('毎月の実績入力'!$C$8:$N$8,$N$2-1)-1,"+0%;-0%;±0%"),"—"))} | M17: 期限の月 | N17: {=IF(N16<1,"",INDEX('毎月の実績入力'!$C$4:$N$4,N16))} | R17: =$A35 | S17: CPL | T17: =IF($G35="上限超え",IF(ISNUMBER($F35),'はじめに入力'!$I$7/$F35,0),"") | U17: =IF(OR(T17="",T17>=1),"",$A35&"のCPLが許容CPLを超えている（"&IF(ISNUMBER($F35),TEXT($F35,"0.0"),"リードなし")&"／許容"&TEXT('はじめに入力'!$I$7,"0.0")&"）") | V17: =IF(T17="","","上限超え")
M18: 必要な商談 | N18: =IFERROR(ROUNDUP(N15/(N3*'はじめに入力'!$G$17),0),"") | R18: =$A36 | S18: CPL | T18: =IF($G36="上限超え",IF(ISNUMBER($F36),'はじめに入力'!$I$7/$F36,0),"") | U18: =IF(OR(T18="",T18>=1),"",$A36&"のCPLが許容CPLを超えている（"&IF(ISNUMBER($F36),TEXT($F36,"0.0"),"リードなし")&"／許容"&TEXT('はじめに入力'!$I$7,"0.0")&"）") | V18: =IF(T18="","","上限超え")
A19: {="期首からの累計（"&INDEX('毎月の実績入力'!$C$4:$N$4,1)&"〜"&$J$1&"） 棒＝計画に対する達成率（右端が100%）"} | M19: 必要なリード | N19: =IFERROR(ROUNDUP(N18/'はじめに入力'!$E$17/'はじめに入力'!$C$17,0),"") | R19: =$A37 | S19: CPL | T19: =IF($G37="上限超え",IF(ISNUMBER($F37),'はじめに入力'!$I$7/$F37,0),"") | U19: =IF(OR(T19="",T19>=1),"",$A37&"のCPLが許容CPLを超えている（"&IF(ISNUMBER($F37),TEXT($F37,"0.0"),"リードなし")&"／許容"&TEXT('はじめに入力'!$I$7,"0.0")&"）") | V19: =IF(T19="","","上限超え")
A20: 段階 | B20: 実績 | D20: 達成率 | J20: 計画 | M20: 前月（番号） | N20: =N2-1 | R20: 全体 | S20: 商談化率 | T20: =IF(ISNUMBER($B$22),IFERROR($B$22/$J$22,""),"") | U20: =IF(OR(T20="",T20>=1),"","商談化率が計画を下回っている（"&TEXT($B$22,"0%")&"／計画"&TEXT($J$22,"0%")&"）") | V20: =IF(T20="","",IF(T20>=1,"達成",IF(T20>=0.9,"やや届かない","届かない")))
A21: リード数 | B21: =SUM(OFFSET('毎月の実績入力'!$C$5,0,0,1,$N$2)) | D21: =IFERROR(B21/J21,"—") | E21: =IFERROR(__xludf.DUMMYFUNCTION("IF(ISNUMBER(D21),SPARKLINE({MIN(D21,1),1-MIN(D21,1)},{""charttype"",""bar"";""max"",1;""color1"",IF(D21<0.9,""#c62828"",IF(D21<1,""#e08a00"",""#9e9e9e""));""color2"",""#e8e8e8""}),"""")"),"") | J21: =SUM(OFFSET('はじめに入力'!$C$31,0,0,1,$N$2)) | M21: 来月 | N21: {=IF(N2>=12,"",INDEX('毎月の実績入力'!$C$4:$N$4,N2+1))} | R21: 全体 | S21: 受注率 | T21: =IF($N$2<=$N$4,"",IF(ISNUMBER($B$24),IFERROR($B$24/$J$24,""),"")) | U21: =IF(OR(T21="",T21>=1),"","受注率が計画を下回っている（"&TEXT($B$24,"0%")&"／計画"&TEXT($J$24,"0%")&"）") | V21: =IF(T21="","",IF(T21>=1,"達成",IF(T21>=0.9,"やや届かない","届かない")))
A22: 有効リード率 | B22: =IFERROR(B23/B21,"—") | D22: =IFERROR(B22/J22,"—") | E22: =IFERROR(__xludf.DUMMYFUNCTION("IF(ISNUMBER(D22),SPARKLINE({MIN(D22,1),1-MIN(D22,1)},{""charttype"",""bar"";""max"",1;""color1"",IF(D22<0.9,""#c62828"",IF(D22<1,""#e08a00"",""#9e9e9e""));""color2"",""#e8e8e8""}),"""")"),"") | J22: =IFERROR(J23/J21,"—")
A23: 有効リード数 | B23: =SUM(OFFSET('毎月の実績入力'!$C$6,0,0,1,$N$2)) | D23: =IFERROR(B23/J23,"—") | E23: =IFERROR(__xludf.DUMMYFUNCTION("IF(ISNUMBER(D23),SPARKLINE({MIN(D23,1),1-MIN(D23,1)},{""charttype"",""bar"";""max"",1;""color1"",IF(D23<0.9,""#c62828"",IF(D23<1,""#e08a00"",""#9e9e9e""));""color2"",""#e8e8e8""}),"""")"),"") | J23: =SUM(OFFSET('はじめに入力'!$C$32,0,0,1,$N$2)) | M23: 月 | N23: 実績の累計 | O23: 着地見込み | P23: 年間目標 | R23: （計算用）課題の上位3つ
A24: 商談化率 | B24: =IFERROR(B25/B23,"—") | D24: =IFERROR(B24/J24,"—") | E24: =IFERROR(__xludf.DUMMYFUNCTION("IF(ISNUMBER(D24),SPARKLINE({MIN(D24,1),1-MIN(D24,1)},{""charttype"",""bar"";""max"",1;""color1"",IF(D24<0.9,""#c62828"",IF(D24<1,""#e08a00"",""#9e9e9e""));""color2"",""#e8e8e8""}),"""")"),"") | J24: ='はじめに入力'!$E$17 | M24: {=INDEX('毎月の実績入力'!$C$4:$N$4,1)} | N24: =IF(1<=$N$2,SUM(OFFSET('毎月の実績入力'!$C$8,0,0,1,1)),NA()) | O24: =IF(1<$N$2,NA(),IF($N$2>=12,$N$7,($N$8+($N$12-$N$8)*(1-$N$2)/(12-$N$2))/$N$3)) | P24: ='はじめに入力'!$H$17 | R24: =IFERROR(__xludf.DUMMYFUNCTION("IFERROR(SORTN(FILTER(R2:V21,ISNUMBER(T2:T21),T2:T21<1),3,0,3,TRUE),"""")"),"メール") | S24: =IFERROR(__xludf.DUMMYFUNCTION("""COMPUTED_VALUE"""),"CPL") | T24: =IFERROR(__xludf.DUMMYFUNCTION("""COMPUTED_VALUE"""),0.5071754573903197) | U24: =IFERROR(__xludf.DUMMYFUNCTION("""COMPUTED_VALUE"""),"メールのCPLが許容CPLを超えている（13.2／許容6.7）") | V24: =IFERROR(__xludf.DUMMYFUNCTION("""COMPUTED_VALUE"""),"上限超え")
A25: 商談数 | B25: =$N$6 | D25: =IFERROR("進捗"&TEXT(B25/'はじめに入力'!$F$17,"0%"),"—") | E25: =IFERROR(__xludf.DUMMYFUNCTION("IFERROR(SPARKLINE({MIN(B25/'はじめに入力'!$F$17,1),1-MIN(B25/'はじめに入力'!$F$17,1)},{""charttype"",""bar"";""max"",1;""color1"",""#9e9e9e"";""color2"",""#e8e8e8""}),"""")"),"") | J25: ="年"&TEXT('はじめに入力'!$F$17,"#,##0") | M25: {=INDEX('毎月の実績入力'!$C$4:$N$4,2)} | N25: =IF(2<=$N$2,SUM(OFFSET('毎月の実績入力'!$C$8,0,0,1,2)),NA()) | O25: =IF(2<$N$2,NA(),IF($N$2>=12,$N$7,($N$8+($N$12-$N$8)*(2-$N$2)/(12-$N$2))/$N$3)) | P25: ='はじめに入力'!$H$17 | R25: =IFERROR(__xludf.DUMMYFUNCTION("""COMPUTED_VALUE"""),"Web広告") | S25: =IFERROR(__xludf.DUMMYFUNCTION("""COMPUTED_VALUE"""),"有効リード率") | T25: =IFERROR(__xludf.DUMMYFUNCTION("""COMPUTED_VALUE"""),0.6577480490523969) | U25: =IFERROR(__xludf.DUMMYFUNCTION("""COMPUTED_VALUE"""),"Web広告の有効リード率が計画を下回っている（達成率66%）") | V25: =IFERROR(__xludf.DUMMYFUNCTION("""COMPUTED_VALUE"""),"届かない")
A26: 受注率 | B26: =IFERROR(B27/B25,"—") | D26: =IF($N$2<=$N$5,"判定前",IFERROR(B26/J26,"—")) | E26: =IFERROR(__xludf.DUMMYFUNCTION("IF(ISNUMBER(D26),SPARKLINE({MIN(D26,1),1-MIN(D26,1)},{""charttype"",""bar"";""max"",1;""color1"",IF(D26<0.9,""#c62828"",IF(D26<1,""#e08a00"",""#9e9e9e""));""color2"",""#e8e8e8""}),"""")"),"") | J26: ='はじめに入力'!$G$17 | M26: {=INDEX('毎月の実績入力'!$C$4:$N$4,3)} | N26: =IF(3<=$N$2,SUM(OFFSET('毎月の実績入力'!$C$8,0,0,1,3)),NA()) | O26: =IF(3<$N$2,NA(),IF($N$2>=12,$N$7,($N$8+($N$12-$N$8)*(3-$N$2)/(12-$N$2))/$N$3)) | P26: ='はじめに入力'!$H$17 | R26: =IFERROR(__xludf.DUMMYFUNCTION("""COMPUTED_VALUE"""),"メール") | S26: =IFERROR(__xludf.DUMMYFUNCTION("""COMPUTED_VALUE"""),"リード数") | T26: =IFERROR(__xludf.DUMMYFUNCTION("""COMPUTED_VALUE"""),0.8181818181818182) | U26: =IFERROR(__xludf.DUMMYFUNCTION("""COMPUTED_VALUE"""),"メールのリード数が計画を下回っている（達成率82%）") | V26: =IFERROR(__xludf.DUMMYFUNCTION("""COMPUTED_VALUE"""),"届かない")
A27: 受注数 | B27: =$N$7 | D27: =IFERROR("進捗"&TEXT(B27/'はじめに入力'!$H$17,"0%"),"—") | E27: =IFERROR(__xludf.DUMMYFUNCTION("IFERROR(SPARKLINE({MIN(B27/'はじめに入力'!$H$17,1),1-MIN(B27/'はじめに入力'!$H$17,1)},{""charttype"",""bar"";""max"",1;""color1"",""#9e9e9e"";""color2"",""#e8e8e8""}),"""")"),"") | J27: ="年"&TEXT('はじめに入力'!$H$17,"#,##0") | M27: {=INDEX('毎月の実績入力'!$C$4:$N$4,4)} | N27: =IF(4<=$N$2,SUM(OFFSET('毎月の実績入力'!$C$8,0,0,1,4)),NA()) | O27: =IF(4<$N$2,NA(),IF($N$2>=12,$N$7,($N$8+($N$12-$N$8)*(4-$N$2)/(12-$N$2))/$N$3)) | P27: ='はじめに入力'!$H$17
M28: {=INDEX('毎月の実績入力'!$C$4:$N$4,5)} | N28: =IF(5<=$N$2,SUM(OFFSET('毎月の実績入力'!$C$8,0,0,1,5)),NA()) | O28: =IF(5<$N$2,NA(),IF($N$2>=12,$N$7,($N$8+($N$12-$N$8)*(5-$N$2)/(12-$N$2))/$N$3)) | P28: ='はじめに入力'!$H$17
A29: {="3. チャネル別（"&INDEX('毎月の実績入力'!$C$4:$N$4,1)&"〜"&$J$1&"）"} | M29: {=INDEX('毎月の実績入力'!$C$4:$N$4,6)} | N29: =IF(6<=$N$2,SUM(OFFSET('毎月の実績入力'!$C$8,0,0,1,6)),NA()) | O29: =IF(6<$N$2,NA(),IF($N$2>=12,$N$7,($N$8+($N$12-$N$8)*(6-$N$2)/(12-$N$2))/$N$3)) | P29: ='はじめに入力'!$H$17
A31: チャネル | B31: リード数 | C31: 達成率 | D31: 有効リード数 | E31: 達成率 | F31: CPL | G31: 判定 | H31: 撤退の判断 | M31: {=INDEX('毎月の実績入力'!$C$4:$N$4,7)} | N31: =IF(7<=$N$2,SUM(OFFSET('毎月の実績入力'!$C$8,0,0,1,7)),NA()) | O31: =IF(7<$N$2,NA(),IF($N$2>=12,$N$7,($N$8+($N$12-$N$8)*(7-$N$2)/(12-$N$2))/$N$3)) | P31: ='はじめに入力'!$H$17
A32: 展示会 | B32: {=IFERROR(LET(s,IFERROR(MATCH(TRUE,INDEX('はじめに入力'!$C$38:$N$38>0,0),0),""),c,IF(OR($N$2="",s="",$N$2<s),"",IF(INDEX('毎月の実績入力'!$C$16:$N$16,$N$2)="","",SUM(OFFSET('毎月の実績入力'!$C$20,0,s-1,1,$N$2-s+1))+SUM(OFFSET('はじめに入力'!$C$41,0,s-1,1,$N$2-s+1)))),IF(c="","",SUM(OFFSET('毎月の実績入力'!$C$16,0,s-1,1,$N$2-s+1)))),"")} | C32: {=IFERROR(IF(B32="","",LET(s,IFERROR(MATCH(TRUE,INDEX('はじめに入力'!$C$38:$N$38>0,0),0),""),IFERROR(B32/SUM(OFFSET('はじめに入力'!$C$38,0,s-1,1,$N$2-s+1)),""))),"")} | D32: {=IFERROR(LET(s,IFERROR(MATCH(TRUE,INDEX('はじめに入力'!$C$38:$N$38>0,0),0),""),c,IF(OR($N$2="",s="",$N$2<s),"",IF(INDEX('毎月の実績入力'!$C$16:$N$16,$N$2)="","",SUM(OFFSET('毎月の実績入力'!$C$20,0,s-1,1,$N$2-s+1))+SUM(OFFSET('はじめに入力'!$C$41,0,s-1,1,$N$2-s+1)))),IF(c="","",SUM(OFFSET('毎月の実績入力'!$C$17,0,s-1,1,$N$2-s+1)))),"")} | E32: {=IFERROR(IF(D32="","",LET(s,IFERROR(MATCH(TRUE,INDEX('はじめに入力'!$C$38:$N$38>0,0),0),""),IFERROR(D32/SUM(OFFSET('はじめに入力'!$C$39,0,s-1,1,$N$2-s+1)),""))),"")} | F32: {=IFERROR(LET(s,IFERROR(MATCH(TRUE,INDEX('はじめに入力'!$C$38:$N$38>0,0),0),""),c,IF(OR($N$2="",s="",$N$2<s),"",IF(INDEX('毎月の実績入力'!$C$16:$N$16,$N$2)="","",SUM(OFFSET('毎月の実績入力'!$C$20,0,s-1,1,$N$2-s+1))+SUM(OFFSET('はじめに入力'!$C$41,0,s-1,1,$N$2-s+1)))),IF(c="","",IFERROR(c/B32,"―"))),"")} | G32: {=IFERROR(IF(F32="","",LET(s,IFERROR(MATCH(TRUE,INDEX('はじめに入力'!$C$38:$N$38>0,0),0),""),IF(SUM(OFFSET('毎月の実績入力'!$C$20,0,s-1,1,$N$2-s+1))=0,"費用なし",IF(OR(F32="―",F32>'はじめに入力'!$I$7),"上限超え","上限内")))),"")} | H32: {=IFERROR(IF(G32="","",LET(s,IFERROR(MATCH(TRUE,INDEX('はじめに入力'!$C$38:$N$38>0,0),0),""),IF($N$2<s+6,"判定前",IF(G32="費用なし","判定しない",IF(AND(G32="上限超え",C32<0.9),"撤退を検討","なし"))))),"")} | M32: {=INDEX('毎月の実績入力'!$C$4:$N$4,8)} | N32: =IF(8<=$N$2,SUM(OFFSET('毎月の実績入力'!$C$8,0,0,1,8)),NA()) | O32: =IF(8<$N$2,NA(),IF($N$2>=12,$N$7,($N$8+($N$12-$N$8)*(8-$N$2)/(12-$N$2))/$N$3)) | P32: ='はじめに入力'!$H$17
A33: セミナー | B33: {=IFERROR(LET(s,IFERROR(MATCH(TRUE,INDEX('はじめに入力'!$C$44:$N$44>0,0),0),""),c,IF(OR($N$2="",s="",$N$2<s),"",IF(INDEX('毎月の実績入力'!$C$24:$N$24,$N$2)="","",SUM(OFFSET('毎月の実績入力'!$C$28,0,s-1,1,$N$2-s+1))+SUM(OFFSET('はじめに入力'!$C$47,0,s-1,1,$N$2-s+1)))),IF(c="","",SUM(OFFSET('毎月の実績入力'!$C$24,0,s-1,1,$N$2-s+1)))),"")} | C33: {=IFERROR(IF(B33="","",LET(s,IFERROR(MATCH(TRUE,INDEX('はじめに入力'!$C$44:$N$44>0,0),0),""),IFERROR(B33/SUM(OFFSET('はじめに入力'!$C$44,0,s-1,1,$N$2-s+1)),""))),"")} | D33: {=IFERROR(LET(s,IFERROR(MATCH(TRUE,INDEX('はじめに入力'!$C$44:$N$44>0,0),0),""),c,IF(OR($N$2="",s="",$N$2<s),"",IF(INDEX('毎月の実績入力'!$C$24:$N$24,$N$2)="","",SUM(OFFSET('毎月の実績入力'!$C$28,0,s-1,1,$N$2-s+1))+SUM(OFFSET('はじめに入力'!$C$47,0,s-1,1,$N$2-s+1)))),IF(c="","",SUM(OFFSET('毎月の実績入力'!$C$25,0,s-1,1,$N$2-s+1)))),"")} | E33: {=IFERROR(IF(D33="","",LET(s,IFERROR(MATCH(TRUE,INDEX('はじめに入力'!$C$44:$N$44>0,0),0),""),IFERROR(D33/SUM(OFFSET('はじめに入力'!$C$45,0,s-1,1,$N$2-s+1)),""))),"")} | F33: {=IFERROR(LET(s,IFERROR(MATCH(TRUE,INDEX('はじめに入力'!$C$44:$N$44>0,0),0),""),c,IF(OR($N$2="",s="",$N$2<s),"",IF(INDEX('毎月の実績入力'!$C$24:$N$24,$N$2)="","",SUM(OFFSET('毎月の実績入力'!$C$28,0,s-1,1,$N$2-s+1))+SUM(OFFSET('はじめに入力'!$C$47,0,s-1,1,$N$2-s+1)))),IF(c="","",IFERROR(c/B33,"―"))),"")} | G33: {=IFERROR(IF(F33="","",LET(s,IFERROR(MATCH(TRUE,INDEX('はじめに入力'!$C$44:$N$44>0,0),0),""),IF(SUM(OFFSET('毎月の実績入力'!$C$28,0,s-1,1,$N$2-s+1))=0,"費用なし",IF(OR(F33="―",F33>'はじめに入力'!$I$7),"上限超え","上限内")))),"")} | H33: {=IFERROR(IF(G33="","",LET(s,IFERROR(MATCH(TRUE,INDEX('はじめに入力'!$C$44:$N$44>0,0),0),""),IF($N$2<s+6,"判定前",IF(G33="費用なし","判定しない",IF(AND(G33="上限超え",C33<0.9),"撤退を検討","なし"))))),"")} | M33: {=INDEX('毎月の実績入力'!$C$4:$N$4,9)} | N33: =IF(9<=$N$2,SUM(OFFSET('毎月の実績入力'!$C$8,0,0,1,9)),NA()) | O33: =IF(9<$N$2,NA(),IF($N$2>=12,$N$7,($N$8+($N$12-$N$8)*(9-$N$2)/(12-$N$2))/$N$3)) | P33: ='はじめに入力'!$H$17
A34: Web広告 | B34: {=IFERROR(LET(s,IFERROR(MATCH(TRUE,INDEX('はじめに入力'!$C$50:$N$50>0,0),0),""),c,IF(OR($N$2="",s="",$N$2<s),"",IF(INDEX('毎月の実績入力'!$C$32:$N$32,$N$2)="","",SUM(OFFSET('毎月の実績入力'!$C$36,0,s-1,1,$N$2-s+1))+SUM(OFFSET('はじめに入力'!$C$53,0,s-1,1,$N$2-s+1)))),IF(c="","",SUM(OFFSET('毎月の実績入力'!$C$32,0,s-1,1,$N$2-s+1)))),"")} | C34: {=IFERROR(IF(B34="","",LET(s,IFERROR(MATCH(TRUE,INDEX('はじめに入力'!$C$50:$N$50>0,0),0),""),IFERROR(B34/SUM(OFFSET('はじめに入力'!$C$50,0,s-1,1,$N$2-s+1)),""))),"")} | D34: {=IFERROR(LET(s,IFERROR(MATCH(TRUE,INDEX('はじめに入力'!$C$50:$N$50>0,0),0),""),c,IF(OR($N$2="",s="",$N$2<s),"",IF(INDEX('毎月の実績入力'!$C$32:$N$32,$N$2)="","",SUM(OFFSET('毎月の実績入力'!$C$36,0,s-1,1,$N$2-s+1))+SUM(OFFSET('はじめに入力'!$C$53,0,s-1,1,$N$2-s+1)))),IF(c="","",SUM(OFFSET('毎月の実績入力'!$C$33,0,s-1,1,$N$2-s+1)))),"")} | E34: {=IFERROR(IF(D34="","",LET(s,IFERROR(MATCH(TRUE,INDEX('はじめに入力'!$C$50:$N$50>0,0),0),""),IFERROR(D34/SUM(OFFSET('はじめに入力'!$C$51,0,s-1,1,$N$2-s+1)),""))),"")} | F34: {=IFERROR(LET(s,IFERROR(MATCH(TRUE,INDEX('はじめに入力'!$C$50:$N$50>0,0),0),""),c,IF(OR($N$2="",s="",$N$2<s),"",IF(INDEX('毎月の実績入力'!$C$32:$N$32,$N$2)="","",SUM(OFFSET('毎月の実績入力'!$C$36,0,s-1,1,$N$2-s+1))+SUM(OFFSET('はじめに入力'!$C$53,0,s-1,1,$N$2-s+1)))),IF(c="","",IFERROR(c/B34,"―"))),"")} | G34: {=IFERROR(IF(F34="","",LET(s,IFERROR(MATCH(TRUE,INDEX('はじめに入力'!$C$50:$N$50>0,0),0),""),IF(SUM(OFFSET('毎月の実績入力'!$C$36,0,s-1,1,$N$2-s+1))=0,"費用なし",IF(OR(F34="―",F34>'はじめに入力'!$I$7),"上限超え","上限内")))),"")} | H34: {=IFERROR(IF(G34="","",LET(s,IFERROR(MATCH(TRUE,INDEX('はじめに入力'!$C$50:$N$50>0,0),0),""),IF($N$2<s+6,"判定前",IF(G34="費用なし","判定しない",IF(AND(G34="上限超え",C34<0.9),"撤退を検討","なし"))))),"")} | M34: {=INDEX('毎月の実績入力'!$C$4:$N$4,10)} | N34: =IF(10<=$N$2,SUM(OFFSET('毎月の実績入力'!$C$8,0,0,1,10)),NA()) | O34: =IF(10<$N$2,NA(),IF($N$2>=12,$N$7,($N$8+($N$12-$N$8)*(10-$N$2)/(12-$N$2))/$N$3)) | P34: ='はじめに入力'!$H$17
A35: 自社サイト | B35: {=IFERROR(LET(s,IFERROR(MATCH(TRUE,INDEX('はじめに入力'!$C$56:$N$56>0,0),0),""),c,IF(OR($N$2="",s="",$N$2<s),"",IF(INDEX('毎月の実績入力'!$C$40:$N$40,$N$2)="","",SUM(OFFSET('毎月の実績入力'!$C$44,0,s-1,1,$N$2-s+1))+SUM(OFFSET('はじめに入力'!$C$59,0,s-1,1,$N$2-s+1)))),IF(c="","",SUM(OFFSET('毎月の実績入力'!$C$40,0,s-1,1,$N$2-s+1)))),"")} | C35: {=IFERROR(IF(B35="","",LET(s,IFERROR(MATCH(TRUE,INDEX('はじめに入力'!$C$56:$N$56>0,0),0),""),IFERROR(B35/SUM(OFFSET('はじめに入力'!$C$56,0,s-1,1,$N$2-s+1)),""))),"")} | D35: {=IFERROR(LET(s,IFERROR(MATCH(TRUE,INDEX('はじめに入力'!$C$56:$N$56>0,0),0),""),c,IF(OR($N$2="",s="",$N$2<s),"",IF(INDEX('毎月の実績入力'!$C$40:$N$40,$N$2)="","",SUM(OFFSET('毎月の実績入力'!$C$44,0,s-1,1,$N$2-s+1))+SUM(OFFSET('はじめに入力'!$C$59,0,s-1,1,$N$2-s+1)))),IF(c="","",SUM(OFFSET('毎月の実績入力'!$C$41,0,s-1,1,$N$2-s+1)))),"")} | E35: {=IFERROR(IF(D35="","",LET(s,IFERROR(MATCH(TRUE,INDEX('はじめに入力'!$C$56:$N$56>0,0),0),""),IFERROR(D35/SUM(OFFSET('はじめに入力'!$C$57,0,s-1,1,$N$2-s+1)),""))),"")} | F35: {=IFERROR(LET(s,IFERROR(MATCH(TRUE,INDEX('はじめに入力'!$C$56:$N$56>0,0),0),""),c,IF(OR($N$2="",s="",$N$2<s),"",IF(INDEX('毎月の実績入力'!$C$40:$N$40,$N$2)="","",SUM(OFFSET('毎月の実績入力'!$C$44,0,s-1,1,$N$2-s+1))+SUM(OFFSET('はじめに入力'!$C$59,0,s-1,1,$N$2-s+1)))),IF(c="","",IFERROR(c/B35,"―"))),"")} | G35: {=IFERROR(IF(F35="","",LET(s,IFERROR(MATCH(TRUE,INDEX('はじめに入力'!$C$56:$N$56>0,0),0),""),IF(SUM(OFFSET('毎月の実績入力'!$C$44,0,s-1,1,$N$2-s+1))=0,"費用なし",IF(OR(F35="―",F35>'はじめに入力'!$I$7),"上限超え","上限内")))),"")} | H35: {=IFERROR(IF(G35="","",LET(s,IFERROR(MATCH(TRUE,INDEX('はじめに入力'!$C$56:$N$56>0,0),0),""),IF($N$2<s+6,"判定前",IF(G35="費用なし","判定しない",IF(AND(G35="上限超え",C35<0.9),"撤退を検討","なし"))))),"")} | M35: {=INDEX('毎月の実績入力'!$C$4:$N$4,11)} | N35: =IF(11<=$N$2,SUM(OFFSET('毎月の実績入力'!$C$8,0,0,1,11)),NA()) | O35: =IF(11<$N$2,NA(),IF($N$2>=12,$N$7,($N$8+($N$12-$N$8)*(11-$N$2)/(12-$N$2))/$N$3)) | P35: ='はじめに入力'!$H$17
A36: SNS | B36: {=IFERROR(LET(s,IFERROR(MATCH(TRUE,INDEX('はじめに入力'!$C$62:$N$62>0,0),0),""),c,IF(OR($N$2="",s="",$N$2<s),"",IF(INDEX('毎月の実績入力'!$C$48:$N$48,$N$2)="","",SUM(OFFSET('毎月の実績入力'!$C$52,0,s-1,1,$N$2-s+1))+SUM(OFFSET('はじめに入力'!$C$65,0,s-1,1,$N$2-s+1)))),IF(c="","",SUM(OFFSET('毎月の実績入力'!$C$48,0,s-1,1,$N$2-s+1)))),"")} | C36: {=IFERROR(IF(B36="","",LET(s,IFERROR(MATCH(TRUE,INDEX('はじめに入力'!$C$62:$N$62>0,0),0),""),IFERROR(B36/SUM(OFFSET('はじめに入力'!$C$62,0,s-1,1,$N$2-s+1)),""))),"")} | D36: {=IFERROR(LET(s,IFERROR(MATCH(TRUE,INDEX('はじめに入力'!$C$62:$N$62>0,0),0),""),c,IF(OR($N$2="",s="",$N$2<s),"",IF(INDEX('毎月の実績入力'!$C$48:$N$48,$N$2)="","",SUM(OFFSET('毎月の実績入力'!$C$52,0,s-1,1,$N$2-s+1))+SUM(OFFSET('はじめに入力'!$C$65,0,s-1,1,$N$2-s+1)))),IF(c="","",SUM(OFFSET('毎月の実績入力'!$C$49,0,s-1,1,$N$2-s+1)))),"")} | E36: {=IFERROR(IF(D36="","",LET(s,IFERROR(MATCH(TRUE,INDEX('はじめに入力'!$C$62:$N$62>0,0),0),""),IFERROR(D36/SUM(OFFSET('はじめに入力'!$C$63,0,s-1,1,$N$2-s+1)),""))),"")} | F36: {=IFERROR(LET(s,IFERROR(MATCH(TRUE,INDEX('はじめに入力'!$C$62:$N$62>0,0),0),""),c,IF(OR($N$2="",s="",$N$2<s),"",IF(INDEX('毎月の実績入力'!$C$48:$N$48,$N$2)="","",SUM(OFFSET('毎月の実績入力'!$C$52,0,s-1,1,$N$2-s+1))+SUM(OFFSET('はじめに入力'!$C$65,0,s-1,1,$N$2-s+1)))),IF(c="","",IFERROR(c/B36,"―"))),"")} | G36: {=IFERROR(IF(F36="","",LET(s,IFERROR(MATCH(TRUE,INDEX('はじめに入力'!$C$62:$N$62>0,0),0),""),IF(SUM(OFFSET('毎月の実績入力'!$C$52,0,s-1,1,$N$2-s+1))=0,"費用なし",IF(OR(F36="―",F36>'はじめに入力'!$I$7),"上限超え","上限内")))),"")} | H36: {=IFERROR(IF(G36="","",LET(s,IFERROR(MATCH(TRUE,INDEX('はじめに入力'!$C$62:$N$62>0,0),0),""),IF($N$2<s+6,"判定前",IF(G36="費用なし","判定しない",IF(AND(G36="上限超え",C36<0.9),"撤退を検討","なし"))))),"")} | M36: {=INDEX('毎月の実績入力'!$C$4:$N$4,12)} | N36: =IF(12<=$N$2,SUM(OFFSET('毎月の実績入力'!$C$8,0,0,1,12)),NA()) | O36: =IF(12<$N$2,NA(),IF($N$2>=12,$N$7,($N$8+($N$12-$N$8)*(12-$N$2)/(12-$N$2))/$N$3)) | P36: ='はじめに入力'!$H$17
