Workbook

Sheet 使い方
A1: KPI管理表
A3: このシートでできること
A4: チャネル別に、毎月の費用・リード数・有効リード数を計画と比べ、CPLの判定と撤退の判断を自動で出します。商談数・受注数は期末に年間の数字だけを入れ、年間の目標と比べます
A6: 使い方（シートは左から 計画 → 実績 → 判定 の順に並んでいます）
A7: 1. 「はじめに入力」の灰色のセルには、KPI管理表メーカーで入れた数字が入っています。計画を変えるときは、灰色のセルを書き換える
A8: 2. 各チャネルのシートの「1. 計画」の月別のリード数・有効リード数は、年間を12か月に分けて入っています。展示会のように月によって違う場合は書き換える。外部費用・人件費は年額÷12が自動で入るので、月ごとに違う場合だけ上書きする
A9: 3. 毎月、「毎月の実績入力」に全チャネルのリード数・有効リード数・外部費用を入れる（各チャネルのシートの「2. 実績」に自動で反映）
A10: 4. 毎月、「全体」で対象月を選び、予実と判定を確認する
A11: 5. 期末に、営業から年間の商談数・受注数を受け取り、「全体」の「1. 年間の結果」に入れる
A13: 色の意味
A14: 赤＝直す（撤退を検討、届かない） オレンジ＝確認する（上限超え、やや届かない、計画の合計が年間の目標と合わない）
A16: 入っている数字
... A18: 計算式と判定の基準は、MeerKitLabの「数字の定義」に従います

Sheet はじめに入力
A1: KPI管理表 はじめに入力 | D1: 灰色＝入力 白＝自動計算 単位：万円
A2: 期のはじめに1回だけ入力します。年間予算表を作った人は、年間予算表の「1. 前提の入力」「2. チャネル別の計画（年間）の入力」と同じ数字を入れます
A3: 1. 前提
A4: 期首 | B4: マーケ経由の売上目標 | C4: 平均受注単価 | D4: 粗利率 | E4: 回収期間 | F4: リードタイム | G4: 1社あたりの月の粗利 | H4: CACの上限 | I4: 許容CPL | K4: 共通費
A5: 46478 | B5: 5750 | C5: 250 | D5: 0.4 | E5: 1.5 | F5: 4 | G5: =IFERROR(C5*D5/12,"") | H5: =IFERROR(C5*D5*E5,"") | I5: =IFERROR(H5*H15/B15,"") | K5: 0
A7: 2. チャネル別の計画（年間）
A8: チャネル | B8: リード数 | C8: 有効リード率 | D8: 有効リード数 | E8: 商談化率 | F8: 商談数 | G8: 受注率 | H8: 受注数 | I8: 受注金額 | J8: 外部費用 | K8: 人件費 | L8: CPL | M8: CAC | N8: 回収期間 | O8: CPL判定
A9: 展示会 | B9: 220 | C9: =IFERROR(D9/B9,"") | D9: 55 | E9: =IFERROR(F9/D9,"") | F9: 22 | G9: =IFERROR(H9/F9,"") | H9: 6 | I9: =H9*$C$5 | J9: 500 | K9: 107 | L9: =IFERROR((J9+K9)/B9,"") | M9: =IFERROR((J9+K9)/H9,"") | N9: =IFERROR(M9/$G$5,"") | O9: =IF(L9="","",IF(L9<=$I$5,"上限内","上限超え"))
A10: セミナー | B10: 80 | C10: =IFERROR(D10/B10,"") | D10: 50 | E10: =IFERROR(F10/D10,"") | F10: 20 | G10: =IFERROR(H10/F10,"") | H10: 6 | I10: =H10*$C$5 | J10: 90 | K10: 80 | L10: =IFERROR((J10+K10)/B10,"") | M10: =IFERROR((J10+K10)/H10,"") | N10: =IFERROR(M10/$G$5,"") | O10: =IF(L10="","",IF(L10<=$I$5,"上限内","上限超え"))
A11: Web広告 | B11: 95 | C11: =IFERROR(D11/B11,"") | D11: 43 | E11: =IFERROR(F11/D11,"") | F11: 17 | G11: =IFERROR(H11/F11,"") | H11: 5 | I11: =H11*$C$5 | J11: 488 | K11: 35 | L11: =IFERROR((J11+K11)/B11,"") | M11: =IFERROR((J11+K11)/H11,"") | N11: =IFERROR(M11/$G$5,"") | O11: =IF(L11="","",IF(L11<=$I$5,"上限内","上限超え"))
A12: 自社サイト | B12: 90 | C12: =IFERROR(D12/B12,"") | D12: 34 | E12: =IFERROR(F12/D12,"") | F12: 14 | G12: =IFERROR(H12/F12,"") | H12: 4 | I12: =H12*$C$5 | J12: 356 | K12: 141 | L12: =IFERROR((J12+K12)/B12,"") | M12: =IFERROR((J12+K12)/H12,"") | N12: =IFERROR(M12/$G$5,"") | O12: =IF(L12="","",IF(L12<=$I$5,"上限内","上限超え"))
A13: SNS | B13: 12 | C13: =IFERROR(D13/B13,"") | D13: 5 | E13: =IFERROR(F13/D13,"") | F13: 2 | G13: =IFERROR(H13/F13,"") | H13: 1 | I13: =H13*$C$5 | J13: 12 | K13: 42 | L13: =IFERROR((J13+K13)/B13,"") | M13: =IFERROR((J13+K13)/H13,"") | N13: =IFERROR(M13/$G$5,"") | O13: =IF(L13="","",IF(L13<=$I$5,"上限内","上限超え"))
A14: メール | B14: 20 | C14: =IFERROR(D14/B14,"") | D14: 8 | E14: =IFERROR(F14/D14,"") | F14: 3 | G14: =IFERROR(H14/F14,"") | H14: 1 | I14: =H14*$C$5 | J14: 96 | K14: 107 | L14: =IFERROR((J14+K14)/B14,"") | M14: =IFERROR((J14+K14)/H14,"") | N14: =IFERROR(M14/$G$5,"") | O14: =IF(L14="","",IF(L14<=$I$5,"上限内","上限超え"))
A15: 合計 | B15: =SUM(B9:B14) | C15: =IFERROR(D15/B15,"") | D15: =SUM(D9:D14) | E15: =IFERROR(F15/D15,"") | F15: =SUM(F9:F14) | G15: =IFERROR(H15/F15,"") | H15: =SUM(H9:H14) | I15: =SUM(I9:I14) | J15: =SUM(J9:J14) | K15: =SUM(K9:K14) | L15: =IFERROR((J15+K15)/B15,"") | M15: =IFERROR((J15+K15)/H15,"") | N15: =IFERROR(M15/$G$5,"") | O15: =IF(L15="","",IF(L15<=$I$5,"上限内","上限超え"))
A16: 判定＝CPLが許容CPL以下なら「上限内」、超えたら「上限超え」。CPL・CAC・回収期間（か月）は外部費用＋人件費で計算する。許容CPL＝CACの上限×受注数÷リード数（合計）
A18: 3. 計画の妥当性の確認：目標 | K18: 4. 計画の妥当性の確認：コスト
B19: リード数 | C19: 有効リード率 | D19: 有効リード数 | E19: 商談化率 | F19: 商談数 | G19: 受注率 | H19: 受注数 | I19: 受注金額 | K19: コスト合計 | L19: ROI（1年）
A20: 必要な数（逆算） | B20: =IF(D21=0,0,ROUNDUP(D20*B21/D21,0)) | C20: =IF(B20=0,0,D20/B20) | D20: =IF(F21=0,0,ROUNDUP(F20*D21/F21,0)) | E20: =IF(D20=0,0,F20/D20) | F20: =IF(H21=0,0,ROUNDUP(H20*F21/H21,0)) | G20: =IF(F20=0,0,H20/F20) | H20: =IF(C5=0,0,ROUNDUP(B5/C5,0)) | I20: =B5 | K20: =J15+K15+K5 | L20: =IF(K20=0,0,(I15*D5-K20)/K20)
A21: 計画の数 | B21: =B15 | C21: =IF(B21=0,0,D21/B21) | D21: =D15 | E21: =IF(D21=0,0,F21/D21) | F21: =F15 | G21: =IF(F21=0,0,H21/F21) | H21: =H15 | I21: =I15
A22: 判定 | B22: =IF(B21>=B20,"足りる","直す") | C22: - | D22: =IF(D21>=D20,"足りる","直す") | E22: - | F22: =IF(F21>=F20,"足りる","直す") | G22: - | H22: =IF(H21>=H20,"足りる","直す") | I22: =IF(I21>=I20,"足りる","直す")

Sheet 毎月の実績入力
A1: KPI管理表 毎月の実績入力 | D1: 灰色＝入力 白＝自動計算 単位：万円
A2: 毎月、灰色のセルに実績を入れます。人件費は計画の月額（各チャネルのシートの人件費）を自動で表示します
A3: 1. 実績の合計（自動）
B4: 項目 | C4: =MONTH(EDATE('はじめに入力'!$A$5,0))&"月" | D4: =MONTH(EDATE('はじめに入力'!$A$5,1))&"月" | E4: =MONTH(EDATE('はじめに入力'!$A$5,2))&"月" | F4: =MONTH(EDATE('はじめに入力'!$A$5,3))&"月" | G4: =MONTH(EDATE('はじめに入力'!$A$5,4))&"月" | H4: =MONTH(EDATE('はじめに入力'!$A$5,5))&"月" | I4: =MONTH(EDATE('はじめに入力'!$A$5,6))&"月" | J4: =MONTH(EDATE('はじめに入力'!$A$5,7))&"月" | K4: =MONTH(EDATE('はじめに入力'!$A$5,8))&"月" | L4: =MONTH(EDATE('はじめに入力'!$A$5,9))&"月" | M4: =MONTH(EDATE('はじめに入力'!$A$5,10))&"月" | N4: =MONTH(EDATE('はじめに入力'!$A$5,11))&"月" | O4: 年間
B5: リード数 | C5: =C12+C18+C24+C30+C36+C42 | D5: =D12+D18+D24+D30+D36+D42 | E5: =E12+E18+E24+E30+E36+E42 | F5: =F12+F18+F24+F30+F36+F42 | G5: =G12+G18+G24+G30+G36+G42 | H5: =H12+H18+H24+H30+H36+H42 | I5: =I12+I18+I24+I30+I36+I42 | J5: =J12+J18+J24+J30+J36+J42 | ... N5: =N12+N18+N24+N30+N36+N42 | O5: =SUM(C5:N5)
B6: 有効リード数 | C6: =C13+C19+C25+C31+C37+C43 | D6: =D13+D19+D25+D31+D37+D43 | E6: =E13+E19+E25+E31+E37+E43 | F6: =F13+F19+F25+F31+F37+F43 | G6: =G13+G19+G25+G31+G37+G43 | H6: =H13+H19+H25+H31+H37+H43 | I6: =I13+I19+I25+I31+I37+I43 | J6: =J13+J19+J25+J31+J37+J43 | ... N6: =N13+N19+N25+N31+N37+N43 | O6: =SUM(C6:N6)
B7: 外部費用 | C7: =C14+C20+C26+C32+C38+C44 | D7: =D14+D20+D26+D32+D38+D44 | E7: =E14+E20+E26+E32+E38+E44 | F7: =F14+F20+F26+F32+F38+F44 | G7: =G14+G20+G26+G32+G38+G44 | H7: =H14+H20+H26+H32+H38+H44 | I7: =I14+I20+I26+I32+I38+I44 | J7: =J14+J20+J26+J32+J38+J44 | ... N7: =N14+N20+N26+N32+N38+N44 | O7: =SUM(C7:N7)
B8: 人件費 | C8: =C15+C21+C27+C33+C39+C45 | D8: =D15+D21+D27+D33+D39+D45 | E8: =E15+E21+E27+E33+E39+E45 | F8: =F15+F21+F27+F33+F39+F45 | G8: =G15+G21+G27+G33+G39+G45 | H8: =H15+H21+H27+H33+H39+H45 | I8: =I15+I21+I27+I33+I39+I45 | J8: =J15+J21+J27+J33+J39+J45 | ... N8: =N15+N21+N27+N33+N39+N45 | O8: =SUM(C8:N8)
A10: 2. チャネル別の実績（月別）の入力
A11: チャネル | B11: 展示会 | C11: =C$4 | D11: =D$4 | E11: =E$4 | F11: =F$4 | G11: =G$4 | H11: =H$4 | I11: =I$4 | J11: =J$4 | ... N11: =N$4 | O11: 年間
A12: 展示会 | B12: リード数 | O12: =SUM(C12:N12)
B13: 有効リード数 | O13: =SUM(C13:N13)
B14: 外部費用 | O14: =SUM(C14:N14)
B15: 人件費 | C15: ='展示会'!B10 | D15: ='展示会'!C10 | E15: ='展示会'!D10 | F15: ='展示会'!E10 | G15: ='展示会'!F10 | H15: ='展示会'!G10 | I15: ='展示会'!H10 | J15: ='展示会'!I10 | ... N15: ='展示会'!M10 | O15: =SUM(C15:N15)
A17: チャネル | B17: セミナー | C17: =C$4 | D17: =D$4 | E17: =E$4 | F17: =F$4 | G17: =G$4 | H17: =H$4 | I17: =I$4 | J17: =J$4 | ... N17: =N$4 | O17: 年間
A18: セミナー | B18: リード数 | O18: =SUM(C18:N18)
B19: 有効リード数 | O19: =SUM(C19:N19)
B20: 外部費用 | O20: =SUM(C20:N20)
B21: 人件費 | C21: ='セミナー'!B10 | D21: ='セミナー'!C10 | E21: ='セミナー'!D10 | F21: ='セミナー'!E10 | G21: ='セミナー'!F10 | H21: ='セミナー'!G10 | I21: ='セミナー'!H10 | J21: ='セミナー'!I10 | ... N21: ='セミナー'!M10 | O21: =SUM(C21:N21)
A23: チャネル | B23: Web広告 | C23: =C$4 | D23: =D$4 | E23: =E$4 | F23: =F$4 | G23: =G$4 | H23: =H$4 | I23: =I$4 | J23: =J$4 | ... N23: =N$4 | O23: 年間
A24: Web広告 | B24: リード数 | O24: =SUM(C24:N24)
B25: 有効リード数 | O25: =SUM(C25:N25)
B26: 外部費用 | O26: =SUM(C26:N26)
B27: 人件費 | C27: ='Web広告'!B10 | D27: ='Web広告'!C10 | E27: ='Web広告'!D10 | F27: ='Web広告'!E10 | G27: ='Web広告'!F10 | H27: ='Web広告'!G10 | I27: ='Web広告'!H10 | J27: ='Web広告'!I10 | ... N27: ='Web広告'!M10 | O27: =SUM(C27:N27)
A29: チャネル | B29: 自社サイト | C29: =C$4 | D29: =D$4 | E29: =E$4 | F29: =F$4 | G29: =G$4 | H29: =H$4 | I29: =I$4 | J29: =J$4 | ... N29: =N$4 | O29: 年間
A30: 自社サイト | B30: リード数 | O30: =SUM(C30:N30)
B31: 有効リード数 | O31: =SUM(C31:N31)
B32: 外部費用 | O32: =SUM(C32:N32)
B33: 人件費 | C33: ='自社サイト'!B10 | D33: ='自社サイト'!C10 | E33: ='自社サイト'!D10 | F33: ='自社サイト'!E10 | G33: ='自社サイト'!F10 | H33: ='自社サイト'!G10 | I33: ='自社サイト'!H10 | J33: ='自社サイト'!I10 | ... N33: ='自社サイト'!M10 | O33: =SUM(C33:N33)
A35: チャネル | B35: SNS | C35: =C$4 | D35: =D$4 | E35: =E$4 | F35: =F$4 | G35: =G$4 | H35: =H$4 | I35: =I$4 | J35: =J$4 | ... N35: =N$4 | O35: 年間
A36: SNS | B36: リード数 | O36: =SUM(C36:N36)
B37: 有効リード数 | O37: =SUM(C37:N37)
B38: 外部費用 | O38: =SUM(C38:N38)
B39: 人件費 | C39: =SNS!B10 | D39: =SNS!C10 | E39: =SNS!D10 | F39: =SNS!E10 | G39: =SNS!F10 | H39: =SNS!G10 | I39: =SNS!H10 | J39: =SNS!I10 | ... N39: =SNS!M10 | O39: =SUM(C39:N39)
A41: チャネル | B41: メール | C41: =C$4 | D41: =D$4 | E41: =E$4 | F41: =F$4 | G41: =G$4 | H41: =H$4 | I41: =I$4 | J41: =J$4 | ... N41: =N$4 | O41: 年間
A42: メール | B42: リード数 | O42: =SUM(C42:N42)
B43: 有効リード数 | O43: =SUM(C43:N43)
B44: 外部費用 | O44: =SUM(C44:N44)
B45: 人件費 | C45: ='メール'!B10 | D45: ='メール'!C10 | E45: ='メール'!D10 | F45: ='メール'!E10 | G45: ='メール'!F10 | H45: ='メール'!G10 | I45: ='メール'!H10 | J45: ='メール'!I10 | ... N45: ='メール'!M10 | O45: =SUM(C45:N45)

Sheet 展示会
A1: 展示会 | D1: 灰色＝入力 白＝自動計算 単位：万円
A2: 開始月 | B2: {=IF(B3="","計画なし",INDEX($B$6:$M$6,B3))} | C2: 判定する月 | D2: {=IF(D3="","",IF(D3>12,"今期は判定なし",INDEX($B$6:$M$6,D3)))} | E2: 許容CPL | F2: ='はじめに入力'!$I$5
A3: （計算用） | B3: {=IFERROR(MATCH(TRUE,INDEX($B$7:$M$7>0,0),0),"")} | D3: =IF(B3="","",B3+6) | F3: =MATCH($A$1,'はじめに入力'!$A$9:$A$14,0)
A4: 1. 計画（期初に入力）
B5: ※外部費用と人件費は、適宜修正してください。
A6: 項目 | B6: =MONTH(EDATE('はじめに入力'!$A$5,0))&"月" | C6: =MONTH(EDATE('はじめに入力'!$A$5,1))&"月" | D6: =MONTH(EDATE('はじめに入力'!$A$5,2))&"月" | E6: =MONTH(EDATE('はじめに入力'!$A$5,3))&"月" | F6: =MONTH(EDATE('はじめに入力'!$A$5,4))&"月" | G6: =MONTH(EDATE('はじめに入力'!$A$5,5))&"月" | H6: =MONTH(EDATE('はじめに入力'!$A$5,6))&"月" | I6: =MONTH(EDATE('はじめに入力'!$A$5,7))&"月" | J6: =MONTH(EDATE('はじめに入力'!$A$5,8))&"月" | K6: =MONTH(EDATE('はじめに入力'!$A$5,9))&"月" | L6: =MONTH(EDATE('はじめに入力'!$A$5,10))&"月" | M6: =MONTH(EDATE('はじめに入力'!$A$5,11))&"月" | N6: 年間 | O6: 年間の計画と
A7: リード数 | B7: 0 | C7: 0 | D7: 110 | E7: 0 | F7: 0 | G7: 0 | H7: 0 | I7: 110 | J7: 0 | K7: 0 | L7: 0 | M7: 0 | N7: =SUM(B7:M7) | O7: {=IF(N7=INDEX('はじめに入力'!$B$9:$B$14,$F$3),"一致","確認")}
A8: 有効リード数 | B8: 0 | C8: 0 | D8: 27 | E8: 0 | F8: 0 | G8: 0 | H8: 0 | I8: 28 | J8: 0 | K8: 0 | L8: 0 | M8: 0 | N8: =SUM(B8:M8) | O8: {=IF(N8=INDEX('はじめに入力'!$D$9:$D$14,$F$3),"一致","確認")}
A9: 外部費用 | B9: {=INDEX('はじめに入力'!$J$9:$J$14,$F$3)/12} | C9: {=INDEX('はじめに入力'!$J$9:$J$14,$F$3)/12} | D9: {=INDEX('はじめに入力'!$J$9:$J$14,$F$3)/12} | E9: {=INDEX('はじめに入力'!$J$9:$J$14,$F$3)/12} | F9: {=INDEX('はじめに入力'!$J$9:$J$14,$F$3)/12} | G9: {=INDEX('はじめに入力'!$J$9:$J$14,$F$3)/12} | H9: {=INDEX('はじめに入力'!$J$9:$J$14,$F$3)/12} | I9: {=INDEX('はじめに入力'!$J$9:$J$14,$F$3)/12} | ... M9: {=INDEX('はじめに入力'!$J$9:$J$14,$F$3)/12} | N9: =SUM(B9:M9) | O9: {=IF(ROUND(N9,1)=ROUND(INDEX('はじめに入力'!$J$9:$J$14,$F$3),1),"一致","確認")}
A10: 人件費 | B10: {=INDEX('はじめに入力'!$K$9:$K$14,$F$3)/12} | C10: {=INDEX('はじめに入力'!$K$9:$K$14,$F$3)/12} | D10: {=INDEX('はじめに入力'!$K$9:$K$14,$F$3)/12} | E10: {=INDEX('はじめに入力'!$K$9:$K$14,$F$3)/12} | F10: {=INDEX('はじめに入力'!$K$9:$K$14,$F$3)/12} | G10: {=INDEX('はじめに入力'!$K$9:$K$14,$F$3)/12} | H10: {=INDEX('はじめに入力'!$K$9:$K$14,$F$3)/12} | I10: {=INDEX('はじめに入力'!$K$9:$K$14,$F$3)/12} | ... M10: {=INDEX('はじめに入力'!$K$9:$K$14,$F$3)/12} | N10: =SUM(B10:M10)
A12: 2. 実績（「毎月の実績入力」から自動）
A13: 項目 | B13: =B$6 | C13: =C$6 | D13: =D$6 | E13: =E$6 | F13: =F$6 | G13: =G$6 | H13: =H$6 | I13: =I$6 | ... M13: =M$6 | N13: 年間
A14: リード数 | B14: {=IF(INDEX('毎月の実績入力'!C$12:C$45,($F$3-1)*6+1)="","",INDEX('毎月の実績入力'!C$12:C$45,($F$3-1)*6+1))} | C14: {=IF(INDEX('毎月の実績入力'!D$12:D$45,($F$3-1)*6+1)="","",INDEX('毎月の実績入力'!D$12:D$45,($F$3-1)*6+1))} | D14: {=IF(INDEX('毎月の実績入力'!E$12:E$45,($F$3-1)*6+1)="","",INDEX('毎月の実績入力'!E$12:E$45,($F$3-1)*6+1))} | E14: {=IF(INDEX('毎月の実績入力'!F$12:F$45,($F$3-1)*6+1)="","",INDEX('毎月の実績入力'!F$12:F$45,($F$3-1)*6+1))} | F14: {=IF(INDEX('毎月の実績入力'!G$12:G$45,($F$3-1)*6+1)="","",INDEX('毎月の実績入力'!G$12:G$45,($F$3-1)*6+1))} | G14: {=IF(INDEX('毎月の実績入力'!H$12:H$45,($F$3-1)*6+1)="","",INDEX('毎月の実績入力'!H$12:H$45,($F$3-1)*6+1))} | H14: {=IF(INDEX('毎月の実績入力'!I$12:I$45,($F$3-1)*6+1)="","",INDEX('毎月の実績入力'!I$12:I$45,($F$3-1)*6+1))} | I14: {=IF(INDEX('毎月の実績入力'!J$12:J$45,($F$3-1)*6+1)="","",INDEX('毎月の実績入力'!J$12:J$45,($F$3-1)*6+1))} | ... M14: {=IF(INDEX('毎月の実績入力'!N$12:N$45,($F$3-1)*6+1)="","",INDEX('毎月の実績入力'!N$12:N$45,($F$3-1)*6+1))} | N14: =SUM(B14:M14)
A15: 有効リード率 | B15: =IF(OR(B14="",B16=""),"",IFERROR(B16/B14,"")) | C15: =IF(OR(C14="",C16=""),"",IFERROR(C16/C14,"")) | D15: =IF(OR(D14="",D16=""),"",IFERROR(D16/D14,"")) | E15: =IF(OR(E14="",E16=""),"",IFERROR(E16/E14,"")) | F15: =IF(OR(F14="",F16=""),"",IFERROR(F16/F14,"")) | G15: =IF(OR(G14="",G16=""),"",IFERROR(G16/G14,"")) | H15: =IF(OR(H14="",H16=""),"",IFERROR(H16/H14,"")) | I15: =IF(OR(I14="",I16=""),"",IFERROR(I16/I14,"")) | ... M15: =IF(OR(M14="",M16=""),"",IFERROR(M16/M14,"")) | N15: =IFERROR(N16/N14,"")
A16: 有効リード数 | B16: {=IF(INDEX('毎月の実績入力'!C$12:C$45,($F$3-1)*6+2)="","",INDEX('毎月の実績入力'!C$12:C$45,($F$3-1)*6+2))} | C16: {=IF(INDEX('毎月の実績入力'!D$12:D$45,($F$3-1)*6+2)="","",INDEX('毎月の実績入力'!D$12:D$45,($F$3-1)*6+2))} | D16: {=IF(INDEX('毎月の実績入力'!E$12:E$45,($F$3-1)*6+2)="","",INDEX('毎月の実績入力'!E$12:E$45,($F$3-1)*6+2))} | E16: {=IF(INDEX('毎月の実績入力'!F$12:F$45,($F$3-1)*6+2)="","",INDEX('毎月の実績入力'!F$12:F$45,($F$3-1)*6+2))} | F16: {=IF(INDEX('毎月の実績入力'!G$12:G$45,($F$3-1)*6+2)="","",INDEX('毎月の実績入力'!G$12:G$45,($F$3-1)*6+2))} | G16: {=IF(INDEX('毎月の実績入力'!H$12:H$45,($F$3-1)*6+2)="","",INDEX('毎月の実績入力'!H$12:H$45,($F$3-1)*6+2))} | H16: {=IF(INDEX('毎月の実績入力'!I$12:I$45,($F$3-1)*6+2)="","",INDEX('毎月の実績入力'!I$12:I$45,($F$3-1)*6+2))} | I16: {=IF(INDEX('毎月の実績入力'!J$12:J$45,($F$3-1)*6+2)="","",INDEX('毎月の実績入力'!J$12:J$45,($F$3-1)*6+2))} | ... M16: {=IF(INDEX('毎月の実績入力'!N$12:N$45,($F$3-1)*6+2)="","",INDEX('毎月の実績入力'!N$12:N$45,($F$3-1)*6+2))} | N16: =SUM(B16:M16)
A17: 外部費用 | B17: {=IF(INDEX('毎月の実績入力'!C$12:C$45,($F$3-1)*6+3)="","",INDEX('毎月の実績入力'!C$12:C$45,($F$3-1)*6+3))} | C17: {=IF(INDEX('毎月の実績入力'!D$12:D$45,($F$3-1)*6+3)="","",INDEX('毎月の実績入力'!D$12:D$45,($F$3-1)*6+3))} | D17: {=IF(INDEX('毎月の実績入力'!E$12:E$45,($F$3-1)*6+3)="","",INDEX('毎月の実績入力'!E$12:E$45,($F$3-1)*6+3))} | E17: {=IF(INDEX('毎月の実績入力'!F$12:F$45,($F$3-1)*6+3)="","",INDEX('毎月の実績入力'!F$12:F$45,($F$3-1)*6+3))} | F17: {=IF(INDEX('毎月の実績入力'!G$12:G$45,($F$3-1)*6+3)="","",INDEX('毎月の実績入力'!G$12:G$45,($F$3-1)*6+3))} | G17: {=IF(INDEX('毎月の実績入力'!H$12:H$45,($F$3-1)*6+3)="","",INDEX('毎月の実績入力'!H$12:H$45,($F$3-1)*6+3))} | H17: {=IF(INDEX('毎月の実績入力'!I$12:I$45,($F$3-1)*6+3)="","",INDEX('毎月の実績入力'!I$12:I$45,($F$3-1)*6+3))} | I17: {=IF(INDEX('毎月の実績入力'!J$12:J$45,($F$3-1)*6+3)="","",INDEX('毎月の実績入力'!J$12:J$45,($F$3-1)*6+3))} | ... M17: {=IF(INDEX('毎月の実績入力'!N$12:N$45,($F$3-1)*6+3)="","",INDEX('毎月の実績入力'!N$12:N$45,($F$3-1)*6+3))} | N17: =SUM(B17:M17)
A19: 3. 判定（開始月からの累計）
A20: 項目 | B20: =B$6 | C20: =C$6 | D20: =D$6 | E20: =E$6 | F20: =F$6 | G20: =G$6 | H20: =H$6 | I20: =I$6 | ... M20: =M$6
A21: リード数の達成率 | B21: =IF(B26="","",IFERROR(SUM(INDEX($B$14:$M$14,$B$3):B$14)/SUM(INDEX($B$7:$M$7,$B$3):B$7),"")) | C21: =IF(C26="","",IFERROR(SUM(INDEX($B$14:$M$14,$B$3):C$14)/SUM(INDEX($B$7:$M$7,$B$3):C$7),"")) | D21: =IF(D26="","",IFERROR(SUM(INDEX($B$14:$M$14,$B$3):D$14)/SUM(INDEX($B$7:$M$7,$B$3):D$7),"")) | E21: =IF(E26="","",IFERROR(SUM(INDEX($B$14:$M$14,$B$3):E$14)/SUM(INDEX($B$7:$M$7,$B$3):E$7),"")) | F21: =IF(F26="","",IFERROR(SUM(INDEX($B$14:$M$14,$B$3):F$14)/SUM(INDEX($B$7:$M$7,$B$3):F$7),"")) | G21: =IF(G26="","",IFERROR(SUM(INDEX($B$14:$M$14,$B$3):G$14)/SUM(INDEX($B$7:$M$7,$B$3):G$7),"")) | H21: =IF(H26="","",IFERROR(SUM(INDEX($B$14:$M$14,$B$3):H$14)/SUM(INDEX($B$7:$M$7,$B$3):H$7),"")) | I21: =IF(I26="","",IFERROR(SUM(INDEX($B$14:$M$14,$B$3):I$14)/SUM(INDEX($B$7:$M$7,$B$3):I$7),"")) | ... M21: =IF(M26="","",IFERROR(SUM(INDEX($B$14:$M$14,$B$3):M$14)/SUM(INDEX($B$7:$M$7,$B$3):M$7),""))
A22: 有効リード数の達成率 | B22: =IF(B26="","",IFERROR(SUM(INDEX($B$16:$M$16,$B$3):B$16)/SUM(INDEX($B$8:$M$8,$B$3):B$8),"")) | C22: =IF(C26="","",IFERROR(SUM(INDEX($B$16:$M$16,$B$3):C$16)/SUM(INDEX($B$8:$M$8,$B$3):C$8),"")) | D22: =IF(D26="","",IFERROR(SUM(INDEX($B$16:$M$16,$B$3):D$16)/SUM(INDEX($B$8:$M$8,$B$3):D$8),"")) | E22: =IF(E26="","",IFERROR(SUM(INDEX($B$16:$M$16,$B$3):E$16)/SUM(INDEX($B$8:$M$8,$B$3):E$8),"")) | F22: =IF(F26="","",IFERROR(SUM(INDEX($B$16:$M$16,$B$3):F$16)/SUM(INDEX($B$8:$M$8,$B$3):F$8),"")) | G22: =IF(G26="","",IFERROR(SUM(INDEX($B$16:$M$16,$B$3):G$16)/SUM(INDEX($B$8:$M$8,$B$3):G$8),"")) | H22: =IF(H26="","",IFERROR(SUM(INDEX($B$16:$M$16,$B$3):H$16)/SUM(INDEX($B$8:$M$8,$B$3):H$8),"")) | I22: =IF(I26="","",IFERROR(SUM(INDEX($B$16:$M$16,$B$3):I$16)/SUM(INDEX($B$8:$M$8,$B$3):I$8),"")) | ... M22: =IF(M26="","",IFERROR(SUM(INDEX($B$16:$M$16,$B$3):M$16)/SUM(INDEX($B$8:$M$8,$B$3):M$8),""))
A23: CPL | B23: =IF(B26="","",IFERROR(B26/SUM(INDEX($B$14:$M$14,$B$3):B$14),"―")) | C23: =IF(C26="","",IFERROR(C26/SUM(INDEX($B$14:$M$14,$B$3):C$14),"―")) | D23: =IF(D26="","",IFERROR(D26/SUM(INDEX($B$14:$M$14,$B$3):D$14),"―")) | E23: =IF(E26="","",IFERROR(E26/SUM(INDEX($B$14:$M$14,$B$3):E$14),"―")) | F23: =IF(F26="","",IFERROR(F26/SUM(INDEX($B$14:$M$14,$B$3):F$14),"―")) | G23: =IF(G26="","",IFERROR(G26/SUM(INDEX($B$14:$M$14,$B$3):G$14),"―")) | H23: =IF(H26="","",IFERROR(H26/SUM(INDEX($B$14:$M$14,$B$3):H$14),"―")) | I23: =IF(I26="","",IFERROR(I26/SUM(INDEX($B$14:$M$14,$B$3):I$14),"―")) | ... M23: =IF(M26="","",IFERROR(M26/SUM(INDEX($B$14:$M$14,$B$3):M$14),"―"))
A24: 判定 | B24: =IF(B26="","",IF(SUM(INDEX($B$17:$M$17,$B$3):B$17)=0,"費用なし",IF(OR(B23="―",B23>$F$2),"上限超え","上限内"))) | C24: =IF(C26="","",IF(SUM(INDEX($B$17:$M$17,$B$3):C$17)=0,"費用なし",IF(OR(C23="―",C23>$F$2),"上限超え","上限内"))) | D24: =IF(D26="","",IF(SUM(INDEX($B$17:$M$17,$B$3):D$17)=0,"費用なし",IF(OR(D23="―",D23>$F$2),"上限超え","上限内"))) | E24: =IF(E26="","",IF(SUM(INDEX($B$17:$M$17,$B$3):E$17)=0,"費用なし",IF(OR(E23="―",E23>$F$2),"上限超え","上限内"))) | F24: =IF(F26="","",IF(SUM(INDEX($B$17:$M$17,$B$3):F$17)=0,"費用なし",IF(OR(F23="―",F23>$F$2),"上限超え","上限内"))) | G24: =IF(G26="","",IF(SUM(INDEX($B$17:$M$17,$B$3):G$17)=0,"費用なし",IF(OR(G23="―",G23>$F$2),"上限超え","上限内"))) | H24: =IF(H26="","",IF(SUM(INDEX($B$17:$M$17,$B$3):H$17)=0,"費用なし",IF(OR(H23="―",H23>$F$2),"上限超え","上限内"))) | I24: =IF(I26="","",IF(SUM(INDEX($B$17:$M$17,$B$3):I$17)=0,"費用なし",IF(OR(I23="―",I23>$F$2),"上限超え","上限内"))) | ... M24: =IF(M26="","",IF(SUM(INDEX($B$17:$M$17,$B$3):M$17)=0,"費用なし",IF(OR(M23="―",M23>$F$2),"上限超え","上限内")))
A25: 撤退の判断 | B25: =IF(B26="","",IF(COLUMN()-1<$D$3,"判定前",IF(B24="費用なし","判定しない",IF(AND(B24="上限超え",B21<0.9),"撤退を検討","なし")))) | C25: =IF(C26="","",IF(COLUMN()-1<$D$3,"判定前",IF(C24="費用なし","判定しない",IF(AND(C24="上限超え",C21<0.9),"撤退を検討","なし")))) | D25: =IF(D26="","",IF(COLUMN()-1<$D$3,"判定前",IF(D24="費用なし","判定しない",IF(AND(D24="上限超え",D21<0.9),"撤退を検討","なし")))) | E25: =IF(E26="","",IF(COLUMN()-1<$D$3,"判定前",IF(E24="費用なし","判定しない",IF(AND(E24="上限超え",E21<0.9),"撤退を検討","なし")))) | F25: =IF(F26="","",IF(COLUMN()-1<$D$3,"判定前",IF(F24="費用なし","判定しない",IF(AND(F24="上限超え",F21<0.9),"撤退を検討","なし")))) | G25: =IF(G26="","",IF(COLUMN()-1<$D$3,"判定前",IF(G24="費用なし","判定しない",IF(AND(G24="上限超え",G21<0.9),"撤退を検討","なし")))) | H25: =IF(H26="","",IF(COLUMN()-1<$D$3,"判定前",IF(H24="費用なし","判定しない",IF(AND(H24="上限超え",H21<0.9),"撤退を検討","なし")))) | I25: =IF(I26="","",IF(COLUMN()-1<$D$3,"判定前",IF(I24="費用なし","判定しない",IF(AND(I24="上限超え",I21<0.9),"撤退を検討","なし")))) | ... M25: =IF(M26="","",IF(COLUMN()-1<$D$3,"判定前",IF(M24="費用なし","判定しない",IF(AND(M24="上限超え",M21<0.9),"撤退を検討","なし"))))
A26: 費用（外部費用＋人件費） | B26: =IF(OR($B$3="",COLUMN()-1<$B$3,B$14=""),"",SUM(INDEX($B$17:$M$17,$B$3):B$17)+SUM(INDEX($B$10:$M$10,$B$3):B$10)) | C26: =IF(OR($B$3="",COLUMN()-1<$B$3,C$14=""),"",SUM(INDEX($B$17:$M$17,$B$3):C$17)+SUM(INDEX($B$10:$M$10,$B$3):C$10)) | D26: =IF(OR($B$3="",COLUMN()-1<$B$3,D$14=""),"",SUM(INDEX($B$17:$M$17,$B$3):D$17)+SUM(INDEX($B$10:$M$10,$B$3):D$10)) | E26: =IF(OR($B$3="",COLUMN()-1<$B$3,E$14=""),"",SUM(INDEX($B$17:$M$17,$B$3):E$17)+SUM(INDEX($B$10:$M$10,$B$3):E$10)) | F26: =IF(OR($B$3="",COLUMN()-1<$B$3,F$14=""),"",SUM(INDEX($B$17:$M$17,$B$3):F$17)+SUM(INDEX($B$10:$M$10,$B$3):F$10)) | G26: =IF(OR($B$3="",COLUMN()-1<$B$3,G$14=""),"",SUM(INDEX($B$17:$M$17,$B$3):G$17)+SUM(INDEX($B$10:$M$10,$B$3):G$10)) | H26: =IF(OR($B$3="",COLUMN()-1<$B$3,H$14=""),"",SUM(INDEX($B$17:$M$17,$B$3):H$17)+SUM(INDEX($B$10:$M$10,$B$3):H$10)) | I26: =IF(OR($B$3="",COLUMN()-1<$B$3,I$14=""),"",SUM(INDEX($B$17:$M$17,$B$3):I$17)+SUM(INDEX($B$10:$M$10,$B$3):I$10)) | ... M26: =IF(OR($B$3="",COLUMN()-1<$B$3,M$14=""),"",SUM(INDEX($B$17:$M$17,$B$3):M$17)+SUM(INDEX($B$10:$M$10,$B$3):M$10))
A28: 開始月＝計画のリード数を最初に入れた月。判定する月＝開始月＋6か月。実績は、リード数を入れた月まで計算する。外部費用の計画は年額÷12を自動で入れているので、月ごとに違う場合は上書きする
A29: 判定＝開始月からの累計のCPL（外部費用＋人件費÷リード数）が許容CPL以下なら「上限内」、超えたら「上限超え」
A30: 撤退の判断＝判定する月から毎月、累計で「上限超え」かつ「リード数の達成率が90%未満」なら「撤退を検討」。費用を入れていない施策は判定しない

Sheet セミナー
A1: セミナー | D1: 灰色＝入力 白＝自動計算 単位：万円
A2: 開始月 | B2: {=IF(B3="","計画なし",INDEX($B$6:$M$6,B3))} | C2: 判定する月 | D2: {=IF(D3="","",IF(D3>12,"今期は判定なし",INDEX($B$6:$M$6,D3)))} | E2: 許容CPL | F2: ='はじめに入力'!$I$5
A3: （計算用） | B3: {=IFERROR(MATCH(TRUE,INDEX($B$7:$M$7>0,0),0),"")} | D3: =IF(B3="","",B3+6) | F3: =MATCH($A$1,'はじめに入力'!$A$9:$A$14,0)
A4: 1. 計画（期初に入力）
B5: ※外部費用と人件費は、適宜修正してください。
A6: 項目 | B6: =MONTH(EDATE('はじめに入力'!$A$5,0))&"月" | C6: =MONTH(EDATE('はじめに入力'!$A$5,1))&"月" | D6: =MONTH(EDATE('はじめに入力'!$A$5,2))&"月" | E6: =MONTH(EDATE('はじめに入力'!$A$5,3))&"月" | F6: =MONTH(EDATE('はじめに入力'!$A$5,4))&"月" | G6: =MONTH(EDATE('はじめに入力'!$A$5,5))&"月" | H6: =MONTH(EDATE('はじめに入力'!$A$5,6))&"月" | I6: =MONTH(EDATE('はじめに入力'!$A$5,7))&"月" | J6: =MONTH(EDATE('はじめに入力'!$A$5,8))&"月" | K6: =MONTH(EDATE('はじめに入力'!$A$5,9))&"月" | L6: =MONTH(EDATE('はじめに入力'!$A$5,10))&"月" | M6: =MONTH(EDATE('はじめに入力'!$A$5,11))&"月" | N6: 年間 | O6: 年間の計画と
A7: リード数 | B7: 0 | C7: 13 | D7: 0 | E7: 13 | F7: 0 | G7: 13 | H7: 0 | I7: 13 | J7: 0 | K7: 14 | L7: 0 | M7: 14 | N7: =SUM(B7:M7) | O7: {=IF(N7=INDEX('はじめに入力'!$B$9:$B$14,$F$3),"一致","確認")}
A8: 有効リード数 | B8: 0 | C8: 8 | D8: 0 | E8: 8 | F8: 0 | G8: 8 | H8: 0 | I8: 8 | J8: 0 | K8: 9 | L8: 0 | M8: 9 | N8: =SUM(B8:M8) | O8: {=IF(N8=INDEX('はじめに入力'!$D$9:$D$14,$F$3),"一致","確認")}
A9: 外部費用 | B9: {=INDEX('はじめに入力'!$J$9:$J$14,$F$3)/12} | C9: {=INDEX('はじめに入力'!$J$9:$J$14,$F$3)/12} | D9: {=INDEX('はじめに入力'!$J$9:$J$14,$F$3)/12} | E9: {=INDEX('はじめに入力'!$J$9:$J$14,$F$3)/12} | F9: {=INDEX('はじめに入力'!$J$9:$J$14,$F$3)/12} | G9: {=INDEX('はじめに入力'!$J$9:$J$14,$F$3)/12} | H9: {=INDEX('はじめに入力'!$J$9:$J$14,$F$3)/12} | I9: {=INDEX('はじめに入力'!$J$9:$J$14,$F$3)/12} | ... M9: {=INDEX('はじめに入力'!$J$9:$J$14,$F$3)/12} | N9: =SUM(B9:M9) | O9: {=IF(ROUND(N9,1)=ROUND(INDEX('はじめに入力'!$J$9:$J$14,$F$3),1),"一致","確認")}
A10: 人件費 | B10: {=INDEX('はじめに入力'!$K$9:$K$14,$F$3)/12} | C10: {=INDEX('はじめに入力'!$K$9:$K$14,$F$3)/12} | D10: {=INDEX('はじめに入力'!$K$9:$K$14,$F$3)/12} | E10: {=INDEX('はじめに入力'!$K$9:$K$14,$F$3)/12} | F10: {=INDEX('はじめに入力'!$K$9:$K$14,$F$3)/12} | G10: {=INDEX('はじめに入力'!$K$9:$K$14,$F$3)/12} | H10: {=INDEX('はじめに入力'!$K$9:$K$14,$F$3)/12} | I10: {=INDEX('はじめに入力'!$K$9:$K$14,$F$3)/12} | ... M10: {=INDEX('はじめに入力'!$K$9:$K$14,$F$3)/12} | N10: =SUM(B10:M10)
A12: 2. 実績（「毎月の実績入力」から自動）
A13: 項目 | B13: =B$6 | C13: =C$6 | D13: =D$6 | E13: =E$6 | F13: =F$6 | G13: =G$6 | H13: =H$6 | I13: =I$6 | ... M13: =M$6 | N13: 年間
A14: リード数 | B14: {=IF(INDEX('毎月の実績入力'!C$12:C$45,($F$3-1)*6+1)="","",INDEX('毎月の実績入力'!C$12:C$45,($F$3-1)*6+1))} | C14: {=IF(INDEX('毎月の実績入力'!D$12:D$45,($F$3-1)*6+1)="","",INDEX('毎月の実績入力'!D$12:D$45,($F$3-1)*6+1))} | D14: {=IF(INDEX('毎月の実績入力'!E$12:E$45,($F$3-1)*6+1)="","",INDEX('毎月の実績入力'!E$12:E$45,($F$3-1)*6+1))} | E14: {=IF(INDEX('毎月の実績入力'!F$12:F$45,($F$3-1)*6+1)="","",INDEX('毎月の実績入力'!F$12:F$45,($F$3-1)*6+1))} | F14: {=IF(INDEX('毎月の実績入力'!G$12:G$45,($F$3-1)*6+1)="","",INDEX('毎月の実績入力'!G$12:G$45,($F$3-1)*6+1))} | G14: {=IF(INDEX('毎月の実績入力'!H$12:H$45,($F$3-1)*6+1)="","",INDEX('毎月の実績入力'!H$12:H$45,($F$3-1)*6+1))} | H14: {=IF(INDEX('毎月の実績入力'!I$12:I$45,($F$3-1)*6+1)="","",INDEX('毎月の実績入力'!I$12:I$45,($F$3-1)*6+1))} | I14: {=IF(INDEX('毎月の実績入力'!J$12:J$45,($F$3-1)*6+1)="","",INDEX('毎月の実績入力'!J$12:J$45,($F$3-1)*6+1))} | ... M14: {=IF(INDEX('毎月の実績入力'!N$12:N$45,($F$3-1)*6+1)="","",INDEX('毎月の実績入力'!N$12:N$45,($F$3-1)*6+1))} | N14: =SUM(B14:M14)
A15: 有効リード率 | B15: =IF(OR(B14="",B16=""),"",IFERROR(B16/B14,"")) | C15: =IF(OR(C14="",C16=""),"",IFERROR(C16/C14,"")) | D15: =IF(OR(D14="",D16=""),"",IFERROR(D16/D14,"")) | E15: =IF(OR(E14="",E16=""),"",IFERROR(E16/E14,"")) | F15: =IF(OR(F14="",F16=""),"",IFERROR(F16/F14,"")) | G15: =IF(OR(G14="",G16=""),"",IFERROR(G16/G14,"")) | H15: =IF(OR(H14="",H16=""),"",IFERROR(H16/H14,"")) | I15: =IF(OR(I14="",I16=""),"",IFERROR(I16/I14,"")) | ... M15: =IF(OR(M14="",M16=""),"",IFERROR(M16/M14,"")) | N15: =IFERROR(N16/N14,"")
A16: 有効リード数 | B16: {=IF(INDEX('毎月の実績入力'!C$12:C$45,($F$3-1)*6+2)="","",INDEX('毎月の実績入力'!C$12:C$45,($F$3-1)*6+2))} | C16: {=IF(INDEX('毎月の実績入力'!D$12:D$45,($F$3-1)*6+2)="","",INDEX('毎月の実績入力'!D$12:D$45,($F$3-1)*6+2))} | D16: {=IF(INDEX('毎月の実績入力'!E$12:E$45,($F$3-1)*6+2)="","",INDEX('毎月の実績入力'!E$12:E$45,($F$3-1)*6+2))} | E16: {=IF(INDEX('毎月の実績入力'!F$12:F$45,($F$3-1)*6+2)="","",INDEX('毎月の実績入力'!F$12:F$45,($F$3-1)*6+2))} | F16: {=IF(INDEX('毎月の実績入力'!G$12:G$45,($F$3-1)*6+2)="","",INDEX('毎月の実績入力'!G$12:G$45,($F$3-1)*6+2))} | G16: {=IF(INDEX('毎月の実績入力'!H$12:H$45,($F$3-1)*6+2)="","",INDEX('毎月の実績入力'!H$12:H$45,($F$3-1)*6+2))} | H16: {=IF(INDEX('毎月の実績入力'!I$12:I$45,($F$3-1)*6+2)="","",INDEX('毎月の実績入力'!I$12:I$45,($F$3-1)*6+2))} | I16: {=IF(INDEX('毎月の実績入力'!J$12:J$45,($F$3-1)*6+2)="","",INDEX('毎月の実績入力'!J$12:J$45,($F$3-1)*6+2))} | ... M16: {=IF(INDEX('毎月の実績入力'!N$12:N$45,($F$3-1)*6+2)="","",INDEX('毎月の実績入力'!N$12:N$45,($F$3-1)*6+2))} | N16: =SUM(B16:M16)
A17: 外部費用 | B17: {=IF(INDEX('毎月の実績入力'!C$12:C$45,($F$3-1)*6+3)="","",INDEX('毎月の実績入力'!C$12:C$45,($F$3-1)*6+3))} | C17: {=IF(INDEX('毎月の実績入力'!D$12:D$45,($F$3-1)*6+3)="","",INDEX('毎月の実績入力'!D$12:D$45,($F$3-1)*6+3))} | D17: {=IF(INDEX('毎月の実績入力'!E$12:E$45,($F$3-1)*6+3)="","",INDEX('毎月の実績入力'!E$12:E$45,($F$3-1)*6+3))} | E17: {=IF(INDEX('毎月の実績入力'!F$12:F$45,($F$3-1)*6+3)="","",INDEX('毎月の実績入力'!F$12:F$45,($F$3-1)*6+3))} | F17: {=IF(INDEX('毎月の実績入力'!G$12:G$45,($F$3-1)*6+3)="","",INDEX('毎月の実績入力'!G$12:G$45,($F$3-1)*6+3))} | G17: {=IF(INDEX('毎月の実績入力'!H$12:H$45,($F$3-1)*6+3)="","",INDEX('毎月の実績入力'!H$12:H$45,($F$3-1)*6+3))} | H17: {=IF(INDEX('毎月の実績入力'!I$12:I$45,($F$3-1)*6+3)="","",INDEX('毎月の実績入力'!I$12:I$45,($F$3-1)*6+3))} | I17: {=IF(INDEX('毎月の実績入力'!J$12:J$45,($F$3-1)*6+3)="","",INDEX('毎月の実績入力'!J$12:J$45,($F$3-1)*6+3))} | ... M17: {=IF(INDEX('毎月の実績入力'!N$12:N$45,($F$3-1)*6+3)="","",INDEX('毎月の実績入力'!N$12:N$45,($F$3-1)*6+3))} | N17: =SUM(B17:M17)
A19: 3. 判定（開始月からの累計）
A20: 項目 | B20: =B$6 | C20: =C$6 | D20: =D$6 | E20: =E$6 | F20: =F$6 | G20: =G$6 | H20: =H$6 | I20: =I$6 | ... M20: =M$6
A21: リード数の達成率 | B21: =IF(B26="","",IFERROR(SUM(INDEX($B$14:$M$14,$B$3):B$14)/SUM(INDEX($B$7:$M$7,$B$3):B$7),"")) | C21: =IF(C26="","",IFERROR(SUM(INDEX($B$14:$M$14,$B$3):C$14)/SUM(INDEX($B$7:$M$7,$B$3):C$7),"")) | D21: =IF(D26="","",IFERROR(SUM(INDEX($B$14:$M$14,$B$3):D$14)/SUM(INDEX($B$7:$M$7,$B$3):D$7),"")) | E21: =IF(E26="","",IFERROR(SUM(INDEX($B$14:$M$14,$B$3):E$14)/SUM(INDEX($B$7:$M$7,$B$3):E$7),"")) | F21: =IF(F26="","",IFERROR(SUM(INDEX($B$14:$M$14,$B$3):F$14)/SUM(INDEX($B$7:$M$7,$B$3):F$7),"")) | G21: =IF(G26="","",IFERROR(SUM(INDEX($B$14:$M$14,$B$3):G$14)/SUM(INDEX($B$7:$M$7,$B$3):G$7),"")) | H21: =IF(H26="","",IFERROR(SUM(INDEX($B$14:$M$14,$B$3):H$14)/SUM(INDEX($B$7:$M$7,$B$3):H$7),"")) | I21: =IF(I26="","",IFERROR(SUM(INDEX($B$14:$M$14,$B$3):I$14)/SUM(INDEX($B$7:$M$7,$B$3):I$7),"")) | ... M21: =IF(M26="","",IFERROR(SUM(INDEX($B$14:$M$14,$B$3):M$14)/SUM(INDEX($B$7:$M$7,$B$3):M$7),""))
A22: 有効リード数の達成率 | B22: =IF(B26="","",IFERROR(SUM(INDEX($B$16:$M$16,$B$3):B$16)/SUM(INDEX($B$8:$M$8,$B$3):B$8),"")) | C22: =IF(C26="","",IFERROR(SUM(INDEX($B$16:$M$16,$B$3):C$16)/SUM(INDEX($B$8:$M$8,$B$3):C$8),"")) | D22: =IF(D26="","",IFERROR(SUM(INDEX($B$16:$M$16,$B$3):D$16)/SUM(INDEX($B$8:$M$8,$B$3):D$8),"")) | E22: =IF(E26="","",IFERROR(SUM(INDEX($B$16:$M$16,$B$3):E$16)/SUM(INDEX($B$8:$M$8,$B$3):E$8),"")) | F22: =IF(F26="","",IFERROR(SUM(INDEX($B$16:$M$16,$B$3):F$16)/SUM(INDEX($B$8:$M$8,$B$3):F$8),"")) | G22: =IF(G26="","",IFERROR(SUM(INDEX($B$16:$M$16,$B$3):G$16)/SUM(INDEX($B$8:$M$8,$B$3):G$8),"")) | H22: =IF(H26="","",IFERROR(SUM(INDEX($B$16:$M$16,$B$3):H$16)/SUM(INDEX($B$8:$M$8,$B$3):H$8),"")) | I22: =IF(I26="","",IFERROR(SUM(INDEX($B$16:$M$16,$B$3):I$16)/SUM(INDEX($B$8:$M$8,$B$3):I$8),"")) | ... M22: =IF(M26="","",IFERROR(SUM(INDEX($B$16:$M$16,$B$3):M$16)/SUM(INDEX($B$8:$M$8,$B$3):M$8),""))
A23: CPL | B23: =IF(B26="","",IFERROR(B26/SUM(INDEX($B$14:$M$14,$B$3):B$14),"―")) | C23: =IF(C26="","",IFERROR(C26/SUM(INDEX($B$14:$M$14,$B$3):C$14),"―")) | D23: =IF(D26="","",IFERROR(D26/SUM(INDEX($B$14:$M$14,$B$3):D$14),"―")) | E23: =IF(E26="","",IFERROR(E26/SUM(INDEX($B$14:$M$14,$B$3):E$14),"―")) | F23: =IF(F26="","",IFERROR(F26/SUM(INDEX($B$14:$M$14,$B$3):F$14),"―")) | G23: =IF(G26="","",IFERROR(G26/SUM(INDEX($B$14:$M$14,$B$3):G$14),"―")) | H23: =IF(H26="","",IFERROR(H26/SUM(INDEX($B$14:$M$14,$B$3):H$14),"―")) | I23: =IF(I26="","",IFERROR(I26/SUM(INDEX($B$14:$M$14,$B$3):I$14),"―")) | ... M23: =IF(M26="","",IFERROR(M26/SUM(INDEX($B$14:$M$14,$B$3):M$14),"―"))
A24: 判定 | B24: =IF(B26="","",IF(SUM(INDEX($B$17:$M$17,$B$3):B$17)=0,"費用なし",IF(OR(B23="―",B23>$F$2),"上限超え","上限内"))) | C24: =IF(C26="","",IF(SUM(INDEX($B$17:$M$17,$B$3):C$17)=0,"費用なし",IF(OR(C23="―",C23>$F$2),"上限超え","上限内"))) | D24: =IF(D26="","",IF(SUM(INDEX($B$17:$M$17,$B$3):D$17)=0,"費用なし",IF(OR(D23="―",D23>$F$2),"上限超え","上限内"))) | E24: =IF(E26="","",IF(SUM(INDEX($B$17:$M$17,$B$3):E$17)=0,"費用なし",IF(OR(E23="―",E23>$F$2),"上限超え","上限内"))) | F24: =IF(F26="","",IF(SUM(INDEX($B$17:$M$17,$B$3):F$17)=0,"費用なし",IF(OR(F23="―",F23>$F$2),"上限超え","上限内"))) | G24: =IF(G26="","",IF(SUM(INDEX($B$17:$M$17,$B$3):G$17)=0,"費用なし",IF(OR(G23="―",G23>$F$2),"上限超え","上限内"))) | H24: =IF(H26="","",IF(SUM(INDEX($B$17:$M$17,$B$3):H$17)=0,"費用なし",IF(OR(H23="―",H23>$F$2),"上限超え","上限内"))) | I24: =IF(I26="","",IF(SUM(INDEX($B$17:$M$17,$B$3):I$17)=0,"費用なし",IF(OR(I23="―",I23>$F$2),"上限超え","上限内"))) | ... M24: =IF(M26="","",IF(SUM(INDEX($B$17:$M$17,$B$3):M$17)=0,"費用なし",IF(OR(M23="―",M23>$F$2),"上限超え","上限内")))
A25: 撤退の判断 | B25: =IF(B26="","",IF(COLUMN()-1<$D$3,"判定前",IF(B24="費用なし","判定しない",IF(AND(B24="上限超え",B21<0.9),"撤退を検討","なし")))) | C25: =IF(C26="","",IF(COLUMN()-1<$D$3,"判定前",IF(C24="費用なし","判定しない",IF(AND(C24="上限超え",C21<0.9),"撤退を検討","なし")))) | D25: =IF(D26="","",IF(COLUMN()-1<$D$3,"判定前",IF(D24="費用なし","判定しない",IF(AND(D24="上限超え",D21<0.9),"撤退を検討","なし")))) | E25: =IF(E26="","",IF(COLUMN()-1<$D$3,"判定前",IF(E24="費用なし","判定しない",IF(AND(E24="上限超え",E21<0.9),"撤退を検討","なし")))) | F25: =IF(F26="","",IF(COLUMN()-1<$D$3,"判定前",IF(F24="費用なし","判定しない",IF(AND(F24="上限超え",F21<0.9),"撤退を検討","なし")))) | G25: =IF(G26="","",IF(COLUMN()-1<$D$3,"判定前",IF(G24="費用なし","判定しない",IF(AND(G24="上限超え",G21<0.9),"撤退を検討","なし")))) | H25: =IF(H26="","",IF(COLUMN()-1<$D$3,"判定前",IF(H24="費用なし","判定しない",IF(AND(H24="上限超え",H21<0.9),"撤退を検討","なし")))) | I25: =IF(I26="","",IF(COLUMN()-1<$D$3,"判定前",IF(I24="費用なし","判定しない",IF(AND(I24="上限超え",I21<0.9),"撤退を検討","なし")))) | ... M25: =IF(M26="","",IF(COLUMN()-1<$D$3,"判定前",IF(M24="費用なし","判定しない",IF(AND(M24="上限超え",M21<0.9),"撤退を検討","なし"))))
A26: 費用（外部費用＋人件費） | B26: =IF(OR($B$3="",COLUMN()-1<$B$3,B$14=""),"",SUM(INDEX($B$17:$M$17,$B$3):B$17)+SUM(INDEX($B$10:$M$10,$B$3):B$10)) | C26: =IF(OR($B$3="",COLUMN()-1<$B$3,C$14=""),"",SUM(INDEX($B$17:$M$17,$B$3):C$17)+SUM(INDEX($B$10:$M$10,$B$3):C$10)) | D26: =IF(OR($B$3="",COLUMN()-1<$B$3,D$14=""),"",SUM(INDEX($B$17:$M$17,$B$3):D$17)+SUM(INDEX($B$10:$M$10,$B$3):D$10)) | E26: =IF(OR($B$3="",COLUMN()-1<$B$3,E$14=""),"",SUM(INDEX($B$17:$M$17,$B$3):E$17)+SUM(INDEX($B$10:$M$10,$B$3):E$10)) | F26: =IF(OR($B$3="",COLUMN()-1<$B$3,F$14=""),"",SUM(INDEX($B$17:$M$17,$B$3):F$17)+SUM(INDEX($B$10:$M$10,$B$3):F$10)) | G26: =IF(OR($B$3="",COLUMN()-1<$B$3,G$14=""),"",SUM(INDEX($B$17:$M$17,$B$3):G$17)+SUM(INDEX($B$10:$M$10,$B$3):G$10)) | H26: =IF(OR($B$3="",COLUMN()-1<$B$3,H$14=""),"",SUM(INDEX($B$17:$M$17,$B$3):H$17)+SUM(INDEX($B$10:$M$10,$B$3):H$10)) | I26: =IF(OR($B$3="",COLUMN()-1<$B$3,I$14=""),"",SUM(INDEX($B$17:$M$17,$B$3):I$17)+SUM(INDEX($B$10:$M$10,$B$3):I$10)) | ... M26: =IF(OR($B$3="",COLUMN()-1<$B$3,M$14=""),"",SUM(INDEX($B$17:$M$17,$B$3):M$17)+SUM(INDEX($B$10:$M$10,$B$3):M$10))
A28: 開始月＝計画のリード数を最初に入れた月。判定する月＝開始月＋6か月。実績は、リード数を入れた月まで計算する。外部費用の計画は年額÷12を自動で入れているので、月ごとに違う場合は上書きする
A29: 判定＝開始月からの累計のCPL（外部費用＋人件費÷リード数）が許容CPL以下なら「上限内」、超えたら「上限超え」
A30: 撤退の判断＝判定する月から毎月、累計で「上限超え」かつ「リード数の達成率が90%未満」なら「撤退を検討」。費用を入れていない施策は判定しない

Sheet Web広告
A1: Web広告 | D1: 灰色＝入力 白＝自動計算 単位：万円
A2: 開始月 | B2: {=IF(B3="","計画なし",INDEX($B$6:$M$6,B3))} | C2: 判定する月 | D2: {=IF(D3="","",IF(D3>12,"今期は判定なし",INDEX($B$6:$M$6,D3)))} | E2: 許容CPL | F2: ='はじめに入力'!$I$5
A3: （計算用） | B3: {=IFERROR(MATCH(TRUE,INDEX($B$7:$M$7>0,0),0),"")} | D3: =IF(B3="","",B3+6) | F3: =MATCH($A$1,'はじめに入力'!$A$9:$A$14,0)
A4: 1. 計画（期初に入力）
B5: ※外部費用と人件費は、適宜修正してください。
A6: 項目 | B6: =MONTH(EDATE('はじめに入力'!$A$5,0))&"月" | C6: =MONTH(EDATE('はじめに入力'!$A$5,1))&"月" | D6: =MONTH(EDATE('はじめに入力'!$A$5,2))&"月" | E6: =MONTH(EDATE('はじめに入力'!$A$5,3))&"月" | F6: =MONTH(EDATE('はじめに入力'!$A$5,4))&"月" | G6: =MONTH(EDATE('はじめに入力'!$A$5,5))&"月" | H6: =MONTH(EDATE('はじめに入力'!$A$5,6))&"月" | I6: =MONTH(EDATE('はじめに入力'!$A$5,7))&"月" | J6: =MONTH(EDATE('はじめに入力'!$A$5,8))&"月" | K6: =MONTH(EDATE('はじめに入力'!$A$5,9))&"月" | L6: =MONTH(EDATE('はじめに入力'!$A$5,10))&"月" | M6: =MONTH(EDATE('はじめに入力'!$A$5,11))&"月" | N6: 年間 | O6: 年間の計画と
A7: リード数 | B7: 5 | C7: 9 | D7: 9 | E7: 9 | F7: 9 | G7: 9 | H7: 9 | I7: 9 | J7: 10 | K7: 6 | L7: 6 | M7: 5 | N7: =SUM(B7:M7) | O7: {=IF(N7=INDEX('はじめに入力'!$B$9:$B$14,$F$3),"一致","確認")}
A8: 有効リード数 | B8: 2 | C8: 4 | D8: 4 | E8: 4 | F8: 4 | G8: 4 | H8: 4 | I8: 4 | J8: 5 | K8: 3 | L8: 3 | M8: 2 | N8: =SUM(B8:M8) | O8: {=IF(N8=INDEX('はじめに入力'!$D$9:$D$14,$F$3),"一致","確認")}
A9: 外部費用 | B9: {=INDEX('はじめに入力'!$J$9:$J$14,$F$3)/12} | C9: {=INDEX('はじめに入力'!$J$9:$J$14,$F$3)/12} | D9: {=INDEX('はじめに入力'!$J$9:$J$14,$F$3)/12} | E9: {=INDEX('はじめに入力'!$J$9:$J$14,$F$3)/12} | F9: {=INDEX('はじめに入力'!$J$9:$J$14,$F$3)/12} | G9: {=INDEX('はじめに入力'!$J$9:$J$14,$F$3)/12} | H9: {=INDEX('はじめに入力'!$J$9:$J$14,$F$3)/12} | I9: {=INDEX('はじめに入力'!$J$9:$J$14,$F$3)/12} | ... M9: {=INDEX('はじめに入力'!$J$9:$J$14,$F$3)/12} | N9: =SUM(B9:M9) | O9: {=IF(ROUND(N9,1)=ROUND(INDEX('はじめに入力'!$J$9:$J$14,$F$3),1),"一致","確認")}
A10: 人件費 | B10: {=INDEX('はじめに入力'!$K$9:$K$14,$F$3)/12} | C10: {=INDEX('はじめに入力'!$K$9:$K$14,$F$3)/12} | D10: {=INDEX('はじめに入力'!$K$9:$K$14,$F$3)/12} | E10: {=INDEX('はじめに入力'!$K$9:$K$14,$F$3)/12} | F10: {=INDEX('はじめに入力'!$K$9:$K$14,$F$3)/12} | G10: {=INDEX('はじめに入力'!$K$9:$K$14,$F$3)/12} | H10: {=INDEX('はじめに入力'!$K$9:$K$14,$F$3)/12} | I10: {=INDEX('はじめに入力'!$K$9:$K$14,$F$3)/12} | ... M10: {=INDEX('はじめに入力'!$K$9:$K$14,$F$3)/12} | N10: =SUM(B10:M10)
A12: 2. 実績（「毎月の実績入力」から自動）
A13: 項目 | B13: =B$6 | C13: =C$6 | D13: =D$6 | E13: =E$6 | F13: =F$6 | G13: =G$6 | H13: =H$6 | I13: =I$6 | ... M13: =M$6 | N13: 年間
A14: リード数 | B14: {=IF(INDEX('毎月の実績入力'!C$12:C$45,($F$3-1)*6+1)="","",INDEX('毎月の実績入力'!C$12:C$45,($F$3-1)*6+1))} | C14: {=IF(INDEX('毎月の実績入力'!D$12:D$45,($F$3-1)*6+1)="","",INDEX('毎月の実績入力'!D$12:D$45,($F$3-1)*6+1))} | D14: {=IF(INDEX('毎月の実績入力'!E$12:E$45,($F$3-1)*6+1)="","",INDEX('毎月の実績入力'!E$12:E$45,($F$3-1)*6+1))} | E14: {=IF(INDEX('毎月の実績入力'!F$12:F$45,($F$3-1)*6+1)="","",INDEX('毎月の実績入力'!F$12:F$45,($F$3-1)*6+1))} | F14: {=IF(INDEX('毎月の実績入力'!G$12:G$45,($F$3-1)*6+1)="","",INDEX('毎月の実績入力'!G$12:G$45,($F$3-1)*6+1))} | G14: {=IF(INDEX('毎月の実績入力'!H$12:H$45,($F$3-1)*6+1)="","",INDEX('毎月の実績入力'!H$12:H$45,($F$3-1)*6+1))} | H14: {=IF(INDEX('毎月の実績入力'!I$12:I$45,($F$3-1)*6+1)="","",INDEX('毎月の実績入力'!I$12:I$45,($F$3-1)*6+1))} | I14: {=IF(INDEX('毎月の実績入力'!J$12:J$45,($F$3-1)*6+1)="","",INDEX('毎月の実績入力'!J$12:J$45,($F$3-1)*6+1))} | ... M14: {=IF(INDEX('毎月の実績入力'!N$12:N$45,($F$3-1)*6+1)="","",INDEX('毎月の実績入力'!N$12:N$45,($F$3-1)*6+1))} | N14: =SUM(B14:M14)
A15: 有効リード率 | B15: =IF(OR(B14="",B16=""),"",IFERROR(B16/B14,"")) | C15: =IF(OR(C14="",C16=""),"",IFERROR(C16/C14,"")) | D15: =IF(OR(D14="",D16=""),"",IFERROR(D16/D14,"")) | E15: =IF(OR(E14="",E16=""),"",IFERROR(E16/E14,"")) | F15: =IF(OR(F14="",F16=""),"",IFERROR(F16/F14,"")) | G15: =IF(OR(G14="",G16=""),"",IFERROR(G16/G14,"")) | H15: =IF(OR(H14="",H16=""),"",IFERROR(H16/H14,"")) | I15: =IF(OR(I14="",I16=""),"",IFERROR(I16/I14,"")) | ... M15: =IF(OR(M14="",M16=""),"",IFERROR(M16/M14,"")) | N15: =IFERROR(N16/N14,"")
A16: 有効リード数 | B16: {=IF(INDEX('毎月の実績入力'!C$12:C$45,($F$3-1)*6+2)="","",INDEX('毎月の実績入力'!C$12:C$45,($F$3-1)*6+2))} | C16: {=IF(INDEX('毎月の実績入力'!D$12:D$45,($F$3-1)*6+2)="","",INDEX('毎月の実績入力'!D$12:D$45,($F$3-1)*6+2))} | D16: {=IF(INDEX('毎月の実績入力'!E$12:E$45,($F$3-1)*6+2)="","",INDEX('毎月の実績入力'!E$12:E$45,($F$3-1)*6+2))} | E16: {=IF(INDEX('毎月の実績入力'!F$12:F$45,($F$3-1)*6+2)="","",INDEX('毎月の実績入力'!F$12:F$45,($F$3-1)*6+2))} | F16: {=IF(INDEX('毎月の実績入力'!G$12:G$45,($F$3-1)*6+2)="","",INDEX('毎月の実績入力'!G$12:G$45,($F$3-1)*6+2))} | G16: {=IF(INDEX('毎月の実績入力'!H$12:H$45,($F$3-1)*6+2)="","",INDEX('毎月の実績入力'!H$12:H$45,($F$3-1)*6+2))} | H16: {=IF(INDEX('毎月の実績入力'!I$12:I$45,($F$3-1)*6+2)="","",INDEX('毎月の実績入力'!I$12:I$45,($F$3-1)*6+2))} | I16: {=IF(INDEX('毎月の実績入力'!J$12:J$45,($F$3-1)*6+2)="","",INDEX('毎月の実績入力'!J$12:J$45,($F$3-1)*6+2))} | ... M16: {=IF(INDEX('毎月の実績入力'!N$12:N$45,($F$3-1)*6+2)="","",INDEX('毎月の実績入力'!N$12:N$45,($F$3-1)*6+2))} | N16: =SUM(B16:M16)
A17: 外部費用 | B17: {=IF(INDEX('毎月の実績入力'!C$12:C$45,($F$3-1)*6+3)="","",INDEX('毎月の実績入力'!C$12:C$45,($F$3-1)*6+3))} | C17: {=IF(INDEX('毎月の実績入力'!D$12:D$45,($F$3-1)*6+3)="","",INDEX('毎月の実績入力'!D$12:D$45,($F$3-1)*6+3))} | D17: {=IF(INDEX('毎月の実績入力'!E$12:E$45,($F$3-1)*6+3)="","",INDEX('毎月の実績入力'!E$12:E$45,($F$3-1)*6+3))} | E17: {=IF(INDEX('毎月の実績入力'!F$12:F$45,($F$3-1)*6+3)="","",INDEX('毎月の実績入力'!F$12:F$45,($F$3-1)*6+3))} | F17: {=IF(INDEX('毎月の実績入力'!G$12:G$45,($F$3-1)*6+3)="","",INDEX('毎月の実績入力'!G$12:G$45,($F$3-1)*6+3))} | G17: {=IF(INDEX('毎月の実績入力'!H$12:H$45,($F$3-1)*6+3)="","",INDEX('毎月の実績入力'!H$12:H$45,($F$3-1)*6+3))} | H17: {=IF(INDEX('毎月の実績入力'!I$12:I$45,($F$3-1)*6+3)="","",INDEX('毎月の実績入力'!I$12:I$45,($F$3-1)*6+3))} | I17: {=IF(INDEX('毎月の実績入力'!J$12:J$45,($F$3-1)*6+3)="","",INDEX('毎月の実績入力'!J$12:J$45,($F$3-1)*6+3))} | ... M17: {=IF(INDEX('毎月の実績入力'!N$12:N$45,($F$3-1)*6+3)="","",INDEX('毎月の実績入力'!N$12:N$45,($F$3-1)*6+3))} | N17: =SUM(B17:M17)
A19: 3. 判定（開始月からの累計）
A20: 項目 | B20: =B$6 | C20: =C$6 | D20: =D$6 | E20: =E$6 | F20: =F$6 | G20: =G$6 | H20: =H$6 | I20: =I$6 | ... M20: =M$6
A21: リード数の達成率 | B21: =IF(B26="","",IFERROR(SUM(INDEX($B$14:$M$14,$B$3):B$14)/SUM(INDEX($B$7:$M$7,$B$3):B$7),"")) | C21: =IF(C26="","",IFERROR(SUM(INDEX($B$14:$M$14,$B$3):C$14)/SUM(INDEX($B$7:$M$7,$B$3):C$7),"")) | D21: =IF(D26="","",IFERROR(SUM(INDEX($B$14:$M$14,$B$3):D$14)/SUM(INDEX($B$7:$M$7,$B$3):D$7),"")) | E21: =IF(E26="","",IFERROR(SUM(INDEX($B$14:$M$14,$B$3):E$14)/SUM(INDEX($B$7:$M$7,$B$3):E$7),"")) | F21: =IF(F26="","",IFERROR(SUM(INDEX($B$14:$M$14,$B$3):F$14)/SUM(INDEX($B$7:$M$7,$B$3):F$7),"")) | G21: =IF(G26="","",IFERROR(SUM(INDEX($B$14:$M$14,$B$3):G$14)/SUM(INDEX($B$7:$M$7,$B$3):G$7),"")) | H21: =IF(H26="","",IFERROR(SUM(INDEX($B$14:$M$14,$B$3):H$14)/SUM(INDEX($B$7:$M$7,$B$3):H$7),"")) | I21: =IF(I26="","",IFERROR(SUM(INDEX($B$14:$M$14,$B$3):I$14)/SUM(INDEX($B$7:$M$7,$B$3):I$7),"")) | ... M21: =IF(M26="","",IFERROR(SUM(INDEX($B$14:$M$14,$B$3):M$14)/SUM(INDEX($B$7:$M$7,$B$3):M$7),""))
A22: 有効リード数の達成率 | B22: =IF(B26="","",IFERROR(SUM(INDEX($B$16:$M$16,$B$3):B$16)/SUM(INDEX($B$8:$M$8,$B$3):B$8),"")) | C22: =IF(C26="","",IFERROR(SUM(INDEX($B$16:$M$16,$B$3):C$16)/SUM(INDEX($B$8:$M$8,$B$3):C$8),"")) | D22: =IF(D26="","",IFERROR(SUM(INDEX($B$16:$M$16,$B$3):D$16)/SUM(INDEX($B$8:$M$8,$B$3):D$8),"")) | E22: =IF(E26="","",IFERROR(SUM(INDEX($B$16:$M$16,$B$3):E$16)/SUM(INDEX($B$8:$M$8,$B$3):E$8),"")) | F22: =IF(F26="","",IFERROR(SUM(INDEX($B$16:$M$16,$B$3):F$16)/SUM(INDEX($B$8:$M$8,$B$3):F$8),"")) | G22: =IF(G26="","",IFERROR(SUM(INDEX($B$16:$M$16,$B$3):G$16)/SUM(INDEX($B$8:$M$8,$B$3):G$8),"")) | H22: =IF(H26="","",IFERROR(SUM(INDEX($B$16:$M$16,$B$3):H$16)/SUM(INDEX($B$8:$M$8,$B$3):H$8),"")) | I22: =IF(I26="","",IFERROR(SUM(INDEX($B$16:$M$16,$B$3):I$16)/SUM(INDEX($B$8:$M$8,$B$3):I$8),"")) | ... M22: =IF(M26="","",IFERROR(SUM(INDEX($B$16:$M$16,$B$3):M$16)/SUM(INDEX($B$8:$M$8,$B$3):M$8),""))
A23: CPL | B23: =IF(B26="","",IFERROR(B26/SUM(INDEX($B$14:$M$14,$B$3):B$14),"―")) | C23: =IF(C26="","",IFERROR(C26/SUM(INDEX($B$14:$M$14,$B$3):C$14),"―")) | D23: =IF(D26="","",IFERROR(D26/SUM(INDEX($B$14:$M$14,$B$3):D$14),"―")) | E23: =IF(E26="","",IFERROR(E26/SUM(INDEX($B$14:$M$14,$B$3):E$14),"―")) | F23: =IF(F26="","",IFERROR(F26/SUM(INDEX($B$14:$M$14,$B$3):F$14),"―")) | G23: =IF(G26="","",IFERROR(G26/SUM(INDEX($B$14:$M$14,$B$3):G$14),"―")) | H23: =IF(H26="","",IFERROR(H26/SUM(INDEX($B$14:$M$14,$B$3):H$14),"―")) | I23: =IF(I26="","",IFERROR(I26/SUM(INDEX($B$14:$M$14,$B$3):I$14),"―")) | ... M23: =IF(M26="","",IFERROR(M26/SUM(INDEX($B$14:$M$14,$B$3):M$14),"―"))
A24: 判定 | B24: =IF(B26="","",IF(SUM(INDEX($B$17:$M$17,$B$3):B$17)=0,"費用なし",IF(OR(B23="―",B23>$F$2),"上限超え","上限内"))) | C24: =IF(C26="","",IF(SUM(INDEX($B$17:$M$17,$B$3):C$17)=0,"費用なし",IF(OR(C23="―",C23>$F$2),"上限超え","上限内"))) | D24: =IF(D26="","",IF(SUM(INDEX($B$17:$M$17,$B$3):D$17)=0,"費用なし",IF(OR(D23="―",D23>$F$2),"上限超え","上限内"))) | E24: =IF(E26="","",IF(SUM(INDEX($B$17:$M$17,$B$3):E$17)=0,"費用なし",IF(OR(E23="―",E23>$F$2),"上限超え","上限内"))) | F24: =IF(F26="","",IF(SUM(INDEX($B$17:$M$17,$B$3):F$17)=0,"費用なし",IF(OR(F23="―",F23>$F$2),"上限超え","上限内"))) | G24: =IF(G26="","",IF(SUM(INDEX($B$17:$M$17,$B$3):G$17)=0,"費用なし",IF(OR(G23="―",G23>$F$2),"上限超え","上限内"))) | H24: =IF(H26="","",IF(SUM(INDEX($B$17:$M$17,$B$3):H$17)=0,"費用なし",IF(OR(H23="―",H23>$F$2),"上限超え","上限内"))) | I24: =IF(I26="","",IF(SUM(INDEX($B$17:$M$17,$B$3):I$17)=0,"費用なし",IF(OR(I23="―",I23>$F$2),"上限超え","上限内"))) | ... M24: =IF(M26="","",IF(SUM(INDEX($B$17:$M$17,$B$3):M$17)=0,"費用なし",IF(OR(M23="―",M23>$F$2),"上限超え","上限内")))
A25: 撤退の判断 | B25: =IF(B26="","",IF(COLUMN()-1<$D$3,"判定前",IF(B24="費用なし","判定しない",IF(AND(B24="上限超え",B21<0.9),"撤退を検討","なし")))) | C25: =IF(C26="","",IF(COLUMN()-1<$D$3,"判定前",IF(C24="費用なし","判定しない",IF(AND(C24="上限超え",C21<0.9),"撤退を検討","なし")))) | D25: =IF(D26="","",IF(COLUMN()-1<$D$3,"判定前",IF(D24="費用なし","判定しない",IF(AND(D24="上限超え",D21<0.9),"撤退を検討","なし")))) | E25: =IF(E26="","",IF(COLUMN()-1<$D$3,"判定前",IF(E24="費用なし","判定しない",IF(AND(E24="上限超え",E21<0.9),"撤退を検討","なし")))) | F25: =IF(F26="","",IF(COLUMN()-1<$D$3,"判定前",IF(F24="費用なし","判定しない",IF(AND(F24="上限超え",F21<0.9),"撤退を検討","なし")))) | G25: =IF(G26="","",IF(COLUMN()-1<$D$3,"判定前",IF(G24="費用なし","判定しない",IF(AND(G24="上限超え",G21<0.9),"撤退を検討","なし")))) | H25: =IF(H26="","",IF(COLUMN()-1<$D$3,"判定前",IF(H24="費用なし","判定しない",IF(AND(H24="上限超え",H21<0.9),"撤退を検討","なし")))) | I25: =IF(I26="","",IF(COLUMN()-1<$D$3,"判定前",IF(I24="費用なし","判定しない",IF(AND(I24="上限超え",I21<0.9),"撤退を検討","なし")))) | ... M25: =IF(M26="","",IF(COLUMN()-1<$D$3,"判定前",IF(M24="費用なし","判定しない",IF(AND(M24="上限超え",M21<0.9),"撤退を検討","なし"))))
A26: 費用（外部費用＋人件費） | B26: =IF(OR($B$3="",COLUMN()-1<$B$3,B$14=""),"",SUM(INDEX($B$17:$M$17,$B$3):B$17)+SUM(INDEX($B$10:$M$10,$B$3):B$10)) | C26: =IF(OR($B$3="",COLUMN()-1<$B$3,C$14=""),"",SUM(INDEX($B$17:$M$17,$B$3):C$17)+SUM(INDEX($B$10:$M$10,$B$3):C$10)) | D26: =IF(OR($B$3="",COLUMN()-1<$B$3,D$14=""),"",SUM(INDEX($B$17:$M$17,$B$3):D$17)+SUM(INDEX($B$10:$M$10,$B$3):D$10)) | E26: =IF(OR($B$3="",COLUMN()-1<$B$3,E$14=""),"",SUM(INDEX($B$17:$M$17,$B$3):E$17)+SUM(INDEX($B$10:$M$10,$B$3):E$10)) | F26: =IF(OR($B$3="",COLUMN()-1<$B$3,F$14=""),"",SUM(INDEX($B$17:$M$17,$B$3):F$17)+SUM(INDEX($B$10:$M$10,$B$3):F$10)) | G26: =IF(OR($B$3="",COLUMN()-1<$B$3,G$14=""),"",SUM(INDEX($B$17:$M$17,$B$3):G$17)+SUM(INDEX($B$10:$M$10,$B$3):G$10)) | H26: =IF(OR($B$3="",COLUMN()-1<$B$3,H$14=""),"",SUM(INDEX($B$17:$M$17,$B$3):H$17)+SUM(INDEX($B$10:$M$10,$B$3):H$10)) | I26: =IF(OR($B$3="",COLUMN()-1<$B$3,I$14=""),"",SUM(INDEX($B$17:$M$17,$B$3):I$17)+SUM(INDEX($B$10:$M$10,$B$3):I$10)) | ... M26: =IF(OR($B$3="",COLUMN()-1<$B$3,M$14=""),"",SUM(INDEX($B$17:$M$17,$B$3):M$17)+SUM(INDEX($B$10:$M$10,$B$3):M$10))
A28: 開始月＝計画のリード数を最初に入れた月。判定する月＝開始月＋6か月。実績は、リード数を入れた月まで計算する。外部費用の計画は年額÷12を自動で入れているので、月ごとに違う場合は上書きする
A29: 判定＝開始月からの累計のCPL（外部費用＋人件費÷リード数）が許容CPL以下なら「上限内」、超えたら「上限超え」
A30: 撤退の判断＝判定する月から毎月、累計で「上限超え」かつ「リード数の達成率が90%未満」なら「撤退を検討」。費用を入れていない施策は判定しない

Sheet 自社サイト
A1: 自社サイト | D1: 灰色＝入力 白＝自動計算 単位：万円
A2: 開始月 | B2: {=IF(B3="","計画なし",INDEX($B$6:$M$6,B3))} | C2: 判定する月 | D2: {=IF(D3="","",IF(D3>12,"今期は判定なし",INDEX($B$6:$M$6,D3)))} | E2: 許容CPL | F2: ='はじめに入力'!$I$5
A3: （計算用） | B3: {=IFERROR(MATCH(TRUE,INDEX($B$7:$M$7>0,0),0),"")} | D3: =IF(B3="","",B3+6) | F3: =MATCH($A$1,'はじめに入力'!$A$9:$A$14,0)
A4: 1. 計画（期初に入力）
B5: ※外部費用と人件費は、適宜修正してください。
A6: 項目 | B6: =MONTH(EDATE('はじめに入力'!$A$5,0))&"月" | C6: =MONTH(EDATE('はじめに入力'!$A$5,1))&"月" | D6: =MONTH(EDATE('はじめに入力'!$A$5,2))&"月" | E6: =MONTH(EDATE('はじめに入力'!$A$5,3))&"月" | F6: =MONTH(EDATE('はじめに入力'!$A$5,4))&"月" | G6: =MONTH(EDATE('はじめに入力'!$A$5,5))&"月" | H6: =MONTH(EDATE('はじめに入力'!$A$5,6))&"月" | I6: =MONTH(EDATE('はじめに入力'!$A$5,7))&"月" | J6: =MONTH(EDATE('はじめに入力'!$A$5,8))&"月" | K6: =MONTH(EDATE('はじめに入力'!$A$5,9))&"月" | L6: =MONTH(EDATE('はじめに入力'!$A$5,10))&"月" | M6: =MONTH(EDATE('はじめに入力'!$A$5,11))&"月" | N6: 年間 | O6: 年間の計画と
A7: リード数 | B7: 6 | C7: 5 | D7: 6 | E7: 5 | F7: 6 | G7: 10 | H7: 10 | I7: 8 | J7: 7 | K7: 8 | L7: 10 | M7: 9 | N7: =SUM(B7:M7) | O7: {=IF(N7=INDEX('はじめに入力'!$B$9:$B$14,$F$3),"一致","確認")}
A8: 有効リード数 | B8: 2 | C8: 2 | D8: 2 | E8: 2 | F8: 2 | G8: 4 | H8: 4 | I8: 3 | J8: 3 | K8: 3 | L8: 4 | M8: 3 | N8: =SUM(B8:M8) | O8: {=IF(N8=INDEX('はじめに入力'!$D$9:$D$14,$F$3),"一致","確認")}
A9: 外部費用 | B9: {=INDEX('はじめに入力'!$J$9:$J$14,$F$3)/12} | C9: {=INDEX('はじめに入力'!$J$9:$J$14,$F$3)/12} | D9: {=INDEX('はじめに入力'!$J$9:$J$14,$F$3)/12} | E9: {=INDEX('はじめに入力'!$J$9:$J$14,$F$3)/12} | F9: {=INDEX('はじめに入力'!$J$9:$J$14,$F$3)/12} | G9: {=INDEX('はじめに入力'!$J$9:$J$14,$F$3)/12} | H9: {=INDEX('はじめに入力'!$J$9:$J$14,$F$3)/12} | I9: {=INDEX('はじめに入力'!$J$9:$J$14,$F$3)/12} | ... M9: {=INDEX('はじめに入力'!$J$9:$J$14,$F$3)/12} | N9: =SUM(B9:M9) | O9: {=IF(ROUND(N9,1)=ROUND(INDEX('はじめに入力'!$J$9:$J$14,$F$3),1),"一致","確認")}
A10: 人件費 | B10: {=INDEX('はじめに入力'!$K$9:$K$14,$F$3)/12} | C10: {=INDEX('はじめに入力'!$K$9:$K$14,$F$3)/12} | D10: {=INDEX('はじめに入力'!$K$9:$K$14,$F$3)/12} | E10: {=INDEX('はじめに入力'!$K$9:$K$14,$F$3)/12} | F10: {=INDEX('はじめに入力'!$K$9:$K$14,$F$3)/12} | G10: {=INDEX('はじめに入力'!$K$9:$K$14,$F$3)/12} | H10: {=INDEX('はじめに入力'!$K$9:$K$14,$F$3)/12} | I10: {=INDEX('はじめに入力'!$K$9:$K$14,$F$3)/12} | ... M10: {=INDEX('はじめに入力'!$K$9:$K$14,$F$3)/12} | N10: =SUM(B10:M10)
A12: 2. 実績（「毎月の実績入力」から自動）
A13: 項目 | B13: =B$6 | C13: =C$6 | D13: =D$6 | E13: =E$6 | F13: =F$6 | G13: =G$6 | H13: =H$6 | I13: =I$6 | ... M13: =M$6 | N13: 年間
A14: リード数 | B14: {=IF(INDEX('毎月の実績入力'!C$12:C$45,($F$3-1)*6+1)="","",INDEX('毎月の実績入力'!C$12:C$45,($F$3-1)*6+1))} | C14: {=IF(INDEX('毎月の実績入力'!D$12:D$45,($F$3-1)*6+1)="","",INDEX('毎月の実績入力'!D$12:D$45,($F$3-1)*6+1))} | D14: {=IF(INDEX('毎月の実績入力'!E$12:E$45,($F$3-1)*6+1)="","",INDEX('毎月の実績入力'!E$12:E$45,($F$3-1)*6+1))} | E14: {=IF(INDEX('毎月の実績入力'!F$12:F$45,($F$3-1)*6+1)="","",INDEX('毎月の実績入力'!F$12:F$45,($F$3-1)*6+1))} | F14: {=IF(INDEX('毎月の実績入力'!G$12:G$45,($F$3-1)*6+1)="","",INDEX('毎月の実績入力'!G$12:G$45,($F$3-1)*6+1))} | G14: {=IF(INDEX('毎月の実績入力'!H$12:H$45,($F$3-1)*6+1)="","",INDEX('毎月の実績入力'!H$12:H$45,($F$3-1)*6+1))} | H14: {=IF(INDEX('毎月の実績入力'!I$12:I$45,($F$3-1)*6+1)="","",INDEX('毎月の実績入力'!I$12:I$45,($F$3-1)*6+1))} | I14: {=IF(INDEX('毎月の実績入力'!J$12:J$45,($F$3-1)*6+1)="","",INDEX('毎月の実績入力'!J$12:J$45,($F$3-1)*6+1))} | ... M14: {=IF(INDEX('毎月の実績入力'!N$12:N$45,($F$3-1)*6+1)="","",INDEX('毎月の実績入力'!N$12:N$45,($F$3-1)*6+1))} | N14: =SUM(B14:M14)
A15: 有効リード率 | B15: =IF(OR(B14="",B16=""),"",IFERROR(B16/B14,"")) | C15: =IF(OR(C14="",C16=""),"",IFERROR(C16/C14,"")) | D15: =IF(OR(D14="",D16=""),"",IFERROR(D16/D14,"")) | E15: =IF(OR(E14="",E16=""),"",IFERROR(E16/E14,"")) | F15: =IF(OR(F14="",F16=""),"",IFERROR(F16/F14,"")) | G15: =IF(OR(G14="",G16=""),"",IFERROR(G16/G14,"")) | H15: =IF(OR(H14="",H16=""),"",IFERROR(H16/H14,"")) | I15: =IF(OR(I14="",I16=""),"",IFERROR(I16/I14,"")) | ... M15: =IF(OR(M14="",M16=""),"",IFERROR(M16/M14,"")) | N15: =IFERROR(N16/N14,"")
A16: 有効リード数 | B16: {=IF(INDEX('毎月の実績入力'!C$12:C$45,($F$3-1)*6+2)="","",INDEX('毎月の実績入力'!C$12:C$45,($F$3-1)*6+2))} | C16: {=IF(INDEX('毎月の実績入力'!D$12:D$45,($F$3-1)*6+2)="","",INDEX('毎月の実績入力'!D$12:D$45,($F$3-1)*6+2))} | D16: {=IF(INDEX('毎月の実績入力'!E$12:E$45,($F$3-1)*6+2)="","",INDEX('毎月の実績入力'!E$12:E$45,($F$3-1)*6+2))} | E16: {=IF(INDEX('毎月の実績入力'!F$12:F$45,($F$3-1)*6+2)="","",INDEX('毎月の実績入力'!F$12:F$45,($F$3-1)*6+2))} | F16: {=IF(INDEX('毎月の実績入力'!G$12:G$45,($F$3-1)*6+2)="","",INDEX('毎月の実績入力'!G$12:G$45,($F$3-1)*6+2))} | G16: {=IF(INDEX('毎月の実績入力'!H$12:H$45,($F$3-1)*6+2)="","",INDEX('毎月の実績入力'!H$12:H$45,($F$3-1)*6+2))} | H16: {=IF(INDEX('毎月の実績入力'!I$12:I$45,($F$3-1)*6+2)="","",INDEX('毎月の実績入力'!I$12:I$45,($F$3-1)*6+2))} | I16: {=IF(INDEX('毎月の実績入力'!J$12:J$45,($F$3-1)*6+2)="","",INDEX('毎月の実績入力'!J$12:J$45,($F$3-1)*6+2))} | ... M16: {=IF(INDEX('毎月の実績入力'!N$12:N$45,($F$3-1)*6+2)="","",INDEX('毎月の実績入力'!N$12:N$45,($F$3-1)*6+2))} | N16: =SUM(B16:M16)
A17: 外部費用 | B17: {=IF(INDEX('毎月の実績入力'!C$12:C$45,($F$3-1)*6+3)="","",INDEX('毎月の実績入力'!C$12:C$45,($F$3-1)*6+3))} | C17: {=IF(INDEX('毎月の実績入力'!D$12:D$45,($F$3-1)*6+3)="","",INDEX('毎月の実績入力'!D$12:D$45,($F$3-1)*6+3))} | D17: {=IF(INDEX('毎月の実績入力'!E$12:E$45,($F$3-1)*6+3)="","",INDEX('毎月の実績入力'!E$12:E$45,($F$3-1)*6+3))} | E17: {=IF(INDEX('毎月の実績入力'!F$12:F$45,($F$3-1)*6+3)="","",INDEX('毎月の実績入力'!F$12:F$45,($F$3-1)*6+3))} | F17: {=IF(INDEX('毎月の実績入力'!G$12:G$45,($F$3-1)*6+3)="","",INDEX('毎月の実績入力'!G$12:G$45,($F$3-1)*6+3))} | G17: {=IF(INDEX('毎月の実績入力'!H$12:H$45,($F$3-1)*6+3)="","",INDEX('毎月の実績入力'!H$12:H$45,($F$3-1)*6+3))} | H17: {=IF(INDEX('毎月の実績入力'!I$12:I$45,($F$3-1)*6+3)="","",INDEX('毎月の実績入力'!I$12:I$45,($F$3-1)*6+3))} | I17: {=IF(INDEX('毎月の実績入力'!J$12:J$45,($F$3-1)*6+3)="","",INDEX('毎月の実績入力'!J$12:J$45,($F$3-1)*6+3))} | ... M17: {=IF(INDEX('毎月の実績入力'!N$12:N$45,($F$3-1)*6+3)="","",INDEX('毎月の実績入力'!N$12:N$45,($F$3-1)*6+3))} | N17: =SUM(B17:M17)
A19: 3. 判定（開始月からの累計）
A20: 項目 | B20: =B$6 | C20: =C$6 | D20: =D$6 | E20: =E$6 | F20: =F$6 | G20: =G$6 | H20: =H$6 | I20: =I$6 | ... M20: =M$6
A21: リード数の達成率 | B21: =IF(B26="","",IFERROR(SUM(INDEX($B$14:$M$14,$B$3):B$14)/SUM(INDEX($B$7:$M$7,$B$3):B$7),"")) | C21: =IF(C26="","",IFERROR(SUM(INDEX($B$14:$M$14,$B$3):C$14)/SUM(INDEX($B$7:$M$7,$B$3):C$7),"")) | D21: =IF(D26="","",IFERROR(SUM(INDEX($B$14:$M$14,$B$3):D$14)/SUM(INDEX($B$7:$M$7,$B$3):D$7),"")) | E21: =IF(E26="","",IFERROR(SUM(INDEX($B$14:$M$14,$B$3):E$14)/SUM(INDEX($B$7:$M$7,$B$3):E$7),"")) | F21: =IF(F26="","",IFERROR(SUM(INDEX($B$14:$M$14,$B$3):F$14)/SUM(INDEX($B$7:$M$7,$B$3):F$7),"")) | G21: =IF(G26="","",IFERROR(SUM(INDEX($B$14:$M$14,$B$3):G$14)/SUM(INDEX($B$7:$M$7,$B$3):G$7),"")) | H21: =IF(H26="","",IFERROR(SUM(INDEX($B$14:$M$14,$B$3):H$14)/SUM(INDEX($B$7:$M$7,$B$3):H$7),"")) | I21: =IF(I26="","",IFERROR(SUM(INDEX($B$14:$M$14,$B$3):I$14)/SUM(INDEX($B$7:$M$7,$B$3):I$7),"")) | ... M21: =IF(M26="","",IFERROR(SUM(INDEX($B$14:$M$14,$B$3):M$14)/SUM(INDEX($B$7:$M$7,$B$3):M$7),""))
A22: 有効リード数の達成率 | B22: =IF(B26="","",IFERROR(SUM(INDEX($B$16:$M$16,$B$3):B$16)/SUM(INDEX($B$8:$M$8,$B$3):B$8),"")) | C22: =IF(C26="","",IFERROR(SUM(INDEX($B$16:$M$16,$B$3):C$16)/SUM(INDEX($B$8:$M$8,$B$3):C$8),"")) | D22: =IF(D26="","",IFERROR(SUM(INDEX($B$16:$M$16,$B$3):D$16)/SUM(INDEX($B$8:$M$8,$B$3):D$8),"")) | E22: =IF(E26="","",IFERROR(SUM(INDEX($B$16:$M$16,$B$3):E$16)/SUM(INDEX($B$8:$M$8,$B$3):E$8),"")) | F22: =IF(F26="","",IFERROR(SUM(INDEX($B$16:$M$16,$B$3):F$16)/SUM(INDEX($B$8:$M$8,$B$3):F$8),"")) | G22: =IF(G26="","",IFERROR(SUM(INDEX($B$16:$M$16,$B$3):G$16)/SUM(INDEX($B$8:$M$8,$B$3):G$8),"")) | H22: =IF(H26="","",IFERROR(SUM(INDEX($B$16:$M$16,$B$3):H$16)/SUM(INDEX($B$8:$M$8,$B$3):H$8),"")) | I22: =IF(I26="","",IFERROR(SUM(INDEX($B$16:$M$16,$B$3):I$16)/SUM(INDEX($B$8:$M$8,$B$3):I$8),"")) | ... M22: =IF(M26="","",IFERROR(SUM(INDEX($B$16:$M$16,$B$3):M$16)/SUM(INDEX($B$8:$M$8,$B$3):M$8),""))
A23: CPL | B23: =IF(B26="","",IFERROR(B26/SUM(INDEX($B$14:$M$14,$B$3):B$14),"―")) | C23: =IF(C26="","",IFERROR(C26/SUM(INDEX($B$14:$M$14,$B$3):C$14),"―")) | D23: =IF(D26="","",IFERROR(D26/SUM(INDEX($B$14:$M$14,$B$3):D$14),"―")) | E23: =IF(E26="","",IFERROR(E26/SUM(INDEX($B$14:$M$14,$B$3):E$14),"―")) | F23: =IF(F26="","",IFERROR(F26/SUM(INDEX($B$14:$M$14,$B$3):F$14),"―")) | G23: =IF(G26="","",IFERROR(G26/SUM(INDEX($B$14:$M$14,$B$3):G$14),"―")) | H23: =IF(H26="","",IFERROR(H26/SUM(INDEX($B$14:$M$14,$B$3):H$14),"―")) | I23: =IF(I26="","",IFERROR(I26/SUM(INDEX($B$14:$M$14,$B$3):I$14),"―")) | ... M23: =IF(M26="","",IFERROR(M26/SUM(INDEX($B$14:$M$14,$B$3):M$14),"―"))
A24: 判定 | B24: =IF(B26="","",IF(SUM(INDEX($B$17:$M$17,$B$3):B$17)=0,"費用なし",IF(OR(B23="―",B23>$F$2),"上限超え","上限内"))) | C24: =IF(C26="","",IF(SUM(INDEX($B$17:$M$17,$B$3):C$17)=0,"費用なし",IF(OR(C23="―",C23>$F$2),"上限超え","上限内"))) | D24: =IF(D26="","",IF(SUM(INDEX($B$17:$M$17,$B$3):D$17)=0,"費用なし",IF(OR(D23="―",D23>$F$2),"上限超え","上限内"))) | E24: =IF(E26="","",IF(SUM(INDEX($B$17:$M$17,$B$3):E$17)=0,"費用なし",IF(OR(E23="―",E23>$F$2),"上限超え","上限内"))) | F24: =IF(F26="","",IF(SUM(INDEX($B$17:$M$17,$B$3):F$17)=0,"費用なし",IF(OR(F23="―",F23>$F$2),"上限超え","上限内"))) | G24: =IF(G26="","",IF(SUM(INDEX($B$17:$M$17,$B$3):G$17)=0,"費用なし",IF(OR(G23="―",G23>$F$2),"上限超え","上限内"))) | H24: =IF(H26="","",IF(SUM(INDEX($B$17:$M$17,$B$3):H$17)=0,"費用なし",IF(OR(H23="―",H23>$F$2),"上限超え","上限内"))) | I24: =IF(I26="","",IF(SUM(INDEX($B$17:$M$17,$B$3):I$17)=0,"費用なし",IF(OR(I23="―",I23>$F$2),"上限超え","上限内"))) | ... M24: =IF(M26="","",IF(SUM(INDEX($B$17:$M$17,$B$3):M$17)=0,"費用なし",IF(OR(M23="―",M23>$F$2),"上限超え","上限内")))
A25: 撤退の判断 | B25: =IF(B26="","",IF(COLUMN()-1<$D$3,"判定前",IF(B24="費用なし","判定しない",IF(AND(B24="上限超え",B21<0.9),"撤退を検討","なし")))) | C25: =IF(C26="","",IF(COLUMN()-1<$D$3,"判定前",IF(C24="費用なし","判定しない",IF(AND(C24="上限超え",C21<0.9),"撤退を検討","なし")))) | D25: =IF(D26="","",IF(COLUMN()-1<$D$3,"判定前",IF(D24="費用なし","判定しない",IF(AND(D24="上限超え",D21<0.9),"撤退を検討","なし")))) | E25: =IF(E26="","",IF(COLUMN()-1<$D$3,"判定前",IF(E24="費用なし","判定しない",IF(AND(E24="上限超え",E21<0.9),"撤退を検討","なし")))) | F25: =IF(F26="","",IF(COLUMN()-1<$D$3,"判定前",IF(F24="費用なし","判定しない",IF(AND(F24="上限超え",F21<0.9),"撤退を検討","なし")))) | G25: =IF(G26="","",IF(COLUMN()-1<$D$3,"判定前",IF(G24="費用なし","判定しない",IF(AND(G24="上限超え",G21<0.9),"撤退を検討","なし")))) | H25: =IF(H26="","",IF(COLUMN()-1<$D$3,"判定前",IF(H24="費用なし","判定しない",IF(AND(H24="上限超え",H21<0.9),"撤退を検討","なし")))) | I25: =IF(I26="","",IF(COLUMN()-1<$D$3,"判定前",IF(I24="費用なし","判定しない",IF(AND(I24="上限超え",I21<0.9),"撤退を検討","なし")))) | ... M25: =IF(M26="","",IF(COLUMN()-1<$D$3,"判定前",IF(M24="費用なし","判定しない",IF(AND(M24="上限超え",M21<0.9),"撤退を検討","なし"))))
A26: 費用（外部費用＋人件費） | B26: =IF(OR($B$3="",COLUMN()-1<$B$3,B$14=""),"",SUM(INDEX($B$17:$M$17,$B$3):B$17)+SUM(INDEX($B$10:$M$10,$B$3):B$10)) | C26: =IF(OR($B$3="",COLUMN()-1<$B$3,C$14=""),"",SUM(INDEX($B$17:$M$17,$B$3):C$17)+SUM(INDEX($B$10:$M$10,$B$3):C$10)) | D26: =IF(OR($B$3="",COLUMN()-1<$B$3,D$14=""),"",SUM(INDEX($B$17:$M$17,$B$3):D$17)+SUM(INDEX($B$10:$M$10,$B$3):D$10)) | E26: =IF(OR($B$3="",COLUMN()-1<$B$3,E$14=""),"",SUM(INDEX($B$17:$M$17,$B$3):E$17)+SUM(INDEX($B$10:$M$10,$B$3):E$10)) | F26: =IF(OR($B$3="",COLUMN()-1<$B$3,F$14=""),"",SUM(INDEX($B$17:$M$17,$B$3):F$17)+SUM(INDEX($B$10:$M$10,$B$3):F$10)) | G26: =IF(OR($B$3="",COLUMN()-1<$B$3,G$14=""),"",SUM(INDEX($B$17:$M$17,$B$3):G$17)+SUM(INDEX($B$10:$M$10,$B$3):G$10)) | H26: =IF(OR($B$3="",COLUMN()-1<$B$3,H$14=""),"",SUM(INDEX($B$17:$M$17,$B$3):H$17)+SUM(INDEX($B$10:$M$10,$B$3):H$10)) | I26: =IF(OR($B$3="",COLUMN()-1<$B$3,I$14=""),"",SUM(INDEX($B$17:$M$17,$B$3):I$17)+SUM(INDEX($B$10:$M$10,$B$3):I$10)) | ... M26: =IF(OR($B$3="",COLUMN()-1<$B$3,M$14=""),"",SUM(INDEX($B$17:$M$17,$B$3):M$17)+SUM(INDEX($B$10:$M$10,$B$3):M$10))
A28: 開始月＝計画のリード数を最初に入れた月。判定する月＝開始月＋6か月。実績は、リード数を入れた月まで計算する。外部費用の計画は年額÷12を自動で入れているので、月ごとに違う場合は上書きする
A29: 判定＝開始月からの累計のCPL（外部費用＋人件費÷リード数）が許容CPL以下なら「上限内」、超えたら「上限超え」
A30: 撤退の判断＝判定する月から毎月、累計で「上限超え」かつ「リード数の達成率が90%未満」なら「撤退を検討」。費用を入れていない施策は判定しない

Sheet SNS
A1: SNS | D1: 灰色＝入力 白＝自動計算 単位：万円
A2: 開始月 | B2: {=IF(B3="","計画なし",INDEX($B$6:$M$6,B3))} | C2: 判定する月 | D2: {=IF(D3="","",IF(D3>12,"今期は判定なし",INDEX($B$6:$M$6,D3)))} | E2: 許容CPL | F2: ='はじめに入力'!$I$5
A3: （計算用） | B3: {=IFERROR(MATCH(TRUE,INDEX($B$7:$M$7>0,0),0),"")} | D3: =IF(B3="","",B3+6) | F3: =MATCH($A$1,'はじめに入力'!$A$9:$A$14,0)
A4: 1. 計画（期初に入力）
B5: ※外部費用と人件費は、適宜修正してください。
A6: 項目 | B6: =MONTH(EDATE('はじめに入力'!$A$5,0))&"月" | C6: =MONTH(EDATE('はじめに入力'!$A$5,1))&"月" | D6: =MONTH(EDATE('はじめに入力'!$A$5,2))&"月" | E6: =MONTH(EDATE('はじめに入力'!$A$5,3))&"月" | F6: =MONTH(EDATE('はじめに入力'!$A$5,4))&"月" | G6: =MONTH(EDATE('はじめに入力'!$A$5,5))&"月" | H6: =MONTH(EDATE('はじめに入力'!$A$5,6))&"月" | I6: =MONTH(EDATE('はじめに入力'!$A$5,7))&"月" | J6: =MONTH(EDATE('はじめに入力'!$A$5,8))&"月" | K6: =MONTH(EDATE('はじめに入力'!$A$5,9))&"月" | L6: =MONTH(EDATE('はじめに入力'!$A$5,10))&"月" | M6: =MONTH(EDATE('はじめに入力'!$A$5,11))&"月" | N6: 年間 | O6: 年間の計画と
A7: リード数 | B7: 1 | C7: 1 | D7: 1 | E7: 1 | F7: 1 | G7: 1 | H7: 1 | I7: 1 | J7: 1 | K7: 1 | L7: 1 | M7: 1 | N7: =SUM(B7:M7) | O7: {=IF(N7=INDEX('はじめに入力'!$B$9:$B$14,$F$3),"一致","確認")}
A8: 有効リード数 | B8: 0 | C8: 1 | D8: 0 | E8: 1 | F8: 0 | G8: 1 | H8: 0 | I8: 1 | J8: 0 | K8: 1 | L8: 0 | M8: 0 | N8: =SUM(B8:M8) | O8: {=IF(N8=INDEX('はじめに入力'!$D$9:$D$14,$F$3),"一致","確認")}
A9: 外部費用 | B9: {=INDEX('はじめに入力'!$J$9:$J$14,$F$3)/12} | C9: {=INDEX('はじめに入力'!$J$9:$J$14,$F$3)/12} | D9: {=INDEX('はじめに入力'!$J$9:$J$14,$F$3)/12} | E9: {=INDEX('はじめに入力'!$J$9:$J$14,$F$3)/12} | F9: {=INDEX('はじめに入力'!$J$9:$J$14,$F$3)/12} | G9: {=INDEX('はじめに入力'!$J$9:$J$14,$F$3)/12} | H9: {=INDEX('はじめに入力'!$J$9:$J$14,$F$3)/12} | I9: {=INDEX('はじめに入力'!$J$9:$J$14,$F$3)/12} | ... M9: {=INDEX('はじめに入力'!$J$9:$J$14,$F$3)/12} | N9: =SUM(B9:M9) | O9: {=IF(ROUND(N9,1)=ROUND(INDEX('はじめに入力'!$J$9:$J$14,$F$3),1),"一致","確認")}
A10: 人件費 | B10: {=INDEX('はじめに入力'!$K$9:$K$14,$F$3)/12} | C10: {=INDEX('はじめに入力'!$K$9:$K$14,$F$3)/12} | D10: {=INDEX('はじめに入力'!$K$9:$K$14,$F$3)/12} | E10: {=INDEX('はじめに入力'!$K$9:$K$14,$F$3)/12} | F10: {=INDEX('はじめに入力'!$K$9:$K$14,$F$3)/12} | G10: {=INDEX('はじめに入力'!$K$9:$K$14,$F$3)/12} | H10: {=INDEX('はじめに入力'!$K$9:$K$14,$F$3)/12} | I10: {=INDEX('はじめに入力'!$K$9:$K$14,$F$3)/12} | ... M10: {=INDEX('はじめに入力'!$K$9:$K$14,$F$3)/12} | N10: =SUM(B10:M10)
A12: 2. 実績（「毎月の実績入力」から自動）
A13: 項目 | B13: =B$6 | C13: =C$6 | D13: =D$6 | E13: =E$6 | F13: =F$6 | G13: =G$6 | H13: =H$6 | I13: =I$6 | ... M13: =M$6 | N13: 年間
A14: リード数 | B14: {=IF(INDEX('毎月の実績入力'!C$12:C$45,($F$3-1)*6+1)="","",INDEX('毎月の実績入力'!C$12:C$45,($F$3-1)*6+1))} | C14: {=IF(INDEX('毎月の実績入力'!D$12:D$45,($F$3-1)*6+1)="","",INDEX('毎月の実績入力'!D$12:D$45,($F$3-1)*6+1))} | D14: {=IF(INDEX('毎月の実績入力'!E$12:E$45,($F$3-1)*6+1)="","",INDEX('毎月の実績入力'!E$12:E$45,($F$3-1)*6+1))} | E14: {=IF(INDEX('毎月の実績入力'!F$12:F$45,($F$3-1)*6+1)="","",INDEX('毎月の実績入力'!F$12:F$45,($F$3-1)*6+1))} | F14: {=IF(INDEX('毎月の実績入力'!G$12:G$45,($F$3-1)*6+1)="","",INDEX('毎月の実績入力'!G$12:G$45,($F$3-1)*6+1))} | G14: {=IF(INDEX('毎月の実績入力'!H$12:H$45,($F$3-1)*6+1)="","",INDEX('毎月の実績入力'!H$12:H$45,($F$3-1)*6+1))} | H14: {=IF(INDEX('毎月の実績入力'!I$12:I$45,($F$3-1)*6+1)="","",INDEX('毎月の実績入力'!I$12:I$45,($F$3-1)*6+1))} | I14: {=IF(INDEX('毎月の実績入力'!J$12:J$45,($F$3-1)*6+1)="","",INDEX('毎月の実績入力'!J$12:J$45,($F$3-1)*6+1))} | ... M14: {=IF(INDEX('毎月の実績入力'!N$12:N$45,($F$3-1)*6+1)="","",INDEX('毎月の実績入力'!N$12:N$45,($F$3-1)*6+1))} | N14: =SUM(B14:M14)
A15: 有効リード率 | B15: =IF(OR(B14="",B16=""),"",IFERROR(B16/B14,"")) | C15: =IF(OR(C14="",C16=""),"",IFERROR(C16/C14,"")) | D15: =IF(OR(D14="",D16=""),"",IFERROR(D16/D14,"")) | E15: =IF(OR(E14="",E16=""),"",IFERROR(E16/E14,"")) | F15: =IF(OR(F14="",F16=""),"",IFERROR(F16/F14,"")) | G15: =IF(OR(G14="",G16=""),"",IFERROR(G16/G14,"")) | H15: =IF(OR(H14="",H16=""),"",IFERROR(H16/H14,"")) | I15: =IF(OR(I14="",I16=""),"",IFERROR(I16/I14,"")) | ... M15: =IF(OR(M14="",M16=""),"",IFERROR(M16/M14,"")) | N15: =IFERROR(N16/N14,"")
